2017-10-28T12:32:56.5781395+03:00 0HL8TSQTT6S50 [ERR] FundTrack.BLL.Concrete.BusinessLogicException: Неможливо отримати інформацію для рахунку ---> System.InvalidOperationException: Nullable object must have a value.
   at System.ThrowHelper.ThrowInvalidOperationException(ExceptionResource resource)
   at System.Nullable`1.get_Value()
   at FundTrack.BLL.Concrete.OrganizationAccountService.GetDonateCredentials(Int32 orgAccountId) in C:\FundTrack\FundTrack.BLL\Concrete\OrganizationAccountService.cs:line 354
   --- End of inner exception stack trace ---
   at FundTrack.BLL.Concrete.OrganizationAccountService.GetDonateCredentials(Int32 orgAccountId) in C:\FundTrack\FundTrack.BLL\Concrete\OrganizationAccountService.cs:line 365
   at FundTrack.WebUI.Controllers.OrgAccountController.GetDonateCredentials(Int32 orgAccountId) in C:\FundTrack\FundTrack.WebUI\Controllers\OrgAccountController.cs:line 82
   at lambda_method(Closure , Object , Object[] )
   at Microsoft.AspNetCore.Mvc.Internal.ControllerActionInvoker.<InvokeActionMethodAsync>d__27.MoveNext()
--- End of stack trace from previous location where exception was thrown ---
   at System.Runtime.ExceptionServices.ExceptionDispatchInfo.Throw()
   at System.Runtime.CompilerServices.TaskAwaiter.HandleNonSuccessAndDebuggerNotification(Task task)
   at Microsoft.AspNetCore.Mvc.Internal.ControllerActionInvoker.<InvokeNextActionFilterAsync>d__25.MoveNext()
--- End of stack trace from previous location where exception was thrown ---
   at System.Runtime.ExceptionServices.ExceptionDispatchInfo.Throw()
   at Microsoft.AspNetCore.Mvc.Internal.ControllerActionInvoker.Rethrow(ActionExecutedContext context)
   at Microsoft.AspNetCore.Mvc.Internal.ControllerActionInvoker.Next(State& next, Scope& scope, Object& state, Boolean& isCompleted)
   at Microsoft.AspNetCore.Mvc.Internal.ControllerActionInvoker.<InvokeNextResourceFilter>d__22.MoveNext()
--- End of stack trace from previous location where exception was thrown ---
   at System.Runtime.ExceptionServices.ExceptionDispatchInfo.Throw()
   at Microsoft.AspNetCore.Mvc.Internal.ControllerActionInvoker.Rethrow(ResourceExecutedContext context)
   at Microsoft.AspNetCore.Mvc.Internal.ControllerActionInvoker.Next(State& next, Scope& scope, Object& state, Boolean& isCompleted)
   at Microsoft.AspNetCore.Mvc.Internal.ControllerActionInvoker.<InvokeAsync>d__20.MoveNext()
--- End of stack trace from previous location where exception was thrown ---
   at System.Runtime.ExceptionServices.ExceptionDispatchInfo.Throw()
   at System.Runtime.CompilerServices.TaskAwaiter.HandleNonSuccessAndDebuggerNotification(Task task)
   at Microsoft.AspNetCore.Builder.RouterMiddleware.<Invoke>d__4.MoveNext()
--- End of stack trace from previous location where exception was thrown ---
   at System.Runtime.ExceptionServices.ExceptionDispatchInfo.Throw()
   at System.Runtime.CompilerServices.TaskAwaiter.HandleNonSuccessAndDebuggerNotification(Task task)
   at Microsoft.AspNetCore.SpaServices.Webpack.ConditionalProxyMiddleware.<Invoke>d__5.MoveNext()
--- End of stack trace from previous location where exception was thrown ---
   at System.Runtime.ExceptionServices.ExceptionDispatchInfo.Throw()
   at System.Runtime.CompilerServices.TaskAwaiter.HandleNonSuccessAndDebuggerNotification(Task task)
   at Microsoft.AspNetCore.SpaServices.Webpack.ConditionalProxyMiddleware.<Invoke>d__5.MoveNext()
--- End of stack trace from previous location where exception was thrown ---
   at System.Runtime.ExceptionServices.ExceptionDispatchInfo.Throw()
   at System.Runtime.CompilerServices.TaskAwaiter.HandleNonSuccessAndDebuggerNotification(Task task)
   at Microsoft.AspNetCore.Authentication.AuthenticationMiddleware`1.<Invoke>d__18.MoveNext()
--- End of stack trace from previous location where exception was thrown ---
   at System.Runtime.ExceptionServices.ExceptionDispatchInfo.Throw()
   at Microsoft.AspNetCore.Authentication.AuthenticationMiddleware`1.<Invoke>d__18.MoveNext()
--- End of stack trace from previous location where exception was thrown ---
   at System.Runtime.ExceptionServices.ExceptionDispatchInfo.Throw()
   at System.Runtime.CompilerServices.TaskAwaiter.HandleNonSuccessAndDebuggerNotification(Task task)
   at System.Runtime.CompilerServices.TaskAwaiter.GetResult()
   at FundTrack.WebUI.Middlewares.GlobalErrorHandlingMiddleware.<Invoke>d__4.MoveNext() in C:\FundTrack\FundTrack.WebUI\Middlewares\GlobalErrorHandlingMiddleware.cs:line 28 (682b77bc)
2017-10-28T12:39:04.4748894+03:00 0HL8TSUJ72U9P [ERR] FundTrack.BLL.Concrete.BusinessLogicException: Неможливо отримати інформацію для рахунку ---> System.InvalidOperationException: Nullable object must have a value.
   at System.ThrowHelper.ThrowInvalidOperationException(ExceptionResource resource)
   at System.Nullable`1.get_Value()
   at FundTrack.BLL.Concrete.OrganizationAccountService.GetDonateCredentials(Int32 orgAccountId) in C:\FundTrack\FundTrack.BLL\Concrete\OrganizationAccountService.cs:line 354
   --- End of inner exception stack trace ---
   at FundTrack.BLL.Concrete.OrganizationAccountService.GetDonateCredentials(Int32 orgAccountId) in C:\FundTrack\FundTrack.BLL\Concrete\OrganizationAccountService.cs:line 365
   at FundTrack.WebUI.Controllers.OrgAccountController.GetDonateCredentials(Int32 orgAccountId) in C:\FundTrack\FundTrack.WebUI\Controllers\OrgAccountController.cs:line 82
   at lambda_method(Closure , Object , Object[] )
   at Microsoft.AspNetCore.Mvc.Internal.ControllerActionInvoker.<InvokeActionMethodAsync>d__27.MoveNext()
--- End of stack trace from previous location where exception was thrown ---
   at System.Runtime.ExceptionServices.ExceptionDispatchInfo.Throw()
   at System.Runtime.CompilerServices.TaskAwaiter.HandleNonSuccessAndDebuggerNotification(Task task)
   at Microsoft.AspNetCore.Mvc.Internal.ControllerActionInvoker.<InvokeNextActionFilterAsync>d__25.MoveNext()
--- End of stack trace from previous location where exception was thrown ---
   at System.Runtime.ExceptionServices.ExceptionDispatchInfo.Throw()
   at Microsoft.AspNetCore.Mvc.Internal.ControllerActionInvoker.Rethrow(ActionExecutedContext context)
   at Microsoft.AspNetCore.Mvc.Internal.ControllerActionInvoker.Next(State& next, Scope& scope, Object& state, Boolean& isCompleted)
   at Microsoft.AspNetCore.Mvc.Internal.ControllerActionInvoker.<InvokeNextResourceFilter>d__22.MoveNext()
--- End of stack trace from previous location where exception was thrown ---
   at System.Runtime.ExceptionServices.ExceptionDispatchInfo.Throw()
   at Microsoft.AspNetCore.Mvc.Internal.ControllerActionInvoker.Rethrow(ResourceExecutedContext context)
   at Microsoft.AspNetCore.Mvc.Internal.ControllerActionInvoker.Next(State& next, Scope& scope, Object& state, Boolean& isCompleted)
   at Microsoft.AspNetCore.Mvc.Internal.ControllerActionInvoker.<InvokeAsync>d__20.MoveNext()
--- End of stack trace from previous location where exception was thrown ---
   at System.Runtime.ExceptionServices.ExceptionDispatchInfo.Throw()
   at System.Runtime.CompilerServices.TaskAwaiter.HandleNonSuccessAndDebuggerNotification(Task task)
   at Microsoft.AspNetCore.Builder.RouterMiddleware.<Invoke>d__4.MoveNext()
--- End of stack trace from previous location where exception was thrown ---
   at System.Runtime.ExceptionServices.ExceptionDispatchInfo.Throw()
   at System.Runtime.CompilerServices.TaskAwaiter.HandleNonSuccessAndDebuggerNotification(Task task)
   at Microsoft.AspNetCore.SpaServices.Webpack.ConditionalProxyMiddleware.<Invoke>d__5.MoveNext()
--- End of stack trace from previous location where exception was thrown ---
   at System.Runtime.ExceptionServices.ExceptionDispatchInfo.Throw()
   at System.Runtime.CompilerServices.TaskAwaiter.HandleNonSuccessAndDebuggerNotification(Task task)
   at Microsoft.AspNetCore.SpaServices.Webpack.ConditionalProxyMiddleware.<Invoke>d__5.MoveNext()
--- End of stack trace from previous location where exception was thrown ---
   at System.Runtime.ExceptionServices.ExceptionDispatchInfo.Throw()
   at System.Runtime.CompilerServices.TaskAwaiter.HandleNonSuccessAndDebuggerNotification(Task task)
   at Microsoft.AspNetCore.Authentication.AuthenticationMiddleware`1.<Invoke>d__18.MoveNext()
--- End of stack trace from previous location where exception was thrown ---
   at System.Runtime.ExceptionServices.ExceptionDispatchInfo.Throw()
   at Microsoft.AspNetCore.Authentication.AuthenticationMiddleware`1.<Invoke>d__18.MoveNext()
--- End of stack trace from previous location where exception was thrown ---
   at System.Runtime.ExceptionServices.ExceptionDispatchInfo.Throw()
   at System.Runtime.CompilerServices.TaskAwaiter.HandleNonSuccessAndDebuggerNotification(Task task)
   at System.Runtime.CompilerServices.TaskAwaiter.GetResult()
   at FundTrack.WebUI.Middlewares.GlobalErrorHandlingMiddleware.<Invoke>d__4.MoveNext() in C:\FundTrack\FundTrack.WebUI\Middlewares\GlobalErrorHandlingMiddleware.cs:line 28 (682b77bc)
2017-10-28T12:40:34.4545923+03:00 0HL8TSVGATUSI [ERR] FundTrack.BLL.Concrete.BusinessLogicException: Неможливо отримати інформацію для рахунку ---> System.InvalidOperationException: Nullable object must have a value.
   at System.ThrowHelper.ThrowInvalidOperationException(ExceptionResource resource)
   at System.Nullable`1.get_Value()
   at FundTrack.BLL.Concrete.OrganizationAccountService.GetDonateCredentials(Int32 orgAccountId) in C:\FundTrack\FundTrack.BLL\Concrete\OrganizationAccountService.cs:line 354
   --- End of inner exception stack trace ---
   at FundTrack.BLL.Concrete.OrganizationAccountService.GetDonateCredentials(Int32 orgAccountId) in C:\FundTrack\FundTrack.BLL\Concrete\OrganizationAccountService.cs:line 365
   at FundTrack.WebUI.Controllers.OrgAccountController.GetDonateCredentials(Int32 orgAccountId) in C:\FundTrack\FundTrack.WebUI\Controllers\OrgAccountController.cs:line 82
   at lambda_method(Closure , Object , Object[] )
   at Microsoft.AspNetCore.Mvc.Internal.ControllerActionInvoker.<InvokeActionMethodAsync>d__27.MoveNext()
--- End of stack trace from previous location where exception was thrown ---
   at System.Runtime.ExceptionServices.ExceptionDispatchInfo.Throw()
   at System.Runtime.CompilerServices.TaskAwaiter.HandleNonSuccessAndDebuggerNotification(Task task)
   at Microsoft.AspNetCore.Mvc.Internal.ControllerActionInvoker.<InvokeNextActionFilterAsync>d__25.MoveNext()
--- End of stack trace from previous location where exception was thrown ---
   at System.Runtime.ExceptionServices.ExceptionDispatchInfo.Throw()
   at Microsoft.AspNetCore.Mvc.Internal.ControllerActionInvoker.Rethrow(ActionExecutedContext context)
   at Microsoft.AspNetCore.Mvc.Internal.ControllerActionInvoker.Next(State& next, Scope& scope, Object& state, Boolean& isCompleted)
   at Microsoft.AspNetCore.Mvc.Internal.ControllerActionInvoker.<InvokeNextResourceFilter>d__22.MoveNext()
--- End of stack trace from previous location where exception was thrown ---
   at System.Runtime.ExceptionServices.ExceptionDispatchInfo.Throw()
   at Microsoft.AspNetCore.Mvc.Internal.ControllerActionInvoker.Rethrow(ResourceExecutedContext context)
   at Microsoft.AspNetCore.Mvc.Internal.ControllerActionInvoker.Next(State& next, Scope& scope, Object& state, Boolean& isCompleted)
   at Microsoft.AspNetCore.Mvc.Internal.ControllerActionInvoker.<InvokeAsync>d__20.MoveNext()
--- End of stack trace from previous location where exception was thrown ---
   at System.Runtime.ExceptionServices.ExceptionDispatchInfo.Throw()
   at System.Runtime.CompilerServices.TaskAwaiter.HandleNonSuccessAndDebuggerNotification(Task task)
   at Microsoft.AspNetCore.Builder.RouterMiddleware.<Invoke>d__4.MoveNext()
--- End of stack trace from previous location where exception was thrown ---
   at System.Runtime.ExceptionServices.ExceptionDispatchInfo.Throw()
   at System.Runtime.CompilerServices.TaskAwaiter.HandleNonSuccessAndDebuggerNotification(Task task)
   at Microsoft.AspNetCore.SpaServices.Webpack.ConditionalProxyMiddleware.<Invoke>d__5.MoveNext()
--- End of stack trace from previous location where exception was thrown ---
   at System.Runtime.ExceptionServices.ExceptionDispatchInfo.Throw()
   at System.Runtime.CompilerServices.TaskAwaiter.HandleNonSuccessAndDebuggerNotification(Task task)
   at Microsoft.AspNetCore.SpaServices.Webpack.ConditionalProxyMiddleware.<Invoke>d__5.MoveNext()
--- End of stack trace from previous location where exception was thrown ---
   at System.Runtime.ExceptionServices.ExceptionDispatchInfo.Throw()
   at System.Runtime.CompilerServices.TaskAwaiter.HandleNonSuccessAndDebuggerNotification(Task task)
   at Microsoft.AspNetCore.Authentication.AuthenticationMiddleware`1.<Invoke>d__18.MoveNext()
--- End of stack trace from previous location where exception was thrown ---
   at System.Runtime.ExceptionServices.ExceptionDispatchInfo.Throw()
   at Microsoft.AspNetCore.Authentication.AuthenticationMiddleware`1.<Invoke>d__18.MoveNext()
--- End of stack trace from previous location where exception was thrown ---
   at System.Runtime.ExceptionServices.ExceptionDispatchInfo.Throw()
   at System.Runtime.CompilerServices.TaskAwaiter.HandleNonSuccessAndDebuggerNotification(Task task)
   at System.Runtime.CompilerServices.TaskAwaiter.GetResult()
   at FundTrack.WebUI.Middlewares.GlobalErrorHandlingMiddleware.<Invoke>d__4.MoveNext() in C:\FundTrack\FundTrack.WebUI\Middlewares\GlobalErrorHandlingMiddleware.cs:line 28 (682b77bc)
2017-10-28T13:21:00.2196885+03:00  [ERR] Hash: 4101c040ed2a7c80fb12
Version: webpack 2.7.0
Time: 6886ms
                                   Asset      Size  Chunks                    Chunk Names
                          main-client.js   4.86 MB       0  [emitted]  [big]  main-client
    0.4f59e6fc570ecbd37d0f.hot-update.js   18.3 kB       0  [emitted]         main-client
    4f59e6fc570ecbd37d0f.hot-update.json  43 bytes          [emitted]         
                      main-client.js.map   6.42 MB       0  [emitted]         main-client
0.4f59e6fc570ecbd37d0f.hot-update.js.map   30.1 kB       0  [emitted]         main-client
chunk    {0} main-client.js, 0.4f59e6fc570ecbd37d0f.hot-update.js, main-client.js.map, 0.4f59e6fc570ecbd37d0f.hot-update.js.map (main-client) 4.73 MB [entry] [rendered]
    [0] delegated ./node_modules/@angular/core/index.js from dll-reference vendor_3d6b1ff2e706ed474586 42 bytes {0} [not cacheable] [built]
    [5] external "vendor_3d6b1ff2e706ed474586" 42 bytes {0} [not cacheable]
   [11] delegated ./node_modules/angular2-universal/browser/index.js from dll-reference vendor_3d6b1ff2e706ed474586 42 bytes {0} [not cacheable] [built]
  [118] delegated ./node_modules/webpack/buildin/module.js from dll-reference vendor_3d6b1ff2e706ed474586 42 bytes {0} [not cacheable] [built]
  [221] ./ClientApp/boot-client.ts 1.3 kB {0} [built]
  [222] (webpack)-hot-middleware/client.js?path=%2F__webpack_hmr 7.04 kB {0}
  [223] delegated ./node_modules/event-source-polyfill/eventsource.js from dll-reference vendor_3d6b1ff2e706ed474586 42 bytes {0} [not cacheable] [built]
  [241] ./ClientApp/app/app.module.ts 3.09 kB {0} [built]
  [543] ./~/querystring-es3/index.js 127 bytes {0}
  [556] ./~/strip-ansi/index.js 161 bytes {0}
  [612] (webpack)-hot-middleware/client-overlay.js 1.82 kB {0}
  [613] (webpack)-hot-middleware/process-update.js 3.87 kB {0}
  [635] delegated ./node_modules/angular2-universal-polyfills/browser.js from dll-reference vendor_3d6b1ff2e706ed474586 42 bytes {0} [not cacheable] [built]
  [636] delegated ./node_modules/bootstrap/dist/js/npm.js from dll-reference vendor_3d6b1ff2e706ed474586 42 bytes {0} [not cacheable] [built]
  [641] multi event-source-polyfill webpack-hot-middleware/client?path=%2F__webpack_hmr ./ClientApp/boot-client.ts 52 bytes {0}
     + 627 hidden modules

ERROR in [at-loader] ./ClientApp/app/components/finance/bank-import.component.ts:345:44 
    TS1005: ')' expected.

ERROR in [at-loader] ./ClientApp/app/components/finance/bank-import.component.ts:345:45 
    TS1128: Declaration or statement expected. (53748a40)
2017-10-28T13:24:54.6879172+03:00  [ERR] Hash: eaa3b55e31488c6c3763
Version: webpack 2.7.0
Time: 5952ms
                                   Asset      Size  Chunks                    Chunk Names
                          main-client.js   4.86 MB       0  [emitted]  [big]  main-client
    0.81ef22dd13ce4f64e8b2.hot-update.js   18.6 kB       0  [emitted]         main-client
    81ef22dd13ce4f64e8b2.hot-update.json  43 bytes          [emitted]         
                      main-client.js.map   6.42 MB       0  [emitted]         main-client
0.81ef22dd13ce4f64e8b2.hot-update.js.map   30.4 kB       0  [emitted]         main-client
chunk    {0} main-client.js, 0.81ef22dd13ce4f64e8b2.hot-update.js, main-client.js.map, 0.81ef22dd13ce4f64e8b2.hot-update.js.map (main-client) 4.73 MB [entry] [rendered]
    [0] delegated ./node_modules/@angular/core/index.js from dll-reference vendor_3d6b1ff2e706ed474586 42 bytes {0} [not cacheable] [built]
    [5] external "vendor_3d6b1ff2e706ed474586" 42 bytes {0} [not cacheable]
   [11] delegated ./node_modules/angular2-universal/browser/index.js from dll-reference vendor_3d6b1ff2e706ed474586 42 bytes {0} [not cacheable] [built]
  [118] delegated ./node_modules/webpack/buildin/module.js from dll-reference vendor_3d6b1ff2e706ed474586 42 bytes {0} [not cacheable] [built]
  [221] ./ClientApp/boot-client.ts 1.3 kB {0} [built]
  [222] (webpack)-hot-middleware/client.js?path=%2F__webpack_hmr 7.04 kB {0}
  [223] delegated ./node_modules/event-source-polyfill/eventsource.js from dll-reference vendor_3d6b1ff2e706ed474586 42 bytes {0} [not cacheable] [built]
  [241] ./ClientApp/app/app.module.ts 3.09 kB {0} [built]
  [543] ./~/querystring-es3/index.js 127 bytes {0}
  [556] ./~/strip-ansi/index.js 161 bytes {0}
  [612] (webpack)-hot-middleware/client-overlay.js 1.82 kB {0}
  [613] (webpack)-hot-middleware/process-update.js 3.87 kB {0}
  [635] delegated ./node_modules/angular2-universal-polyfills/browser.js from dll-reference vendor_3d6b1ff2e706ed474586 42 bytes {0} [not cacheable] [built]
  [636] delegated ./node_modules/bootstrap/dist/js/npm.js from dll-reference vendor_3d6b1ff2e706ed474586 42 bytes {0} [not cacheable] [built]
  [641] multi event-source-polyfill webpack-hot-middleware/client?path=%2F__webpack_hmr ./ClientApp/boot-client.ts 52 bytes {0}
     + 627 hidden modules

ERROR in [at-loader] ./ClientApp/app/components/finance/bank-import.component.ts:53:12 
    TS2300: Duplicate identifier 'finOpModalWindow'. (cc1db8ba)
2017-10-28T13:27:01.1911038+03:00 0HL8TTPFT6TGF [ERR] FundTrack.BLL.Concrete.BusinessLogicException: Неможливо отримати інформацію для рахунку ---> System.InvalidOperationException: Nullable object must have a value.
   at System.ThrowHelper.ThrowInvalidOperationException(ExceptionResource resource)
   at System.Nullable`1.get_Value()
   at FundTrack.BLL.Concrete.OrganizationAccountService.GetDonateCredentials(Int32 orgAccountId) in C:\FundTrack\FundTrack.BLL\Concrete\OrganizationAccountService.cs:line 354
   --- End of inner exception stack trace ---
   at FundTrack.BLL.Concrete.OrganizationAccountService.GetDonateCredentials(Int32 orgAccountId) in C:\FundTrack\FundTrack.BLL\Concrete\OrganizationAccountService.cs:line 365
   at FundTrack.WebUI.Controllers.OrgAccountController.GetDonateCredentials(Int32 orgAccountId) in C:\FundTrack\FundTrack.WebUI\Controllers\OrgAccountController.cs:line 82
   at lambda_method(Closure , Object , Object[] )
   at Microsoft.AspNetCore.Mvc.Internal.ControllerActionInvoker.<InvokeActionMethodAsync>d__27.MoveNext()
--- End of stack trace from previous location where exception was thrown ---
   at System.Runtime.ExceptionServices.ExceptionDispatchInfo.Throw()
   at System.Runtime.CompilerServices.TaskAwaiter.HandleNonSuccessAndDebuggerNotification(Task task)
   at Microsoft.AspNetCore.Mvc.Internal.ControllerActionInvoker.<InvokeNextActionFilterAsync>d__25.MoveNext()
--- End of stack trace from previous location where exception was thrown ---
   at System.Runtime.ExceptionServices.ExceptionDispatchInfo.Throw()
   at Microsoft.AspNetCore.Mvc.Internal.ControllerActionInvoker.Rethrow(ActionExecutedContext context)
   at Microsoft.AspNetCore.Mvc.Internal.ControllerActionInvoker.Next(State& next, Scope& scope, Object& state, Boolean& isCompleted)
   at Microsoft.AspNetCore.Mvc.Internal.ControllerActionInvoker.<InvokeNextResourceFilter>d__22.MoveNext()
--- End of stack trace from previous location where exception was thrown ---
   at System.Runtime.ExceptionServices.ExceptionDispatchInfo.Throw()
   at Microsoft.AspNetCore.Mvc.Internal.ControllerActionInvoker.Rethrow(ResourceExecutedContext context)
   at Microsoft.AspNetCore.Mvc.Internal.ControllerActionInvoker.Next(State& next, Scope& scope, Object& state, Boolean& isCompleted)
   at Microsoft.AspNetCore.Mvc.Internal.ControllerActionInvoker.<InvokeAsync>d__20.MoveNext()
--- End of stack trace from previous location where exception was thrown ---
   at System.Runtime.ExceptionServices.ExceptionDispatchInfo.Throw()
   at System.Runtime.CompilerServices.TaskAwaiter.HandleNonSuccessAndDebuggerNotification(Task task)
   at Microsoft.AspNetCore.Builder.RouterMiddleware.<Invoke>d__4.MoveNext()
--- End of stack trace from previous location where exception was thrown ---
   at System.Runtime.ExceptionServices.ExceptionDispatchInfo.Throw()
   at System.Runtime.CompilerServices.TaskAwaiter.HandleNonSuccessAndDebuggerNotification(Task task)
   at Microsoft.AspNetCore.SpaServices.Webpack.ConditionalProxyMiddleware.<Invoke>d__5.MoveNext()
--- End of stack trace from previous location where exception was thrown ---
   at System.Runtime.ExceptionServices.ExceptionDispatchInfo.Throw()
   at System.Runtime.CompilerServices.TaskAwaiter.HandleNonSuccessAndDebuggerNotification(Task task)
   at Microsoft.AspNetCore.SpaServices.Webpack.ConditionalProxyMiddleware.<Invoke>d__5.MoveNext()
--- End of stack trace from previous location where exception was thrown ---
   at System.Runtime.ExceptionServices.ExceptionDispatchInfo.Throw()
   at System.Runtime.CompilerServices.TaskAwaiter.HandleNonSuccessAndDebuggerNotification(Task task)
   at Microsoft.AspNetCore.Authentication.AuthenticationMiddleware`1.<Invoke>d__18.MoveNext()
--- End of stack trace from previous location where exception was thrown ---
   at System.Runtime.ExceptionServices.ExceptionDispatchInfo.Throw()
   at Microsoft.AspNetCore.Authentication.AuthenticationMiddleware`1.<Invoke>d__18.MoveNext()
--- End of stack trace from previous location where exception was thrown ---
   at System.Runtime.ExceptionServices.ExceptionDispatchInfo.Throw()
   at System.Runtime.CompilerServices.TaskAwaiter.HandleNonSuccessAndDebuggerNotification(Task task)
   at System.Runtime.CompilerServices.TaskAwaiter.GetResult()
   at FundTrack.WebUI.Middlewares.GlobalErrorHandlingMiddleware.<Invoke>d__4.MoveNext() in C:\FundTrack\FundTrack.WebUI\Middlewares\GlobalErrorHandlingMiddleware.cs:line 28 (682b77bc)
2017-10-28T13:30:57.2639490+03:00 0HL8TTRHLAUVG [ERR] FundTrack.BLL.Concrete.BusinessLogicException: Неможливо отримати інформацію для рахунку ---> System.InvalidOperationException: Nullable object must have a value.
   at System.ThrowHelper.ThrowInvalidOperationException(ExceptionResource resource)
   at System.Nullable`1.get_Value()
   at FundTrack.BLL.Concrete.OrganizationAccountService.GetDonateCredentials(Int32 orgAccountId) in C:\FundTrack\FundTrack.BLL\Concrete\OrganizationAccountService.cs:line 354
   --- End of inner exception stack trace ---
   at FundTrack.BLL.Concrete.OrganizationAccountService.GetDonateCredentials(Int32 orgAccountId) in C:\FundTrack\FundTrack.BLL\Concrete\OrganizationAccountService.cs:line 365
   at FundTrack.WebUI.Controllers.OrgAccountController.GetDonateCredentials(Int32 orgAccountId) in C:\FundTrack\FundTrack.WebUI\Controllers\OrgAccountController.cs:line 82
   at lambda_method(Closure , Object , Object[] )
   at Microsoft.AspNetCore.Mvc.Internal.ControllerActionInvoker.<InvokeActionMethodAsync>d__27.MoveNext()
--- End of stack trace from previous location where exception was thrown ---
   at System.Runtime.ExceptionServices.ExceptionDispatchInfo.Throw()
   at System.Runtime.CompilerServices.TaskAwaiter.HandleNonSuccessAndDebuggerNotification(Task task)
   at Microsoft.AspNetCore.Mvc.Internal.ControllerActionInvoker.<InvokeNextActionFilterAsync>d__25.MoveNext()
--- End of stack trace from previous location where exception was thrown ---
   at System.Runtime.ExceptionServices.ExceptionDispatchInfo.Throw()
   at Microsoft.AspNetCore.Mvc.Internal.ControllerActionInvoker.Rethrow(ActionExecutedContext context)
   at Microsoft.AspNetCore.Mvc.Internal.ControllerActionInvoker.Next(State& next, Scope& scope, Object& state, Boolean& isCompleted)
   at Microsoft.AspNetCore.Mvc.Internal.ControllerActionInvoker.<InvokeNextResourceFilter>d__22.MoveNext()
--- End of stack trace from previous location where exception was thrown ---
   at System.Runtime.ExceptionServices.ExceptionDispatchInfo.Throw()
   at Microsoft.AspNetCore.Mvc.Internal.ControllerActionInvoker.Rethrow(ResourceExecutedContext context)
   at Microsoft.AspNetCore.Mvc.Internal.ControllerActionInvoker.Next(State& next, Scope& scope, Object& state, Boolean& isCompleted)
   at Microsoft.AspNetCore.Mvc.Internal.ControllerActionInvoker.<InvokeAsync>d__20.MoveNext()
--- End of stack trace from previous location where exception was thrown ---
   at System.Runtime.ExceptionServices.ExceptionDispatchInfo.Throw()
   at System.Runtime.CompilerServices.TaskAwaiter.HandleNonSuccessAndDebuggerNotification(Task task)
   at Microsoft.AspNetCore.Builder.RouterMiddleware.<Invoke>d__4.MoveNext()
--- End of stack trace from previous location where exception was thrown ---
   at System.Runtime.ExceptionServices.ExceptionDispatchInfo.Throw()
   at System.Runtime.CompilerServices.TaskAwaiter.HandleNonSuccessAndDebuggerNotification(Task task)
   at Microsoft.AspNetCore.SpaServices.Webpack.ConditionalProxyMiddleware.<Invoke>d__5.MoveNext()
--- End of stack trace from previous location where exception was thrown ---
   at System.Runtime.ExceptionServices.ExceptionDispatchInfo.Throw()
   at System.Runtime.CompilerServices.TaskAwaiter.HandleNonSuccessAndDebuggerNotification(Task task)
   at Microsoft.AspNetCore.SpaServices.Webpack.ConditionalProxyMiddleware.<Invoke>d__5.MoveNext()
--- End of stack trace from previous location where exception was thrown ---
   at System.Runtime.ExceptionServices.ExceptionDispatchInfo.Throw()
   at System.Runtime.CompilerServices.TaskAwaiter.HandleNonSuccessAndDebuggerNotification(Task task)
   at Microsoft.AspNetCore.Authentication.AuthenticationMiddleware`1.<Invoke>d__18.MoveNext()
--- End of stack trace from previous location where exception was thrown ---
   at System.Runtime.ExceptionServices.ExceptionDispatchInfo.Throw()
   at Microsoft.AspNetCore.Authentication.AuthenticationMiddleware`1.<Invoke>d__18.MoveNext()
--- End of stack trace from previous location where exception was thrown ---
   at System.Runtime.ExceptionServices.ExceptionDispatchInfo.Throw()
   at System.Runtime.CompilerServices.TaskAwaiter.HandleNonSuccessAndDebuggerNotification(Task task)
   at System.Runtime.CompilerServices.TaskAwaiter.GetResult()
   at FundTrack.WebUI.Middlewares.GlobalErrorHandlingMiddleware.<Invoke>d__4.MoveNext() in C:\FundTrack\FundTrack.WebUI\Middlewares\GlobalErrorHandlingMiddleware.cs:line 28 (682b77bc)
2017-10-28T13:32:41.4377066+03:00 0HL8TTRHLAV29 [ERR] FundTrack.BLL.Concrete.BusinessLogicException: Неможливо отримати інформацію для рахунку ---> System.InvalidOperationException: Nullable object must have a value.
   at System.ThrowHelper.ThrowInvalidOperationException(ExceptionResource resource)
   at System.Nullable`1.get_Value()
   at FundTrack.BLL.Concrete.OrganizationAccountService.GetDonateCredentials(Int32 orgAccountId) in C:\FundTrack\FundTrack.BLL\Concrete\OrganizationAccountService.cs:line 354
   --- End of inner exception stack trace ---
   at FundTrack.BLL.Concrete.OrganizationAccountService.GetDonateCredentials(Int32 orgAccountId) in C:\FundTrack\FundTrack.BLL\Concrete\OrganizationAccountService.cs:line 365
   at FundTrack.WebUI.Controllers.OrgAccountController.GetDonateCredentials(Int32 orgAccountId) in C:\FundTrack\FundTrack.WebUI\Controllers\OrgAccountController.cs:line 82
   at lambda_method(Closure , Object , Object[] )
   at Microsoft.AspNetCore.Mvc.Internal.ControllerActionInvoker.<InvokeActionMethodAsync>d__27.MoveNext()
--- End of stack trace from previous location where exception was thrown ---
   at System.Runtime.ExceptionServices.ExceptionDispatchInfo.Throw()
   at System.Runtime.CompilerServices.TaskAwaiter.HandleNonSuccessAndDebuggerNotification(Task task)
   at Microsoft.AspNetCore.Mvc.Internal.ControllerActionInvoker.<InvokeNextActionFilterAsync>d__25.MoveNext()
--- End of stack trace from previous location where exception was thrown ---
   at System.Runtime.ExceptionServices.ExceptionDispatchInfo.Throw()
   at Microsoft.AspNetCore.Mvc.Internal.ControllerActionInvoker.Rethrow(ActionExecutedContext context)
   at Microsoft.AspNetCore.Mvc.Internal.ControllerActionInvoker.Next(State& next, Scope& scope, Object& state, Boolean& isCompleted)
   at Microsoft.AspNetCore.Mvc.Internal.ControllerActionInvoker.<InvokeNextResourceFilter>d__22.MoveNext()
--- End of stack trace from previous location where exception was thrown ---
   at System.Runtime.ExceptionServices.ExceptionDispatchInfo.Throw()
   at Microsoft.AspNetCore.Mvc.Internal.ControllerActionInvoker.Rethrow(ResourceExecutedContext context)
   at Microsoft.AspNetCore.Mvc.Internal.ControllerActionInvoker.Next(State& next, Scope& scope, Object& state, Boolean& isCompleted)
   at Microsoft.AspNetCore.Mvc.Internal.ControllerActionInvoker.<InvokeAsync>d__20.MoveNext()
--- End of stack trace from previous location where exception was thrown ---
   at System.Runtime.ExceptionServices.ExceptionDispatchInfo.Throw()
   at System.Runtime.CompilerServices.TaskAwaiter.HandleNonSuccessAndDebuggerNotification(Task task)
   at Microsoft.AspNetCore.Builder.RouterMiddleware.<Invoke>d__4.MoveNext()
--- End of stack trace from previous location where exception was thrown ---
   at System.Runtime.ExceptionServices.ExceptionDispatchInfo.Throw()
   at System.Runtime.CompilerServices.TaskAwaiter.HandleNonSuccessAndDebuggerNotification(Task task)
   at Microsoft.AspNetCore.SpaServices.Webpack.ConditionalProxyMiddleware.<Invoke>d__5.MoveNext()
--- End of stack trace from previous location where exception was thrown ---
   at System.Runtime.ExceptionServices.ExceptionDispatchInfo.Throw()
   at System.Runtime.CompilerServices.TaskAwaiter.HandleNonSuccessAndDebuggerNotification(Task task)
   at Microsoft.AspNetCore.SpaServices.Webpack.ConditionalProxyMiddleware.<Invoke>d__5.MoveNext()
--- End of stack trace from previous location where exception was thrown ---
   at System.Runtime.ExceptionServices.ExceptionDispatchInfo.Throw()
   at System.Runtime.CompilerServices.TaskAwaiter.HandleNonSuccessAndDebuggerNotification(Task task)
   at Microsoft.AspNetCore.Authentication.AuthenticationMiddleware`1.<Invoke>d__18.MoveNext()
--- End of stack trace from previous location where exception was thrown ---
   at System.Runtime.ExceptionServices.ExceptionDispatchInfo.Throw()
   at Microsoft.AspNetCore.Authentication.AuthenticationMiddleware`1.<Invoke>d__18.MoveNext()
--- End of stack trace from previous location where exception was thrown ---
   at System.Runtime.ExceptionServices.ExceptionDispatchInfo.Throw()
   at System.Runtime.CompilerServices.TaskAwaiter.HandleNonSuccessAndDebuggerNotification(Task task)
   at System.Runtime.CompilerServices.TaskAwaiter.GetResult()
   at FundTrack.WebUI.Middlewares.GlobalErrorHandlingMiddleware.<Invoke>d__4.MoveNext() in C:\FundTrack\FundTrack.WebUI\Middlewares\GlobalErrorHandlingMiddleware.cs:line 28 (682b77bc)
2017-10-28T13:44:16.2515043+03:00 0HL8TTRHLAV7R [ERR] An exception occurred in the database while iterating the results of a query.
 (3b5ca34b)
System.InvalidOperationException: An exception has been raised that is likely due to a transient failure. If you are connecting to a SQL Azure database consider using SqlAzureExecutionStrategy. ---> System.Data.SqlClient.SqlException: A connection was successfully established with the server, but then an error occurred during the login process. (provider: SSL Provider, error: 0 - An existing connection was forcibly closed by the remote host.) ---> System.ComponentModel.Win32Exception: An existing connection was forcibly closed by the remote host
   --- End of inner exception stack trace ---
   at System.Data.ProviderBase.DbConnectionPool.TryGetConnection(DbConnection owningObject, UInt32 waitForMultipleObjectsTimeout, Boolean allowCreate, Boolean onlyOneCheckConnection, DbConnectionOptions userOptions, DbConnectionInternal& connection)
   at System.Data.ProviderBase.DbConnectionPool.TryGetConnection(DbConnection owningObject, TaskCompletionSource`1 retry, DbConnectionOptions userOptions, DbConnectionInternal& connection)
   at System.Data.ProviderBase.DbConnectionFactory.TryGetConnection(DbConnection owningConnection, TaskCompletionSource`1 retry, DbConnectionOptions userOptions, DbConnectionInternal oldConnection, DbConnectionInternal& connection)
   at System.Data.ProviderBase.DbConnectionInternal.TryOpenConnectionInternal(DbConnection outerConnection, DbConnectionFactory connectionFactory, TaskCompletionSource`1 retry, DbConnectionOptions userOptions)
   at System.Data.SqlClient.SqlConnection.TryOpen(TaskCompletionSource`1 retry)
   at System.Data.SqlClient.SqlConnection.Open()
   at Microsoft.EntityFrameworkCore.Storage.RelationalConnection.Open()
   at Microsoft.EntityFrameworkCore.Query.Internal.QueryingEnumerable.Enumerator.BufferlessMoveNext(Boolean buffer)
   at Microsoft.EntityFrameworkCore.Storage.Internal.SqlServerExecutionStrategy.Execute[TState,TResult](Func`2 operation, Func`2 verifySucceeded, TState state)
   --- End of inner exception stack trace ---
   at Microsoft.EntityFrameworkCore.Storage.Internal.SqlServerExecutionStrategy.Execute[TState,TResult](Func`2 operation, Func`2 verifySucceeded, TState state)
   at Microsoft.EntityFrameworkCore.Query.QueryMethodProvider.<_ShapedQuery>d__3`1.MoveNext()
   at Microsoft.EntityFrameworkCore.Query.Internal.LinqOperatorProvider.<_TrackEntities>d__15`2.MoveNext()
   at Microsoft.EntityFrameworkCore.Query.Internal.LinqOperatorProvider.ExceptionInterceptor`1.EnumeratorExceptionInterceptor.MoveNext()
   at System.Linq.Enumerable.WhereSelectEnumerableIterator`2.MoveNext()
   at System.Collections.Generic.List`1..ctor(IEnumerable`1 collection)
   at System.Linq.Enumerable.ToList[TSource](IEnumerable`1 source)
   at FundTrack.BLL.Concrete.TargetService.ConvertTargetsToTargetViewModel(IEnumerable`1 targets) in C:\FundTrack\FundTrack.BLL\Concrete\TargetService.cs:line 63
   at FundTrack.BLL.Concrete.TargetService.GetTargets(Int32 orgId, Int32 parentTargetId) in C:\FundTrack\FundTrack.BLL\Concrete\TargetService.cs:line 243
2017-10-28T13:44:16.2625340+03:00 0HL8TTRHLAV7T [ERR] An exception occurred in the database while iterating the results of a query.
 (3b5ca34b)
System.InvalidOperationException: An exception has been raised that is likely due to a transient failure. If you are connecting to a SQL Azure database consider using SqlAzureExecutionStrategy. ---> System.Data.SqlClient.SqlException: A connection was successfully established with the server, but then an error occurred during the login process. (provider: SSL Provider, error: 0 - An existing connection was forcibly closed by the remote host.) ---> System.ComponentModel.Win32Exception: An existing connection was forcibly closed by the remote host
   --- End of inner exception stack trace ---
   at System.Data.ProviderBase.DbConnectionPool.TryGetConnection(DbConnection owningObject, UInt32 waitForMultipleObjectsTimeout, Boolean allowCreate, Boolean onlyOneCheckConnection, DbConnectionOptions userOptions, DbConnectionInternal& connection)
   at System.Data.ProviderBase.DbConnectionPool.TryGetConnection(DbConnection owningObject, TaskCompletionSource`1 retry, DbConnectionOptions userOptions, DbConnectionInternal& connection)
   at System.Data.ProviderBase.DbConnectionFactory.TryGetConnection(DbConnection owningConnection, TaskCompletionSource`1 retry, DbConnectionOptions userOptions, DbConnectionInternal oldConnection, DbConnectionInternal& connection)
   at System.Data.ProviderBase.DbConnectionInternal.TryOpenConnectionInternal(DbConnection outerConnection, DbConnectionFactory connectionFactory, TaskCompletionSource`1 retry, DbConnectionOptions userOptions)
   at System.Data.SqlClient.SqlConnection.TryOpen(TaskCompletionSource`1 retry)
   at System.Data.SqlClient.SqlConnection.Open()
   at Microsoft.EntityFrameworkCore.Storage.RelationalConnection.Open()
   at Microsoft.EntityFrameworkCore.Query.Internal.QueryingEnumerable.Enumerator.BufferlessMoveNext(Boolean buffer)
   at Microsoft.EntityFrameworkCore.Storage.Internal.SqlServerExecutionStrategy.Execute[TState,TResult](Func`2 operation, Func`2 verifySucceeded, TState state)
   --- End of inner exception stack trace ---
   at Microsoft.EntityFrameworkCore.Storage.Internal.SqlServerExecutionStrategy.Execute[TState,TResult](Func`2 operation, Func`2 verifySucceeded, TState state)
   at Microsoft.EntityFrameworkCore.Query.QueryMethodProvider.<_ShapedQuery>d__3`1.MoveNext()
   at Microsoft.EntityFrameworkCore.Query.QueryMethodProvider.<_Include>d__30`1.MoveNext()
   at System.Linq.Enumerable.SelectEnumerableIterator`2.MoveNext()
   at System.Linq.Enumerable.FirstOrDefault[TSource](IEnumerable`1 source)
   at lambda_method(Closure , QueryContext )
   at Microsoft.EntityFrameworkCore.Query.Internal.QueryCompiler.<>c__DisplayClass20_0`1.<CompileQueryCore>b__0(QueryContext qc)
   at System.Linq.Queryable.FirstOrDefault[TSource](IQueryable`1 source, Expression`1 predicate)
   at FundTrack.DAL.Concrete.OrganizationAccountRepository.GetOrgAccountByCardNumber(Int32 orgId, String card) in C:\FundTrack\FundTrack.DAL\Concrete\OrganizationAccountRepository.cs:line 93
   at FundTrack.BLL.Concrete.OrganizationAccountService.GetAccountForSelect(Int32 organizationId, String card) in C:\FundTrack\FundTrack.BLL\Concrete\OrganizationAccountService.cs:line 294
2017-10-28T13:44:16.2850965+03:00 0HL8TTRHLAV7S [ERR] An exception occurred in the database while iterating the results of a query.
 (3b5ca34b)
System.InvalidOperationException: An exception has been raised that is likely due to a transient failure. If you are connecting to a SQL Azure database consider using SqlAzureExecutionStrategy. ---> System.Data.SqlClient.SqlException: A connection was successfully established with the server, but then an error occurred during the login process. (provider: SSL Provider, error: 0 - An existing connection was forcibly closed by the remote host.) ---> System.ComponentModel.Win32Exception: An existing connection was forcibly closed by the remote host
   --- End of inner exception stack trace ---
   at System.Data.ProviderBase.DbConnectionPool.TryGetConnection(DbConnection owningObject, UInt32 waitForMultipleObjectsTimeout, Boolean allowCreate, Boolean onlyOneCheckConnection, DbConnectionOptions userOptions, DbConnectionInternal& connection)
   at System.Data.ProviderBase.DbConnectionPool.TryGetConnection(DbConnection owningObject, TaskCompletionSource`1 retry, DbConnectionOptions userOptions, DbConnectionInternal& connection)
   at System.Data.ProviderBase.DbConnectionFactory.TryGetConnection(DbConnection owningConnection, TaskCompletionSource`1 retry, DbConnectionOptions userOptions, DbConnectionInternal oldConnection, DbConnectionInternal& connection)
   at System.Data.ProviderBase.DbConnectionInternal.TryOpenConnectionInternal(DbConnection outerConnection, DbConnectionFactory connectionFactory, TaskCompletionSource`1 retry, DbConnectionOptions userOptions)
   at System.Data.SqlClient.SqlConnection.TryOpen(TaskCompletionSource`1 retry)
   at System.Data.SqlClient.SqlConnection.Open()
   at Microsoft.EntityFrameworkCore.Storage.RelationalConnection.Open()
   at Microsoft.EntityFrameworkCore.Query.Internal.QueryingEnumerable.Enumerator.BufferlessMoveNext(Boolean buffer)
   at Microsoft.EntityFrameworkCore.Storage.Internal.SqlServerExecutionStrategy.Execute[TState,TResult](Func`2 operation, Func`2 verifySucceeded, TState state)
   --- End of inner exception stack trace ---
   at Microsoft.EntityFrameworkCore.Storage.Internal.SqlServerExecutionStrategy.Execute[TState,TResult](Func`2 operation, Func`2 verifySucceeded, TState state)
   at Microsoft.EntityFrameworkCore.Query.QueryMethodProvider.<_ShapedQuery>d__3`1.MoveNext()
   at Microsoft.EntityFrameworkCore.Query.Internal.LinqOperatorProvider.<_TrackEntities>d__15`2.MoveNext()
   at Microsoft.EntityFrameworkCore.Query.Internal.LinqOperatorProvider.ExceptionInterceptor`1.EnumeratorExceptionInterceptor.MoveNext()
   at System.Linq.Enumerable.SelectEnumerableIterator`2.MoveNext()
   at Newtonsoft.Json.Serialization.JsonSerializerInternalWriter.SerializeList(JsonWriter writer, IEnumerable values, JsonArrayContract contract, JsonProperty member, JsonContainerContract collectionContract, JsonProperty containerProperty)
   at Newtonsoft.Json.Serialization.JsonSerializerInternalWriter.Serialize(JsonWriter jsonWriter, Object value, Type objectType)
2017-10-28T13:44:16.2941205+03:00 0HL8TTRHLAV7R [ERR] FundTrack.BLL.Concrete.BusinessLogicException: An exception has been raised that is likely due to a transient failure. If you are connecting to a SQL Azure database consider using SqlAzureExecutionStrategy. ---> System.InvalidOperationException: An exception has been raised that is likely due to a transient failure. If you are connecting to a SQL Azure database consider using SqlAzureExecutionStrategy. ---> System.Data.SqlClient.SqlException: A connection was successfully established with the server, but then an error occurred during the login process. (provider: SSL Provider, error: 0 - An existing connection was forcibly closed by the remote host.) ---> System.ComponentModel.Win32Exception: An existing connection was forcibly closed by the remote host
   --- End of inner exception stack trace ---
   at System.Data.ProviderBase.DbConnectionPool.TryGetConnection(DbConnection owningObject, UInt32 waitForMultipleObjectsTimeout, Boolean allowCreate, Boolean onlyOneCheckConnection, DbConnectionOptions userOptions, DbConnectionInternal& connection)
   at System.Data.ProviderBase.DbConnectionPool.TryGetConnection(DbConnection owningObject, TaskCompletionSource`1 retry, DbConnectionOptions userOptions, DbConnectionInternal& connection)
   at System.Data.ProviderBase.DbConnectionFactory.TryGetConnection(DbConnection owningConnection, TaskCompletionSource`1 retry, DbConnectionOptions userOptions, DbConnectionInternal oldConnection, DbConnectionInternal& connection)
   at System.Data.ProviderBase.DbConnectionInternal.TryOpenConnectionInternal(DbConnection outerConnection, DbConnectionFactory connectionFactory, TaskCompletionSource`1 retry, DbConnectionOptions userOptions)
   at System.Data.SqlClient.SqlConnection.TryOpen(TaskCompletionSource`1 retry)
   at System.Data.SqlClient.SqlConnection.Open()
   at Microsoft.EntityFrameworkCore.Storage.RelationalConnection.Open()
   at Microsoft.EntityFrameworkCore.Query.Internal.QueryingEnumerable.Enumerator.BufferlessMoveNext(Boolean buffer)
   at Microsoft.EntityFrameworkCore.Storage.Internal.SqlServerExecutionStrategy.Execute[TState,TResult](Func`2 operation, Func`2 verifySucceeded, TState state)
   --- End of inner exception stack trace ---
   at Microsoft.EntityFrameworkCore.Storage.Internal.SqlServerExecutionStrategy.Execute[TState,TResult](Func`2 operation, Func`2 verifySucceeded, TState state)
   at Microsoft.EntityFrameworkCore.Query.QueryMethodProvider.<_ShapedQuery>d__3`1.MoveNext()
   at Microsoft.EntityFrameworkCore.Query.Internal.LinqOperatorProvider.<_TrackEntities>d__15`2.MoveNext()
   at Microsoft.EntityFrameworkCore.Query.Internal.LinqOperatorProvider.ExceptionInterceptor`1.EnumeratorExceptionInterceptor.MoveNext()
   at System.Linq.Enumerable.WhereSelectEnumerableIterator`2.MoveNext()
   at System.Collections.Generic.List`1..ctor(IEnumerable`1 collection)
   at System.Linq.Enumerable.ToList[TSource](IEnumerable`1 source)
   at FundTrack.BLL.Concrete.TargetService.ConvertTargetsToTargetViewModel(IEnumerable`1 targets) in C:\FundTrack\FundTrack.BLL\Concrete\TargetService.cs:line 63
   at FundTrack.BLL.Concrete.TargetService.GetTargets(Int32 orgId, Int32 parentTargetId) in C:\FundTrack\FundTrack.BLL\Concrete\TargetService.cs:line 243
   --- End of inner exception stack trace ---
   at FundTrack.BLL.Concrete.TargetService.GetTargets(Int32 orgId, Int32 parentTargetId) in C:\FundTrack\FundTrack.BLL\Concrete\TargetService.cs:line 247
   at FundTrack.WebUI.Controllers.TargetController.GetParentTargets(Int32 orgId) in C:\FundTrack\FundTrack.WebUI\Controllers\TargetController.cs:line 63
   at lambda_method(Closure , Object , Object[] )
   at Microsoft.AspNetCore.Mvc.Internal.ControllerActionInvoker.<InvokeActionMethodAsync>d__27.MoveNext()
--- End of stack trace from previous location where exception was thrown ---
   at System.Runtime.ExceptionServices.ExceptionDispatchInfo.Throw()
   at System.Runtime.CompilerServices.TaskAwaiter.HandleNonSuccessAndDebuggerNotification(Task task)
   at Microsoft.AspNetCore.Mvc.Internal.ControllerActionInvoker.<InvokeNextActionFilterAsync>d__25.MoveNext()
--- End of stack trace from previous location where exception was thrown ---
   at System.Runtime.ExceptionServices.ExceptionDispatchInfo.Throw()
   at Microsoft.AspNetCore.Mvc.Internal.ControllerActionInvoker.Rethrow(ActionExecutedContext context)
   at Microsoft.AspNetCore.Mvc.Internal.ControllerActionInvoker.Next(State& next, Scope& scope, Object& state, Boolean& isCompleted)
   at Microsoft.AspNetCore.Mvc.Internal.ControllerActionInvoker.<InvokeNextResourceFilter>d__22.MoveNext()
--- End of stack trace from previous location where exception was thrown ---
   at System.Runtime.ExceptionServices.ExceptionDispatchInfo.Throw()
   at Microsoft.AspNetCore.Mvc.Internal.ControllerActionInvoker.Rethrow(ResourceExecutedContext context)
   at Microsoft.AspNetCore.Mvc.Internal.ControllerActionInvoker.Next(State& next, Scope& scope, Object& state, Boolean& isCompleted)
   at Microsoft.AspNetCore.Mvc.Internal.ControllerActionInvoker.<InvokeAsync>d__20.MoveNext()
--- End of stack trace from previous location where exception was thrown ---
   at System.Runtime.ExceptionServices.ExceptionDispatchInfo.Throw()
   at System.Runtime.CompilerServices.TaskAwaiter.HandleNonSuccessAndDebuggerNotification(Task task)
   at Microsoft.AspNetCore.Builder.RouterMiddleware.<Invoke>d__4.MoveNext()
--- End of stack trace from previous location where exception was thrown ---
   at System.Runtime.ExceptionServices.ExceptionDispatchInfo.Throw()
   at System.Runtime.CompilerServices.TaskAwaiter.HandleNonSuccessAndDebuggerNotification(Task task)
   at Microsoft.AspNetCore.SpaServices.Webpack.ConditionalProxyMiddleware.<Invoke>d__5.MoveNext()
--- End of stack trace from previous location where exception was thrown ---
   at System.Runtime.ExceptionServices.ExceptionDispatchInfo.Throw()
   at System.Runtime.CompilerServices.TaskAwaiter.HandleNonSuccessAndDebuggerNotification(Task task)
   at Microsoft.AspNetCore.SpaServices.Webpack.ConditionalProxyMiddleware.<Invoke>d__5.MoveNext()
--- End of stack trace from previous location where exception was thrown ---
   at System.Runtime.ExceptionServices.ExceptionDispatchInfo.Throw()
   at System.Runtime.CompilerServices.TaskAwaiter.HandleNonSuccessAndDebuggerNotification(Task task)
   at Microsoft.AspNetCore.Authentication.AuthenticationMiddleware`1.<Invoke>d__18.MoveNext()
--- End of stack trace from previous location where exception was thrown ---
   at System.Runtime.ExceptionServices.ExceptionDispatchInfo.Throw()
   at Microsoft.AspNetCore.Authentication.AuthenticationMiddleware`1.<Invoke>d__18.MoveNext()
--- End of stack trace from previous location where exception was thrown ---
   at System.Runtime.ExceptionServices.ExceptionDispatchInfo.Throw()
   at System.Runtime.CompilerServices.TaskAwaiter.HandleNonSuccessAndDebuggerNotification(Task task)
   at System.Runtime.CompilerServices.TaskAwaiter.GetResult()
   at FundTrack.WebUI.Middlewares.GlobalErrorHandlingMiddleware.<Invoke>d__4.MoveNext() in C:\FundTrack\FundTrack.WebUI\Middlewares\GlobalErrorHandlingMiddleware.cs:line 28 (a232b052)
2017-10-28T13:44:16.3021422+03:00 0HL8TTRHLAV7T [ERR] Connection id ""0HL8TTRHKCB80"": An unhandled exception was thrown by the application. (8c14976b)
System.IO.IOException: The process cannot access the file 'C:\FundTrack\FundTrack.WebUI\Middlewares\Logging\28.10.2017_Exception_Logs.txt' because it is being used by another process.
   at System.IO.Win32FileStream..ctor(String path, FileMode mode, FileAccess access, FileShare share, Int32 bufferSize, FileOptions options, FileStream parent)
   at System.IO.Win32FileSystem.Open(String fullPath, FileMode mode, FileAccess access, FileShare share, Int32 bufferSize, FileOptions options, FileStream parent)
   at System.IO.FileStream.Init(String path, FileMode mode, FileAccess access, FileShare share, Int32 bufferSize, FileOptions options)
   at System.IO.FileStream..ctor(String path, FileMode mode)
   at FundTrack.WebUI.Middlewares.Logging.ErrorLogger.WriteErrorLogInFile(Exception ex) in C:\FundTrack\FundTrack.WebUI\Middlewares\Logging\LoggingMiddleware.cs:line 20
   at FundTrack.WebUI.Middlewares.GlobalErrorHandlingMiddleware.<Invoke>d__4.MoveNext() in C:\FundTrack\FundTrack.WebUI\Middlewares\GlobalErrorHandlingMiddleware.cs:line 44
--- End of stack trace from previous location where exception was thrown ---
   at System.Runtime.ExceptionServices.ExceptionDispatchInfo.Throw()
   at System.Runtime.CompilerServices.TaskAwaiter.HandleNonSuccessAndDebuggerNotification(Task task)
   at Microsoft.AspNetCore.Server.IISIntegration.IISMiddleware.<Invoke>d__8.MoveNext()
--- End of stack trace from previous location where exception was thrown ---
   at System.Runtime.ExceptionServices.ExceptionDispatchInfo.Throw()
   at System.Runtime.CompilerServices.TaskAwaiter.HandleNonSuccessAndDebuggerNotification(Task task)
   at Microsoft.AspNetCore.Hosting.Internal.RequestServicesContainerMiddleware.<Invoke>d__3.MoveNext()
--- End of stack trace from previous location where exception was thrown ---
   at System.Runtime.ExceptionServices.ExceptionDispatchInfo.Throw()
   at System.Runtime.CompilerServices.TaskAwaiter.HandleNonSuccessAndDebuggerNotification(Task task)
   at Microsoft.AspNetCore.Server.Kestrel.Internal.Http.Frame`1.<RequestProcessingAsync>d__2.MoveNext()
2017-10-28T13:44:16.3683236+03:00 0HL8TTRHLAV7O [ERR] An exception occurred in the database while iterating the results of a query.
 (3b5ca34b)
System.InvalidOperationException: An exception has been raised that is likely due to a transient failure. If you are connecting to a SQL Azure database consider using SqlAzureExecutionStrategy. ---> System.Data.SqlClient.SqlException: A connection was successfully established with the server, but then an error occurred during the login process. (provider: SSL Provider, error: 0 - An existing connection was forcibly closed by the remote host.) ---> System.ComponentModel.Win32Exception: An existing connection was forcibly closed by the remote host
   --- End of inner exception stack trace ---
   at System.Data.SqlClient.SqlInternalConnectionTds..ctor(DbConnectionPoolIdentity identity, SqlConnectionString connectionOptions, Object providerInfo, Boolean redirectedUserInstance, SqlConnectionString userConnectionOptions, SessionData reconnectSessionData, Boolean applyTransientFaultHandling)
   at System.Data.SqlClient.SqlConnectionFactory.CreateConnection(DbConnectionOptions options, DbConnectionPoolKey poolKey, Object poolGroupProviderInfo, DbConnectionPool pool, DbConnection owningConnection, DbConnectionOptions userOptions)
   at System.Data.ProviderBase.DbConnectionFactory.CreatePooledConnection(DbConnectionPool pool, DbConnection owningObject, DbConnectionOptions options, DbConnectionPoolKey poolKey, DbConnectionOptions userOptions)
   at System.Data.ProviderBase.DbConnectionPool.CreateObject(DbConnection owningObject, DbConnectionOptions userOptions, DbConnectionInternal oldConnection)
   at System.Data.ProviderBase.DbConnectionPool.UserCreateRequest(DbConnection owningObject, DbConnectionOptions userOptions, DbConnectionInternal oldConnection)
   at System.Data.ProviderBase.DbConnectionPool.TryGetConnection(DbConnection owningObject, UInt32 waitForMultipleObjectsTimeout, Boolean allowCreate, Boolean onlyOneCheckConnection, DbConnectionOptions userOptions, DbConnectionInternal& connection)
   at System.Data.ProviderBase.DbConnectionPool.TryGetConnection(DbConnection owningObject, TaskCompletionSource`1 retry, DbConnectionOptions userOptions, DbConnectionInternal& connection)
   at System.Data.ProviderBase.DbConnectionFactory.TryGetConnection(DbConnection owningConnection, TaskCompletionSource`1 retry, DbConnectionOptions userOptions, DbConnectionInternal oldConnection, DbConnectionInternal& connection)
   at System.Data.ProviderBase.DbConnectionInternal.TryOpenConnectionInternal(DbConnection outerConnection, DbConnectionFactory connectionFactory, TaskCompletionSource`1 retry, DbConnectionOptions userOptions)
   at System.Data.SqlClient.SqlConnection.TryOpen(TaskCompletionSource`1 retry)
   at System.Data.SqlClient.SqlConnection.Open()
   at Microsoft.EntityFrameworkCore.Storage.RelationalConnection.Open()
   at Microsoft.EntityFrameworkCore.Query.Internal.QueryingEnumerable.Enumerator.BufferlessMoveNext(Boolean buffer)
   at Microsoft.EntityFrameworkCore.Storage.Internal.SqlServerExecutionStrategy.Execute[TState,TResult](Func`2 operation, Func`2 verifySucceeded, TState state)
   --- End of inner exception stack trace ---
   at Microsoft.EntityFrameworkCore.Storage.Internal.SqlServerExecutionStrategy.Execute[TState,TResult](Func`2 operation, Func`2 verifySucceeded, TState state)
   at Microsoft.EntityFrameworkCore.Query.QueryMethodProvider.<_ShapedQuery>d__3`1.MoveNext()
   at Microsoft.EntityFrameworkCore.Query.QueryMethodProvider.<_Include>d__30`1.MoveNext()
   at Microsoft.EntityFrameworkCore.Query.Internal.LinqOperatorProvider.<_TrackEntities>d__15`2.MoveNext()
   at Microsoft.EntityFrameworkCore.Query.Internal.LinqOperatorProvider.ExceptionInterceptor`1.EnumeratorExceptionInterceptor.MoveNext()
   at System.Linq.Enumerable.WhereSelectEnumerableIterator`2.MoveNext()
   at Newtonsoft.Json.Serialization.JsonSerializerInternalWriter.SerializeList(JsonWriter writer, IEnumerable values, JsonArrayContract contract, JsonProperty member, JsonContainerContract collectionContract, JsonProperty containerProperty)
   at Newtonsoft.Json.Serialization.JsonSerializerInternalWriter.Serialize(JsonWriter jsonWriter, Object value, Type objectType)
   at Newtonsoft.Json.JsonSerializer.SerializeInternal(JsonWriter jsonWriter, Object value, Type objectType)
   at Microsoft.AspNetCore.Mvc.Formatters.JsonOutputFormatter.WriteObject(TextWriter writer, Object value)
   at Microsoft.AspNetCore.Mvc.Formatters.JsonOutputFormatter.<WriteResponseBodyAsync>d__11.MoveNext()
--- End of stack trace from previous location where exception was thrown ---
   at System.Runtime.ExceptionServices.ExceptionDispatchInfo.Throw()
   at System.Runtime.CompilerServices.TaskAwaiter.HandleNonSuccessAndDebuggerNotification(Task task)
   at Microsoft.AspNetCore.Mvc.Internal.ControllerActionInvoker.<InvokeResultAsync>d__30.MoveNext()
--- End of stack trace from previous location where exception was thrown ---
   at System.Runtime.ExceptionServices.ExceptionDispatchInfo.Throw()
   at System.Runtime.CompilerServices.TaskAwaiter.HandleNonSuccessAndDebuggerNotification(Task task)
   at Microsoft.AspNetCore.Mvc.Internal.ControllerActionInvoker.<InvokeNextResultFilterAsync>d__28.MoveNext()
--- End of stack trace from previous location where exception was thrown ---
   at System.Runtime.ExceptionServices.ExceptionDispatchInfo.Throw()
   at Microsoft.AspNetCore.Mvc.Internal.ControllerActionInvoker.Rethrow(ResultExecutedContext context)
   at Microsoft.AspNetCore.Mvc.Internal.ControllerActionInvoker.Next(State& next, Scope& scope, Object& state, Boolean& isCompleted)
   at Microsoft.AspNetCore.Mvc.Internal.ControllerActionInvoker.<InvokeNextResourceFilter>d__22.MoveNext()
--- End of stack trace from previous location where exception was thrown ---
   at System.Runtime.ExceptionServices.ExceptionDispatchInfo.Throw()
   at Microsoft.AspNetCore.Mvc.Internal.ControllerActionInvoker.Rethrow(ResourceExecutedContext context)
   at Microsoft.AspNetCore.Mvc.Internal.ControllerActionInvoker.Next(State& next, Scope& scope, Object& state, Boolean& isCompleted)
   at Microsoft.AspNetCore.Mvc.Internal.ControllerActionInvoker.<InvokeAsync>d__20.MoveNext()
--- End of stack trace from previous location where exception was thrown ---
   at System.Runtime.ExceptionServices.ExceptionDispatchInfo.Throw()
   at System.Runtime.CompilerServices.TaskAwaiter.HandleNonSuccessAndDebuggerNotification(Task task)
   at Microsoft.AspNetCore.Builder.RouterMiddleware.<Invoke>d__4.MoveNext()
--- End of stack trace from previous location where exception was thrown ---
   at System.Runtime.ExceptionServices.ExceptionDispatchInfo.Throw()
   at System.Runtime.CompilerServices.TaskAwaiter.HandleNonSuccessAndDebuggerNotification(Task task)
   at Microsoft.AspNetCore.SpaServices.Webpack.ConditionalProxyMiddleware.<Invoke>d__5.MoveNext()
--- End of stack trace from previous location where exception was thrown ---
   at System.Runtime.ExceptionServices.ExceptionDispatchInfo.Throw()
   at System.Runtime.CompilerServices.TaskAwaiter.HandleNonSuccessAndDebuggerNotification(Task task)
   at Microsoft.AspNetCore.SpaServices.Webpack.ConditionalProxyMiddleware.<Invoke>d__5.MoveNext()
--- End of stack trace from previous location where exception was thrown ---
   at System.Runtime.ExceptionServices.ExceptionDispatchInfo.Throw()
   at System.Runtime.CompilerServices.TaskAwaiter.HandleNonSuccessAndDebuggerNotification(Task task)
   at Microsoft.AspNetCore.Authentication.AuthenticationMiddleware`1.<Invoke>d__18.MoveNext()
--- End of stack trace from previous location where exception was thrown ---
   at System.Runtime.ExceptionServices.ExceptionDispatchInfo.Throw()
   at Microsoft.AspNetCore.Authentication.AuthenticationMiddleware`1.<Invoke>d__18.MoveNext()
--- End of stack trace from previous location where exception was thrown ---
   at System.Runtime.ExceptionServices.ExceptionDispatchInfo.Throw()
   at System.Runtime.CompilerServices.TaskAwaiter.HandleNonSuccessAndDebuggerNotification(Task task)
   at System.Runtime.CompilerServices.TaskAwaiter.GetResult()
   at FundTrack.WebUI.Middlewares.GlobalErrorHandlingMiddleware.<Invoke>d__4.MoveNext() in C:\FundTrack\FundTrack.WebUI\Middlewares\GlobalErrorHandlingMiddleware.cs:line 28
2017-10-28T13:44:16.3713345+03:00 0HL8TTRHLAV7O [ERR] Connection id ""0HL8TTRHKCB7T"": An unhandled exception was thrown by the application. (8c14976b)
System.InvalidOperationException: Headers are read-only, response has already started.
   at Microsoft.AspNetCore.Server.Kestrel.Internal.Http.FrameHeaders.ThrowHeadersReadOnlyException()
   at Microsoft.AspNetCore.Server.Kestrel.Internal.Http.FrameHeaders.Microsoft.AspNetCore.Http.IHeaderDictionary.set_Item(String key, StringValues value)
   at Microsoft.AspNetCore.Http.Internal.DefaultHttpResponse.set_ContentType(String value)
   at FundTrack.WebUI.Middlewares.GlobalErrorHandlingMiddleware.<Invoke>d__4.MoveNext() in C:\FundTrack\FundTrack.WebUI\Middlewares\GlobalErrorHandlingMiddleware.cs:line 32
--- End of stack trace from previous location where exception was thrown ---
   at System.Runtime.ExceptionServices.ExceptionDispatchInfo.Throw()
   at System.Runtime.CompilerServices.TaskAwaiter.HandleNonSuccessAndDebuggerNotification(Task task)
   at Microsoft.AspNetCore.Server.IISIntegration.IISMiddleware.<Invoke>d__8.MoveNext()
--- End of stack trace from previous location where exception was thrown ---
   at System.Runtime.ExceptionServices.ExceptionDispatchInfo.Throw()
   at System.Runtime.CompilerServices.TaskAwaiter.HandleNonSuccessAndDebuggerNotification(Task task)
   at Microsoft.AspNetCore.Hosting.Internal.RequestServicesContainerMiddleware.<Invoke>d__3.MoveNext()
--- End of stack trace from previous location where exception was thrown ---
   at System.Runtime.ExceptionServices.ExceptionDispatchInfo.Throw()
   at System.Runtime.CompilerServices.TaskAwaiter.HandleNonSuccessAndDebuggerNotification(Task task)
   at Microsoft.AspNetCore.Server.Kestrel.Internal.Http.Frame`1.<RequestProcessingAsync>d__2.MoveNext()
2017-10-28T13:44:16.3778489+03:00 0HL8TTRHLAV7S [ERR] Connection id ""0HL8TTRHKCB7U"": An unhandled exception was thrown by the application. (8c14976b)
System.InvalidOperationException: Headers are read-only, response has already started.
   at Microsoft.AspNetCore.Server.Kestrel.Internal.Http.FrameHeaders.ThrowHeadersReadOnlyException()
   at Microsoft.AspNetCore.Server.Kestrel.Internal.Http.FrameHeaders.Microsoft.AspNetCore.Http.IHeaderDictionary.set_Item(String key, StringValues value)
   at Microsoft.AspNetCore.Http.Internal.DefaultHttpResponse.set_ContentType(String value)
   at FundTrack.WebUI.Middlewares.GlobalErrorHandlingMiddleware.<Invoke>d__4.MoveNext() in C:\FundTrack\FundTrack.WebUI\Middlewares\GlobalErrorHandlingMiddleware.cs:line 32
--- End of stack trace from previous location where exception was thrown ---
   at System.Runtime.ExceptionServices.ExceptionDispatchInfo.Throw()
   at System.Runtime.CompilerServices.TaskAwaiter.HandleNonSuccessAndDebuggerNotification(Task task)
   at Microsoft.AspNetCore.Server.IISIntegration.IISMiddleware.<Invoke>d__8.MoveNext()
--- End of stack trace from previous location where exception was thrown ---
   at System.Runtime.ExceptionServices.ExceptionDispatchInfo.Throw()
   at System.Runtime.CompilerServices.TaskAwaiter.HandleNonSuccessAndDebuggerNotification(Task task)
   at Microsoft.AspNetCore.Hosting.Internal.RequestServicesContainerMiddleware.<Invoke>d__3.MoveNext()
--- End of stack trace from previous location where exception was thrown ---
   at System.Runtime.ExceptionServices.ExceptionDispatchInfo.Throw()
   at System.Runtime.CompilerServices.TaskAwaiter.HandleNonSuccessAndDebuggerNotification(Task task)
   at Microsoft.AspNetCore.Server.Kestrel.Internal.Http.Frame`1.<RequestProcessingAsync>d__2.MoveNext()
2017-10-28T14:10:58.1396650+03:00 0HL8TUHEUOF98 [ERR] FundTrack.BLL.Concrete.BusinessLogicException: Неможливо отримати інформацію для рахунку ---> System.InvalidOperationException: Nullable object must have a value.
   at System.ThrowHelper.ThrowInvalidOperationException(ExceptionResource resource)
   at System.Nullable`1.get_Value()
   at FundTrack.BLL.Concrete.OrganizationAccountService.GetDonateCredentials(Int32 orgAccountId) in C:\FundTrack\FundTrack.BLL\Concrete\OrganizationAccountService.cs:line 354
   --- End of inner exception stack trace ---
   at FundTrack.BLL.Concrete.OrganizationAccountService.GetDonateCredentials(Int32 orgAccountId) in C:\FundTrack\FundTrack.BLL\Concrete\OrganizationAccountService.cs:line 365
   at FundTrack.WebUI.Controllers.OrgAccountController.GetDonateCredentials(Int32 orgAccountId) in C:\FundTrack\FundTrack.WebUI\Controllers\OrgAccountController.cs:line 82
   at lambda_method(Closure , Object , Object[] )
   at Microsoft.AspNetCore.Mvc.Internal.ControllerActionInvoker.<InvokeActionMethodAsync>d__27.MoveNext()
--- End of stack trace from previous location where exception was thrown ---
   at System.Runtime.ExceptionServices.ExceptionDispatchInfo.Throw()
   at System.Runtime.CompilerServices.TaskAwaiter.HandleNonSuccessAndDebuggerNotification(Task task)
   at Microsoft.AspNetCore.Mvc.Internal.ControllerActionInvoker.<InvokeNextActionFilterAsync>d__25.MoveNext()
--- End of stack trace from previous location where exception was thrown ---
   at System.Runtime.ExceptionServices.ExceptionDispatchInfo.Throw()
   at Microsoft.AspNetCore.Mvc.Internal.ControllerActionInvoker.Rethrow(ActionExecutedContext context)
   at Microsoft.AspNetCore.Mvc.Internal.ControllerActionInvoker.Next(State& next, Scope& scope, Object& state, Boolean& isCompleted)
   at Microsoft.AspNetCore.Mvc.Internal.ControllerActionInvoker.<InvokeNextResourceFilter>d__22.MoveNext()
--- End of stack trace from previous location where exception was thrown ---
   at System.Runtime.ExceptionServices.ExceptionDispatchInfo.Throw()
   at Microsoft.AspNetCore.Mvc.Internal.ControllerActionInvoker.Rethrow(ResourceExecutedContext context)
   at Microsoft.AspNetCore.Mvc.Internal.ControllerActionInvoker.Next(State& next, Scope& scope, Object& state, Boolean& isCompleted)
   at Microsoft.AspNetCore.Mvc.Internal.ControllerActionInvoker.<InvokeAsync>d__20.MoveNext()
--- End of stack trace from previous location where exception was thrown ---
   at System.Runtime.ExceptionServices.ExceptionDispatchInfo.Throw()
   at System.Runtime.CompilerServices.TaskAwaiter.HandleNonSuccessAndDebuggerNotification(Task task)
   at Microsoft.AspNetCore.Builder.RouterMiddleware.<Invoke>d__4.MoveNext()
--- End of stack trace from previous location where exception was thrown ---
   at System.Runtime.ExceptionServices.ExceptionDispatchInfo.Throw()
   at System.Runtime.CompilerServices.TaskAwaiter.HandleNonSuccessAndDebuggerNotification(Task task)
   at Microsoft.AspNetCore.SpaServices.Webpack.ConditionalProxyMiddleware.<Invoke>d__5.MoveNext()
--- End of stack trace from previous location where exception was thrown ---
   at System.Runtime.ExceptionServices.ExceptionDispatchInfo.Throw()
   at System.Runtime.CompilerServices.TaskAwaiter.HandleNonSuccessAndDebuggerNotification(Task task)
   at Microsoft.AspNetCore.SpaServices.Webpack.ConditionalProxyMiddleware.<Invoke>d__5.MoveNext()
--- End of stack trace from previous location where exception was thrown ---
   at System.Runtime.ExceptionServices.ExceptionDispatchInfo.Throw()
   at System.Runtime.CompilerServices.TaskAwaiter.HandleNonSuccessAndDebuggerNotification(Task task)
   at Microsoft.AspNetCore.Authentication.AuthenticationMiddleware`1.<Invoke>d__18.MoveNext()
--- End of stack trace from previous location where exception was thrown ---
   at System.Runtime.ExceptionServices.ExceptionDispatchInfo.Throw()
   at Microsoft.AspNetCore.Authentication.AuthenticationMiddleware`1.<Invoke>d__18.MoveNext()
--- End of stack trace from previous location where exception was thrown ---
   at System.Runtime.ExceptionServices.ExceptionDispatchInfo.Throw()
   at System.Runtime.CompilerServices.TaskAwaiter.HandleNonSuccessAndDebuggerNotification(Task task)
   at System.Runtime.CompilerServices.TaskAwaiter.GetResult()
   at FundTrack.WebUI.Middlewares.GlobalErrorHandlingMiddleware.<Invoke>d__4.MoveNext() in C:\FundTrack\FundTrack.WebUI\Middlewares\GlobalErrorHandlingMiddleware.cs:line 28 (682b77bc)
