Date and time:  01.11.2017 10:27:48
Error message:  An exception has been raised that is likely due to a transient failure. If you are connecting to a SQL Azure database consider using SqlAzureExecutionStrategy.
Source:  Microsoft.EntityFrameworkCore.SqlServer
InnerException:  System.Data.SqlClient.SqlException: The client was unable to establish a connection because of an error during connection initialization process before login. Possible causes include the following:  the client tried to connect to an unsupported version of SQL Server; the server was too busy to accept new connections; or there was a resource limitation (insufficient memory or maximum allowed connections) on the server. (provider: TCP Provider, error: 0 - An existing connection was forcibly closed by the remote host.) ---> System.ComponentModel.Win32Exception: An existing connection was forcibly closed by the remote host
   --- End of inner exception stack trace ---
   at System.Data.ProviderBase.DbConnectionPool.TryGetConnection(DbConnection owningObject, UInt32 waitForMultipleObjectsTimeout, Boolean allowCreate, Boolean onlyOneCheckConnection, DbConnectionOptions userOptions, DbConnectionInternal& connection)
   at System.Data.ProviderBase.DbConnectionPool.TryGetConnection(DbConnection owningObject, TaskCompletionSource`1 retry, DbConnectionOptions userOptions, DbConnectionInternal& connection)
   at System.Data.ProviderBase.DbConnectionFactory.TryGetConnection(DbConnection owningConnection, TaskCompletionSource`1 retry, DbConnectionOptions userOptions, DbConnectionInternal oldConnection, DbConnectionInternal& connection)
   at System.Data.ProviderBase.DbConnectionInternal.TryOpenConnectionInternal(DbConnection outerConnection, DbConnectionFactory connectionFactory, TaskCompletionSource`1 retry, DbConnectionOptions userOptions)
   at System.Data.SqlClient.SqlConnection.TryOpen(TaskCompletionSource`1 retry)
   at System.Data.SqlClient.SqlConnection.Open()
   at Microsoft.EntityFrameworkCore.Storage.RelationalConnection.Open()
   at Microsoft.EntityFrameworkCore.Query.Internal.QueryingEnumerable.Enumerator.BufferlessMoveNext(Boolean buffer)
   at Microsoft.EntityFrameworkCore.Storage.Internal.SqlServerExecutionStrategy.Execute[TState,TResult](Func`2 operation, Func`2 verifySucceeded, TState state)
ClientConnectionId:c1d01bf4-69f9-4ff8-b93b-f1d5729ecbb8
Error Number:10054,State:0,Class:20
StackTrace:     at Microsoft.EntityFrameworkCore.Storage.Internal.SqlServerExecutionStrategy.Execute[TState,TResult](Func`2 operation, Func`2 verifySucceeded, TState state)
   at Microsoft.EntityFrameworkCore.Query.QueryMethodProvider.<_ShapedQuery>d__3`1.MoveNext()
   at Microsoft.EntityFrameworkCore.Query.Internal.LinqOperatorProvider.<_TrackEntities>d__15`2.MoveNext()
   at Microsoft.EntityFrameworkCore.Query.Internal.LinqOperatorProvider.ExceptionInterceptor`1.EnumeratorExceptionInterceptor.MoveNext()
   at System.Linq.Enumerable.FirstOrDefault[TSource](IEnumerable`1 source, Func`2 predicate)
   at FundTrack.BLL.Concrete.ModeratorService.GetOrganizationModerators(Int32 organizationId) in C:\FundTrack\FundTrack.BLL\Concrete\ModeratorService.cs:line 26
   at FundTrack.WebUI.Controllers.ModeratorController.GetModerators(Int32 id) in C:\FundTrack\FundTrack.WebUI\Controllers\ModeratorController.cs:line 24
   at lambda_method(Closure , Object , Object[] )
   at Microsoft.AspNetCore.Mvc.Internal.ControllerActionInvoker.<InvokeActionMethodAsync>d__27.MoveNext()
--- End of stack trace from previous location where exception was thrown ---
   at System.Runtime.ExceptionServices.ExceptionDispatchInfo.Throw()
   at System.Runtime.CompilerServices.TaskAwaiter.HandleNonSuccessAndDebuggerNotification(Task task)
   at Microsoft.AspNetCore.Mvc.Internal.ControllerActionInvoker.<InvokeNextActionFilterAsync>d__25.MoveNext()
--- End of stack trace from previous location where exception was thrown ---
   at System.Runtime.ExceptionServices.ExceptionDispatchInfo.Throw()
   at Microsoft.AspNetCore.Mvc.Internal.ControllerActionInvoker.Rethrow(ActionExecutedContext context)
   at Microsoft.AspNetCore.Mvc.Internal.ControllerActionInvoker.Next(State& next, Scope& scope, Object& state, Boolean& isCompleted)
   at Microsoft.AspNetCore.Mvc.Internal.ControllerActionInvoker.<InvokeNextResourceFilter>d__22.MoveNext()
--- End of stack trace from previous location where exception was thrown ---
   at System.Runtime.ExceptionServices.ExceptionDispatchInfo.Throw()
   at Microsoft.AspNetCore.Mvc.Internal.ControllerActionInvoker.Rethrow(ResourceExecutedContext context)
   at Microsoft.AspNetCore.Mvc.Internal.ControllerActionInvoker.Next(State& next, Scope& scope, Object& state, Boolean& isCompleted)
   at Microsoft.AspNetCore.Mvc.Internal.ControllerActionInvoker.<InvokeAsync>d__20.MoveNext()
--- End of stack trace from previous location where exception was thrown ---
   at System.Runtime.ExceptionServices.ExceptionDispatchInfo.Throw()
   at System.Runtime.CompilerServices.TaskAwaiter.HandleNonSuccessAndDebuggerNotification(Task task)
   at Microsoft.AspNetCore.Builder.RouterMiddleware.<Invoke>d__4.MoveNext()
--- End of stack trace from previous location where exception was thrown ---
   at System.Runtime.ExceptionServices.ExceptionDispatchInfo.Throw()
   at System.Runtime.CompilerServices.TaskAwaiter.HandleNonSuccessAndDebuggerNotification(Task task)
   at Microsoft.AspNetCore.SpaServices.Webpack.ConditionalProxyMiddleware.<Invoke>d__5.MoveNext()
--- End of stack trace from previous location where exception was thrown ---
   at System.Runtime.ExceptionServices.ExceptionDispatchInfo.Throw()
   at System.Runtime.CompilerServices.TaskAwaiter.HandleNonSuccessAndDebuggerNotification(Task task)
   at Microsoft.AspNetCore.SpaServices.Webpack.ConditionalProxyMiddleware.<Invoke>d__5.MoveNext()
--- End of stack trace from previous location where exception was thrown ---
   at System.Runtime.ExceptionServices.ExceptionDispatchInfo.Throw()
   at System.Runtime.CompilerServices.TaskAwaiter.HandleNonSuccessAndDebuggerNotification(Task task)
   at Microsoft.AspNetCore.Authentication.AuthenticationMiddleware`1.<Invoke>d__18.MoveNext()
--- End of stack trace from previous location where exception was thrown ---
   at System.Runtime.ExceptionServices.ExceptionDispatchInfo.Throw()
   at Microsoft.AspNetCore.Authentication.AuthenticationMiddleware`1.<Invoke>d__18.MoveNext()
--- End of stack trace from previous location where exception was thrown ---
   at System.Runtime.ExceptionServices.ExceptionDispatchInfo.Throw()
   at System.Runtime.CompilerServices.TaskAwaiter.HandleNonSuccessAndDebuggerNotification(Task task)
   at System.Runtime.CompilerServices.TaskAwaiter.GetResult()
   at FundTrack.WebUI.Middlewares.GlobalErrorHandlingMiddleware.<Invoke>d__4.MoveNext() in C:\FundTrack\FundTrack.WebUI\Middlewares\GlobalErrorHandlingMiddleware.cs:line 33
____________________________________________________________________________________________________________________________________________

Date and time:  01.11.2017 10:27:49
Error message:  Неможливо отримати рахунок організації
Source:  FundTrack.BLL
InnerException:  System.InvalidOperationException: An exception has been raised that is likely due to a transient failure. If you are connecting to a SQL Azure database consider using SqlAzureExecutionStrategy. ---> System.Data.SqlClient.SqlException: The client was unable to establish a connection because of an error during connection initialization process before login. Possible causes include the following:  the client tried to connect to an unsupported version of SQL Server; the server was too busy to accept new connections; or there was a resource limitation (insufficient memory or maximum allowed connections) on the server. (provider: TCP Provider, error: 0 - An existing connection was forcibly closed by the remote host.) ---> System.ComponentModel.Win32Exception: An existing connection was forcibly closed by the remote host
   --- End of inner exception stack trace ---
   at System.Data.SqlClient.SqlInternalConnectionTds..ctor(DbConnectionPoolIdentity identity, SqlConnectionString connectionOptions, Object providerInfo, Boolean redirectedUserInstance, SqlConnectionString userConnectionOptions, SessionData reconnectSessionData, Boolean applyTransientFaultHandling)
   at System.Data.SqlClient.SqlConnectionFactory.CreateConnection(DbConnectionOptions options, DbConnectionPoolKey poolKey, Object poolGroupProviderInfo, DbConnectionPool pool, DbConnection owningConnection, DbConnectionOptions userOptions)
   at System.Data.ProviderBase.DbConnectionFactory.CreatePooledConnection(DbConnectionPool pool, DbConnection owningObject, DbConnectionOptions options, DbConnectionPoolKey poolKey, DbConnectionOptions userOptions)
   at System.Data.ProviderBase.DbConnectionPool.CreateObject(DbConnection owningObject, DbConnectionOptions userOptions, DbConnectionInternal oldConnection)
   at System.Data.ProviderBase.DbConnectionPool.UserCreateRequest(DbConnection owningObject, DbConnectionOptions userOptions, DbConnectionInternal oldConnection)
   at System.Data.ProviderBase.DbConnectionPool.TryGetConnection(DbConnection owningObject, UInt32 waitForMultipleObjectsTimeout, Boolean allowCreate, Boolean onlyOneCheckConnection, DbConnectionOptions userOptions, DbConnectionInternal& connection)
   at System.Data.ProviderBase.DbConnectionPool.TryGetConnection(DbConnection owningObject, TaskCompletionSource`1 retry, DbConnectionOptions userOptions, DbConnectionInternal& connection)
   at System.Data.ProviderBase.DbConnectionFactory.TryGetConnection(DbConnection owningConnection, TaskCompletionSource`1 retry, DbConnectionOptions userOptions, DbConnectionInternal oldConnection, DbConnectionInternal& connection)
   at System.Data.ProviderBase.DbConnectionInternal.TryOpenConnectionInternal(DbConnection outerConnection, DbConnectionFactory connectionFactory, TaskCompletionSource`1 retry, DbConnectionOptions userOptions)
   at System.Data.SqlClient.SqlConnection.TryOpen(TaskCompletionSource`1 retry)
   at System.Data.SqlClient.SqlConnection.Open()
   at Microsoft.EntityFrameworkCore.Storage.RelationalConnection.Open()
   at Microsoft.EntityFrameworkCore.Query.Internal.QueryingEnumerable.Enumerator.BufferlessMoveNext(Boolean buffer)
   at Microsoft.EntityFrameworkCore.Storage.Internal.SqlServerExecutionStrategy.Execute[TState,TResult](Func`2 operation, Func`2 verifySucceeded, TState state)
   --- End of inner exception stack trace ---
   at Microsoft.EntityFrameworkCore.Storage.Internal.SqlServerExecutionStrategy.Execute[TState,TResult](Func`2 operation, Func`2 verifySucceeded, TState state)
   at Microsoft.EntityFrameworkCore.Query.QueryMethodProvider.GetResult[TResult](IEnumerable`1 valueBuffers)
   at lambda_method(Closure , QueryContext )
   at Microsoft.EntityFrameworkCore.Query.Internal.QueryCompiler.<>c__DisplayClass20_0`1.<CompileQueryCore>b__0(QueryContext qc)
   at System.Linq.Queryable.Count[TSource](IQueryable`1 source)
   at FundTrack.BLL.Concrete.FinOpService.GetFinOpInitData(Int32 accountId) in C:\FundTrack\FundTrack.BLL\Concrete\FinOpService.cs:line 280
StackTrace:     at FundTrack.BLL.Concrete.FinOpService.GetFinOpInitData(Int32 accountId) in C:\FundTrack\FundTrack.BLL\Concrete\FinOpService.cs:line 291
   at FundTrack.WebUI.Controllers.FinOpController.GetFinOpInitData(Int32 id) in C:\FundTrack\FundTrack.WebUI\Controllers\FinOpController.cs:line 103
   at lambda_method(Closure , Object , Object[] )
   at Microsoft.AspNetCore.Mvc.Internal.ControllerActionInvoker.<InvokeActionMethodAsync>d__27.MoveNext()
--- End of stack trace from previous location where exception was thrown ---
   at System.Runtime.ExceptionServices.ExceptionDispatchInfo.Throw()
   at System.Runtime.CompilerServices.TaskAwaiter.HandleNonSuccessAndDebuggerNotification(Task task)
   at Microsoft.AspNetCore.Mvc.Internal.ControllerActionInvoker.<InvokeNextActionFilterAsync>d__25.MoveNext()
--- End of stack trace from previous location where exception was thrown ---
   at System.Runtime.ExceptionServices.ExceptionDispatchInfo.Throw()
   at Microsoft.AspNetCore.Mvc.Internal.ControllerActionInvoker.Rethrow(ActionExecutedContext context)
   at Microsoft.AspNetCore.Mvc.Internal.ControllerActionInvoker.Next(State& next, Scope& scope, Object& state, Boolean& isCompleted)
   at Microsoft.AspNetCore.Mvc.Internal.ControllerActionInvoker.<InvokeNextResourceFilter>d__22.MoveNext()
--- End of stack trace from previous location where exception was thrown ---
   at System.Runtime.ExceptionServices.ExceptionDispatchInfo.Throw()
   at Microsoft.AspNetCore.Mvc.Internal.ControllerActionInvoker.Rethrow(ResourceExecutedContext context)
   at Microsoft.AspNetCore.Mvc.Internal.ControllerActionInvoker.Next(State& next, Scope& scope, Object& state, Boolean& isCompleted)
   at Microsoft.AspNetCore.Mvc.Internal.ControllerActionInvoker.<InvokeAsync>d__20.MoveNext()
--- End of stack trace from previous location where exception was thrown ---
   at System.Runtime.ExceptionServices.ExceptionDispatchInfo.Throw()
   at System.Runtime.CompilerServices.TaskAwaiter.HandleNonSuccessAndDebuggerNotification(Task task)
   at Microsoft.AspNetCore.Builder.RouterMiddleware.<Invoke>d__4.MoveNext()
--- End of stack trace from previous location where exception was thrown ---
   at System.Runtime.ExceptionServices.ExceptionDispatchInfo.Throw()
   at System.Runtime.CompilerServices.TaskAwaiter.HandleNonSuccessAndDebuggerNotification(Task task)
   at Microsoft.AspNetCore.SpaServices.Webpack.ConditionalProxyMiddleware.<Invoke>d__5.MoveNext()
--- End of stack trace from previous location where exception was thrown ---
   at System.Runtime.ExceptionServices.ExceptionDispatchInfo.Throw()
   at System.Runtime.CompilerServices.TaskAwaiter.HandleNonSuccessAndDebuggerNotification(Task task)
   at Microsoft.AspNetCore.SpaServices.Webpack.ConditionalProxyMiddleware.<Invoke>d__5.MoveNext()
--- End of stack trace from previous location where exception was thrown ---
   at System.Runtime.ExceptionServices.ExceptionDispatchInfo.Throw()
   at System.Runtime.CompilerServices.TaskAwaiter.HandleNonSuccessAndDebuggerNotification(Task task)
   at Microsoft.AspNetCore.Authentication.AuthenticationMiddleware`1.<Invoke>d__18.MoveNext()
--- End of stack trace from previous location where exception was thrown ---
   at System.Runtime.ExceptionServices.ExceptionDispatchInfo.Throw()
   at Microsoft.AspNetCore.Authentication.AuthenticationMiddleware`1.<Invoke>d__18.MoveNext()
--- End of stack trace from previous location where exception was thrown ---
   at System.Runtime.ExceptionServices.ExceptionDispatchInfo.Throw()
   at System.Runtime.CompilerServices.TaskAwaiter.HandleNonSuccessAndDebuggerNotification(Task task)
   at System.Runtime.CompilerServices.TaskAwaiter.GetResult()
   at FundTrack.WebUI.Middlewares.GlobalErrorHandlingMiddleware.<Invoke>d__4.MoveNext() in C:\FundTrack\FundTrack.WebUI\Middlewares\GlobalErrorHandlingMiddleware.cs:line 33
____________________________________________________________________________________________________________________________________________

Date and time:  01.11.2017 10:28:18
Error message:  Неможливо отримати рахунок організації
Source:  FundTrack.BLL
InnerException:  System.InvalidOperationException: An exception has been raised that is likely due to a transient failure. If you are connecting to a SQL Azure database consider using SqlAzureExecutionStrategy. ---> System.Data.SqlClient.SqlException: A connection was successfully established with the server, but then an error occurred during the login process. (provider: TCP Provider, error: 0 - An existing connection was forcibly closed by the remote host.) ---> System.ComponentModel.Win32Exception: An existing connection was forcibly closed by the remote host
   --- End of inner exception stack trace ---
   at System.Data.SqlClient.SqlInternalConnectionTds..ctor(DbConnectionPoolIdentity identity, SqlConnectionString connectionOptions, Object providerInfo, Boolean redirectedUserInstance, SqlConnectionString userConnectionOptions, SessionData reconnectSessionData, Boolean applyTransientFaultHandling)
   at System.Data.SqlClient.SqlConnectionFactory.CreateConnection(DbConnectionOptions options, DbConnectionPoolKey poolKey, Object poolGroupProviderInfo, DbConnectionPool pool, DbConnection owningConnection, DbConnectionOptions userOptions)
   at System.Data.ProviderBase.DbConnectionFactory.CreatePooledConnection(DbConnectionPool pool, DbConnection owningObject, DbConnectionOptions options, DbConnectionPoolKey poolKey, DbConnectionOptions userOptions)
   at System.Data.ProviderBase.DbConnectionPool.CreateObject(DbConnection owningObject, DbConnectionOptions userOptions, DbConnectionInternal oldConnection)
   at System.Data.ProviderBase.DbConnectionPool.UserCreateRequest(DbConnection owningObject, DbConnectionOptions userOptions, DbConnectionInternal oldConnection)
   at System.Data.ProviderBase.DbConnectionPool.TryGetConnection(DbConnection owningObject, UInt32 waitForMultipleObjectsTimeout, Boolean allowCreate, Boolean onlyOneCheckConnection, DbConnectionOptions userOptions, DbConnectionInternal& connection)
   at System.Data.ProviderBase.DbConnectionPool.TryGetConnection(DbConnection owningObject, TaskCompletionSource`1 retry, DbConnectionOptions userOptions, DbConnectionInternal& connection)
   at System.Data.ProviderBase.DbConnectionFactory.TryGetConnection(DbConnection owningConnection, TaskCompletionSource`1 retry, DbConnectionOptions userOptions, DbConnectionInternal oldConnection, DbConnectionInternal& connection)
   at System.Data.ProviderBase.DbConnectionInternal.TryOpenConnectionInternal(DbConnection outerConnection, DbConnectionFactory connectionFactory, TaskCompletionSource`1 retry, DbConnectionOptions userOptions)
   at System.Data.SqlClient.SqlConnection.TryOpen(TaskCompletionSource`1 retry)
   at System.Data.SqlClient.SqlConnection.Open()
   at Microsoft.EntityFrameworkCore.Storage.RelationalConnection.Open()
   at Microsoft.EntityFrameworkCore.Query.Internal.QueryingEnumerable.Enumerator.BufferlessMoveNext(Boolean buffer)
   at Microsoft.EntityFrameworkCore.Storage.Internal.SqlServerExecutionStrategy.Execute[TState,TResult](Func`2 operation, Func`2 verifySucceeded, TState state)
   --- End of inner exception stack trace ---
   at Microsoft.EntityFrameworkCore.Storage.Internal.SqlServerExecutionStrategy.Execute[TState,TResult](Func`2 operation, Func`2 verifySucceeded, TState state)
   at Microsoft.EntityFrameworkCore.Query.QueryMethodProvider.GetResult[TResult](IEnumerable`1 valueBuffers)
   at lambda_method(Closure , QueryContext )
   at Microsoft.EntityFrameworkCore.Query.Internal.QueryCompiler.<>c__DisplayClass20_0`1.<CompileQueryCore>b__0(QueryContext qc)
   at System.Linq.Queryable.Count[TSource](IQueryable`1 source)
   at FundTrack.BLL.Concrete.FinOpService.GetFinOpInitData(Int32 accountId) in C:\FundTrack\FundTrack.BLL\Concrete\FinOpService.cs:line 280
StackTrace:     at FundTrack.BLL.Concrete.FinOpService.GetFinOpInitData(Int32 accountId) in C:\FundTrack\FundTrack.BLL\Concrete\FinOpService.cs:line 291
   at FundTrack.WebUI.Controllers.FinOpController.GetFinOpInitData(Int32 id) in C:\FundTrack\FundTrack.WebUI\Controllers\FinOpController.cs:line 103
   at lambda_method(Closure , Object , Object[] )
   at Microsoft.AspNetCore.Mvc.Internal.ControllerActionInvoker.<InvokeActionMethodAsync>d__27.MoveNext()
--- End of stack trace from previous location where exception was thrown ---
   at System.Runtime.ExceptionServices.ExceptionDispatchInfo.Throw()
   at System.Runtime.CompilerServices.TaskAwaiter.HandleNonSuccessAndDebuggerNotification(Task task)
   at Microsoft.AspNetCore.Mvc.Internal.ControllerActionInvoker.<InvokeNextActionFilterAsync>d__25.MoveNext()
--- End of stack trace from previous location where exception was thrown ---
   at System.Runtime.ExceptionServices.ExceptionDispatchInfo.Throw()
   at Microsoft.AspNetCore.Mvc.Internal.ControllerActionInvoker.Rethrow(ActionExecutedContext context)
   at Microsoft.AspNetCore.Mvc.Internal.ControllerActionInvoker.Next(State& next, Scope& scope, Object& state, Boolean& isCompleted)
   at Microsoft.AspNetCore.Mvc.Internal.ControllerActionInvoker.<InvokeNextResourceFilter>d__22.MoveNext()
--- End of stack trace from previous location where exception was thrown ---
   at System.Runtime.ExceptionServices.ExceptionDispatchInfo.Throw()
   at Microsoft.AspNetCore.Mvc.Internal.ControllerActionInvoker.Rethrow(ResourceExecutedContext context)
   at Microsoft.AspNetCore.Mvc.Internal.ControllerActionInvoker.Next(State& next, Scope& scope, Object& state, Boolean& isCompleted)
   at Microsoft.AspNetCore.Mvc.Internal.ControllerActionInvoker.<InvokeAsync>d__20.MoveNext()
--- End of stack trace from previous location where exception was thrown ---
   at System.Runtime.ExceptionServices.ExceptionDispatchInfo.Throw()
   at System.Runtime.CompilerServices.TaskAwaiter.HandleNonSuccessAndDebuggerNotification(Task task)
   at Microsoft.AspNetCore.Builder.RouterMiddleware.<Invoke>d__4.MoveNext()
--- End of stack trace from previous location where exception was thrown ---
   at System.Runtime.ExceptionServices.ExceptionDispatchInfo.Throw()
   at System.Runtime.CompilerServices.TaskAwaiter.HandleNonSuccessAndDebuggerNotification(Task task)
   at Microsoft.AspNetCore.SpaServices.Webpack.ConditionalProxyMiddleware.<Invoke>d__5.MoveNext()
--- End of stack trace from previous location where exception was thrown ---
   at System.Runtime.ExceptionServices.ExceptionDispatchInfo.Throw()
   at System.Runtime.CompilerServices.TaskAwaiter.HandleNonSuccessAndDebuggerNotification(Task task)
   at Microsoft.AspNetCore.SpaServices.Webpack.ConditionalProxyMiddleware.<Invoke>d__5.MoveNext()
--- End of stack trace from previous location where exception was thrown ---
   at System.Runtime.ExceptionServices.ExceptionDispatchInfo.Throw()
   at System.Runtime.CompilerServices.TaskAwaiter.HandleNonSuccessAndDebuggerNotification(Task task)
   at Microsoft.AspNetCore.Authentication.AuthenticationMiddleware`1.<Invoke>d__18.MoveNext()
--- End of stack trace from previous location where exception was thrown ---
   at System.Runtime.ExceptionServices.ExceptionDispatchInfo.Throw()
   at Microsoft.AspNetCore.Authentication.AuthenticationMiddleware`1.<Invoke>d__18.MoveNext()
--- End of stack trace from previous location where exception was thrown ---
   at System.Runtime.ExceptionServices.ExceptionDispatchInfo.Throw()
   at System.Runtime.CompilerServices.TaskAwaiter.HandleNonSuccessAndDebuggerNotification(Task task)
   at System.Runtime.CompilerServices.TaskAwaiter.GetResult()
   at FundTrack.WebUI.Middlewares.GlobalErrorHandlingMiddleware.<Invoke>d__4.MoveNext() in C:\FundTrack\FundTrack.WebUI\Middlewares\GlobalErrorHandlingMiddleware.cs:line 33
____________________________________________________________________________________________________________________________________________

Date and time:  01.11.2017 10:28:20
Error message:  An exception has been raised that is likely due to a transient failure. If you are connecting to a SQL Azure database consider using SqlAzureExecutionStrategy.
Source:  Microsoft.EntityFrameworkCore.SqlServer
InnerException:  System.Data.SqlClient.SqlException: A connection was successfully established with the server, but then an error occurred during the login process. (provider: TCP Provider, error: 0 - An existing connection was forcibly closed by the remote host.) ---> System.ComponentModel.Win32Exception: An existing connection was forcibly closed by the remote host
   --- End of inner exception stack trace ---
   at System.Data.ProviderBase.DbConnectionPool.TryGetConnection(DbConnection owningObject, UInt32 waitForMultipleObjectsTimeout, Boolean allowCreate, Boolean onlyOneCheckConnection, DbConnectionOptions userOptions, DbConnectionInternal& connection)
   at System.Data.ProviderBase.DbConnectionPool.TryGetConnection(DbConnection owningObject, TaskCompletionSource`1 retry, DbConnectionOptions userOptions, DbConnectionInternal& connection)
   at System.Data.ProviderBase.DbConnectionFactory.TryGetConnection(DbConnection owningConnection, TaskCompletionSource`1 retry, DbConnectionOptions userOptions, DbConnectionInternal oldConnection, DbConnectionInternal& connection)
   at System.Data.ProviderBase.DbConnectionInternal.TryOpenConnectionInternal(DbConnection outerConnection, DbConnectionFactory connectionFactory, TaskCompletionSource`1 retry, DbConnectionOptions userOptions)
   at System.Data.SqlClient.SqlConnection.TryOpen(TaskCompletionSource`1 retry)
   at System.Data.SqlClient.SqlConnection.Open()
   at Microsoft.EntityFrameworkCore.Storage.RelationalConnection.Open()
   at Microsoft.EntityFrameworkCore.Query.Internal.QueryingEnumerable.Enumerator.BufferlessMoveNext(Boolean buffer)
   at Microsoft.EntityFrameworkCore.Storage.Internal.SqlServerExecutionStrategy.Execute[TState,TResult](Func`2 operation, Func`2 verifySucceeded, TState state)
ClientConnectionId:09261608-4f6b-485a-9be6-94ecf586f9e3
Error Number:10054,State:0,Class:20
StackTrace:     at Microsoft.EntityFrameworkCore.Storage.Internal.SqlServerExecutionStrategy.Execute[TState,TResult](Func`2 operation, Func`2 verifySucceeded, TState state)
   at Microsoft.EntityFrameworkCore.Query.QueryMethodProvider.<_ShapedQuery>d__3`1.MoveNext()
   at Microsoft.EntityFrameworkCore.Query.QueryMethodProvider.<_Include>d__30`1.MoveNext()
   at System.Linq.Enumerable.FirstOrDefault[TSource](IEnumerable`1 source)
   at lambda_method(Closure , QueryContext )
   at Microsoft.EntityFrameworkCore.Query.Internal.QueryCompiler.<>c__DisplayClass20_0`1.<CompileQueryCore>b__0(QueryContext qc)
   at System.Linq.Queryable.FirstOrDefault[TSource](IQueryable`1 source, Expression`1 predicate)
   at FundTrack.DAL.Concrete.OrganizationAccountRepository.GetOrgAccountById(Int32 orgAccountId) in C:\FundTrack\FundTrack.DAL\Concrete\OrganizationAccountRepository.cs:line 106
   at FundTrack.BLL.Concrete.OrganizationAccountService.IsExtractsEnabled(Int32 orgAccountId) in C:\FundTrack\FundTrack.BLL\Concrete\OrganizationAccountService.cs:line 474
   at FundTrack.WebUI.Controllers.OrgAccountController.CheckExtractsFunction(Int32 orgAccountId) in C:\FundTrack\FundTrack.WebUI\Controllers\OrgAccountController.cs:line 182
   at lambda_method(Closure , Object , Object[] )
   at Microsoft.AspNetCore.Mvc.Internal.ControllerActionInvoker.<InvokeActionMethodAsync>d__27.MoveNext()
--- End of stack trace from previous location where exception was thrown ---
   at System.Runtime.ExceptionServices.ExceptionDispatchInfo.Throw()
   at System.Runtime.CompilerServices.TaskAwaiter.HandleNonSuccessAndDebuggerNotification(Task task)
   at Microsoft.AspNetCore.Mvc.Internal.ControllerActionInvoker.<InvokeNextActionFilterAsync>d__25.MoveNext()
--- End of stack trace from previous location where exception was thrown ---
   at System.Runtime.ExceptionServices.ExceptionDispatchInfo.Throw()
   at Microsoft.AspNetCore.Mvc.Internal.ControllerActionInvoker.Rethrow(ActionExecutedContext context)
   at Microsoft.AspNetCore.Mvc.Internal.ControllerActionInvoker.Next(State& next, Scope& scope, Object& state, Boolean& isCompleted)
   at Microsoft.AspNetCore.Mvc.Internal.ControllerActionInvoker.<InvokeNextResourceFilter>d__22.MoveNext()
--- End of stack trace from previous location where exception was thrown ---
   at System.Runtime.ExceptionServices.ExceptionDispatchInfo.Throw()
   at Microsoft.AspNetCore.Mvc.Internal.ControllerActionInvoker.Rethrow(ResourceExecutedContext context)
   at Microsoft.AspNetCore.Mvc.Internal.ControllerActionInvoker.Next(State& next, Scope& scope, Object& state, Boolean& isCompleted)
   at Microsoft.AspNetCore.Mvc.Internal.ControllerActionInvoker.<InvokeAsync>d__20.MoveNext()
--- End of stack trace from previous location where exception was thrown ---
   at System.Runtime.ExceptionServices.ExceptionDispatchInfo.Throw()
   at System.Runtime.CompilerServices.TaskAwaiter.HandleNonSuccessAndDebuggerNotification(Task task)
   at Microsoft.AspNetCore.Builder.RouterMiddleware.<Invoke>d__4.MoveNext()
--- End of stack trace from previous location where exception was thrown ---
   at System.Runtime.ExceptionServices.ExceptionDispatchInfo.Throw()
   at System.Runtime.CompilerServices.TaskAwaiter.HandleNonSuccessAndDebuggerNotification(Task task)
   at Microsoft.AspNetCore.SpaServices.Webpack.ConditionalProxyMiddleware.<Invoke>d__5.MoveNext()
--- End of stack trace from previous location where exception was thrown ---
   at System.Runtime.ExceptionServices.ExceptionDispatchInfo.Throw()
   at System.Runtime.CompilerServices.TaskAwaiter.HandleNonSuccessAndDebuggerNotification(Task task)
   at Microsoft.AspNetCore.SpaServices.Webpack.ConditionalProxyMiddleware.<Invoke>d__5.MoveNext()
--- End of stack trace from previous location where exception was thrown ---
   at System.Runtime.ExceptionServices.ExceptionDispatchInfo.Throw()
   at System.Runtime.CompilerServices.TaskAwaiter.HandleNonSuccessAndDebuggerNotification(Task task)
   at Microsoft.AspNetCore.Authentication.AuthenticationMiddleware`1.<Invoke>d__18.MoveNext()
--- End of stack trace from previous location where exception was thrown ---
   at System.Runtime.ExceptionServices.ExceptionDispatchInfo.Throw()
   at Microsoft.AspNetCore.Authentication.AuthenticationMiddleware`1.<Invoke>d__18.MoveNext()
--- End of stack trace from previous location where exception was thrown ---
   at System.Runtime.ExceptionServices.ExceptionDispatchInfo.Throw()
   at System.Runtime.CompilerServices.TaskAwaiter.HandleNonSuccessAndDebuggerNotification(Task task)
   at System.Runtime.CompilerServices.TaskAwaiter.GetResult()
   at FundTrack.WebUI.Middlewares.GlobalErrorHandlingMiddleware.<Invoke>d__4.MoveNext() in C:\FundTrack\FundTrack.WebUI\Middlewares\GlobalErrorHandlingMiddleware.cs:line 33
____________________________________________________________________________________________________________________________________________

Date and time:  01.11.2017 10:30:53
Error message:  Неможливо отримати рахунок організації
Source:  FundTrack.BLL
InnerException:  System.InvalidOperationException: An exception has been raised that is likely due to a transient failure. If you are connecting to a SQL Azure database consider using SqlAzureExecutionStrategy. ---> System.Data.SqlClient.SqlException: A connection was successfully established with the server, but then an error occurred during the pre-login handshake. (provider: TCP Provider, error: 0 - An existing connection was forcibly closed by the remote host.) ---> System.ComponentModel.Win32Exception: An existing connection was forcibly closed by the remote host
   --- End of inner exception stack trace ---
   at System.Data.SqlClient.SqlInternalConnectionTds..ctor(DbConnectionPoolIdentity identity, SqlConnectionString connectionOptions, Object providerInfo, Boolean redirectedUserInstance, SqlConnectionString userConnectionOptions, SessionData reconnectSessionData, Boolean applyTransientFaultHandling)
   at System.Data.SqlClient.SqlConnectionFactory.CreateConnection(DbConnectionOptions options, DbConnectionPoolKey poolKey, Object poolGroupProviderInfo, DbConnectionPool pool, DbConnection owningConnection, DbConnectionOptions userOptions)
   at System.Data.ProviderBase.DbConnectionFactory.CreatePooledConnection(DbConnectionPool pool, DbConnection owningObject, DbConnectionOptions options, DbConnectionPoolKey poolKey, DbConnectionOptions userOptions)
   at System.Data.ProviderBase.DbConnectionPool.CreateObject(DbConnection owningObject, DbConnectionOptions userOptions, DbConnectionInternal oldConnection)
   at System.Data.ProviderBase.DbConnectionPool.UserCreateRequest(DbConnection owningObject, DbConnectionOptions userOptions, DbConnectionInternal oldConnection)
   at System.Data.ProviderBase.DbConnectionPool.TryGetConnection(DbConnection owningObject, UInt32 waitForMultipleObjectsTimeout, Boolean allowCreate, Boolean onlyOneCheckConnection, DbConnectionOptions userOptions, DbConnectionInternal& connection)
   at System.Data.ProviderBase.DbConnectionPool.TryGetConnection(DbConnection owningObject, TaskCompletionSource`1 retry, DbConnectionOptions userOptions, DbConnectionInternal& connection)
   at System.Data.ProviderBase.DbConnectionFactory.TryGetConnection(DbConnection owningConnection, TaskCompletionSource`1 retry, DbConnectionOptions userOptions, DbConnectionInternal oldConnection, DbConnectionInternal& connection)
   at System.Data.ProviderBase.DbConnectionInternal.TryOpenConnectionInternal(DbConnection outerConnection, DbConnectionFactory connectionFactory, TaskCompletionSource`1 retry, DbConnectionOptions userOptions)
   at System.Data.SqlClient.SqlConnection.TryOpen(TaskCompletionSource`1 retry)
   at System.Data.SqlClient.SqlConnection.Open()
   at Microsoft.EntityFrameworkCore.Storage.RelationalConnection.Open()
   at Microsoft.EntityFrameworkCore.Query.Internal.QueryingEnumerable.Enumerator.BufferlessMoveNext(Boolean buffer)
   at Microsoft.EntityFrameworkCore.Storage.Internal.SqlServerExecutionStrategy.Execute[TState,TResult](Func`2 operation, Func`2 verifySucceeded, TState state)
   --- End of inner exception stack trace ---
   at Microsoft.EntityFrameworkCore.Storage.Internal.SqlServerExecutionStrategy.Execute[TState,TResult](Func`2 operation, Func`2 verifySucceeded, TState state)
   at Microsoft.EntityFrameworkCore.Query.QueryMethodProvider.<_ShapedQuery>d__3`1.MoveNext()
   at Microsoft.EntityFrameworkCore.Query.QueryMethodProvider.<_Include>d__30`1.MoveNext()
   at Microsoft.EntityFrameworkCore.Query.QueryMethodProvider.<_Include>d__30`1.MoveNext()
   at Microsoft.EntityFrameworkCore.Query.QueryMethodProvider.<_Include>d__30`1.MoveNext()
   at Microsoft.EntityFrameworkCore.Query.QueryMethodProvider.<_Include>d__30`1.MoveNext()
   at Microsoft.EntityFrameworkCore.Query.QueryMethodProvider.<_Include>d__30`1.MoveNext()
   at Microsoft.EntityFrameworkCore.Query.QueryMethodProvider.<_Include>d__30`1.MoveNext()
   at System.Linq.Enumerable.FirstOrDefault[TSource](IEnumerable`1 source)
   at lambda_method(Closure , QueryContext )
   at Microsoft.EntityFrameworkCore.Query.Internal.QueryCompiler.<>c__DisplayClass20_0`1.<CompileQueryCore>b__0(QueryContext qc)
   at System.Linq.Queryable.FirstOrDefault[TSource](IQueryable`1 source, Expression`1 predicate)
   at FundTrack.DAL.Concrete.OrganizationAccountRepository.Read(Int32 orgAccountId) in C:\FundTrack\FundTrack.DAL\Concrete\OrganizationAccountRepository.cs:line 56
   at FundTrack.BLL.Concrete.OrganizationAccountService.GetOrganizationAccountById(Int32 accountId) in C:\FundTrack\FundTrack.BLL\Concrete\OrganizationAccountService.cs:line 107
StackTrace:     at FundTrack.BLL.Concrete.OrganizationAccountService.GetOrganizationAccountById(Int32 accountId) in C:\FundTrack\FundTrack.BLL\Concrete\OrganizationAccountService.cs:line 117
   at FundTrack.WebUI.Controllers.OrgAccountController.Get(Int32 id) in C:\FundTrack\FundTrack.WebUI\Controllers\OrgAccountController.cs:line 23
   at lambda_method(Closure , Object , Object[] )
   at Microsoft.AspNetCore.Mvc.Internal.ControllerActionInvoker.<InvokeActionMethodAsync>d__27.MoveNext()
--- End of stack trace from previous location where exception was thrown ---
   at System.Runtime.ExceptionServices.ExceptionDispatchInfo.Throw()
   at System.Runtime.CompilerServices.TaskAwaiter.HandleNonSuccessAndDebuggerNotification(Task task)
   at Microsoft.AspNetCore.Mvc.Internal.ControllerActionInvoker.<InvokeNextActionFilterAsync>d__25.MoveNext()
--- End of stack trace from previous location where exception was thrown ---
   at System.Runtime.ExceptionServices.ExceptionDispatchInfo.Throw()
   at Microsoft.AspNetCore.Mvc.Internal.ControllerActionInvoker.Rethrow(ActionExecutedContext context)
   at Microsoft.AspNetCore.Mvc.Internal.ControllerActionInvoker.Next(State& next, Scope& scope, Object& state, Boolean& isCompleted)
   at Microsoft.AspNetCore.Mvc.Internal.ControllerActionInvoker.<InvokeNextResourceFilter>d__22.MoveNext()
--- End of stack trace from previous location where exception was thrown ---
   at System.Runtime.ExceptionServices.ExceptionDispatchInfo.Throw()
   at Microsoft.AspNetCore.Mvc.Internal.ControllerActionInvoker.Rethrow(ResourceExecutedContext context)
   at Microsoft.AspNetCore.Mvc.Internal.ControllerActionInvoker.Next(State& next, Scope& scope, Object& state, Boolean& isCompleted)
   at Microsoft.AspNetCore.Mvc.Internal.ControllerActionInvoker.<InvokeAsync>d__20.MoveNext()
--- End of stack trace from previous location where exception was thrown ---
   at System.Runtime.ExceptionServices.ExceptionDispatchInfo.Throw()
   at System.Runtime.CompilerServices.TaskAwaiter.HandleNonSuccessAndDebuggerNotification(Task task)
   at Microsoft.AspNetCore.Builder.RouterMiddleware.<Invoke>d__4.MoveNext()
--- End of stack trace from previous location where exception was thrown ---
   at System.Runtime.ExceptionServices.ExceptionDispatchInfo.Throw()
   at System.Runtime.CompilerServices.TaskAwaiter.HandleNonSuccessAndDebuggerNotification(Task task)
   at Microsoft.AspNetCore.SpaServices.Webpack.ConditionalProxyMiddleware.<Invoke>d__5.MoveNext()
--- End of stack trace from previous location where exception was thrown ---
   at System.Runtime.ExceptionServices.ExceptionDispatchInfo.Throw()
   at System.Runtime.CompilerServices.TaskAwaiter.HandleNonSuccessAndDebuggerNotification(Task task)
   at Microsoft.AspNetCore.SpaServices.Webpack.ConditionalProxyMiddleware.<Invoke>d__5.MoveNext()
--- End of stack trace from previous location where exception was thrown ---
   at System.Runtime.ExceptionServices.ExceptionDispatchInfo.Throw()
   at System.Runtime.CompilerServices.TaskAwaiter.HandleNonSuccessAndDebuggerNotification(Task task)
   at Microsoft.AspNetCore.Authentication.AuthenticationMiddleware`1.<Invoke>d__18.MoveNext()
--- End of stack trace from previous location where exception was thrown ---
   at System.Runtime.ExceptionServices.ExceptionDispatchInfo.Throw()
   at Microsoft.AspNetCore.Authentication.AuthenticationMiddleware`1.<Invoke>d__18.MoveNext()
--- End of stack trace from previous location where exception was thrown ---
   at System.Runtime.ExceptionServices.ExceptionDispatchInfo.Throw()
   at System.Runtime.CompilerServices.TaskAwaiter.HandleNonSuccessAndDebuggerNotification(Task task)
   at System.Runtime.CompilerServices.TaskAwaiter.GetResult()
   at FundTrack.WebUI.Middlewares.GlobalErrorHandlingMiddleware.<Invoke>d__4.MoveNext() in C:\FundTrack\FundTrack.WebUI\Middlewares\GlobalErrorHandlingMiddleware.cs:line 33
____________________________________________________________________________________________________________________________________________

Date and time:  01.11.2017 10:30:54
Error message:  An exception has been raised that is likely due to a transient failure. If you are connecting to a SQL Azure database consider using SqlAzureExecutionStrategy.
Source:  Microsoft.EntityFrameworkCore.SqlServer
InnerException:  System.Data.SqlClient.SqlException: A connection was successfully established with the server, but then an error occurred during the pre-login handshake. (provider: TCP Provider, error: 0 - An existing connection was forcibly closed by the remote host.) ---> System.ComponentModel.Win32Exception: An existing connection was forcibly closed by the remote host
   --- End of inner exception stack trace ---
   at System.Data.ProviderBase.DbConnectionPool.TryGetConnection(DbConnection owningObject, UInt32 waitForMultipleObjectsTimeout, Boolean allowCreate, Boolean onlyOneCheckConnection, DbConnectionOptions userOptions, DbConnectionInternal& connection)
   at System.Data.ProviderBase.DbConnectionPool.TryGetConnection(DbConnection owningObject, TaskCompletionSource`1 retry, DbConnectionOptions userOptions, DbConnectionInternal& connection)
   at System.Data.ProviderBase.DbConnectionFactory.TryGetConnection(DbConnection owningConnection, TaskCompletionSource`1 retry, DbConnectionOptions userOptions, DbConnectionInternal oldConnection, DbConnectionInternal& connection)
   at System.Data.ProviderBase.DbConnectionInternal.TryOpenConnectionInternal(DbConnection outerConnection, DbConnectionFactory connectionFactory, TaskCompletionSource`1 retry, DbConnectionOptions userOptions)
   at System.Data.SqlClient.SqlConnection.TryOpen(TaskCompletionSource`1 retry)
   at System.Data.SqlClient.SqlConnection.Open()
   at Microsoft.EntityFrameworkCore.Storage.RelationalConnection.Open()
   at Microsoft.EntityFrameworkCore.Query.Internal.QueryingEnumerable.Enumerator.BufferlessMoveNext(Boolean buffer)
   at Microsoft.EntityFrameworkCore.Storage.Internal.SqlServerExecutionStrategy.Execute[TState,TResult](Func`2 operation, Func`2 verifySucceeded, TState state)
ClientConnectionId:1964128b-77fe-4362-8607-fc9c24c1979e
Error Number:10054,State:0,Class:20
StackTrace:     at Microsoft.EntityFrameworkCore.Storage.Internal.SqlServerExecutionStrategy.Execute[TState,TResult](Func`2 operation, Func`2 verifySucceeded, TState state)
   at Microsoft.EntityFrameworkCore.Query.QueryMethodProvider.<_ShapedQuery>d__3`1.MoveNext()
   at Microsoft.EntityFrameworkCore.Query.QueryMethodProvider.<_Include>d__30`1.MoveNext()
   at System.Linq.Enumerable.FirstOrDefault[TSource](IEnumerable`1 source)
   at lambda_method(Closure , QueryContext )
   at Microsoft.EntityFrameworkCore.Query.Internal.QueryCompiler.<>c__DisplayClass20_0`1.<CompileQueryCore>b__0(QueryContext qc)
   at System.Linq.Queryable.FirstOrDefault[TSource](IQueryable`1 source, Expression`1 predicate)
   at FundTrack.DAL.Concrete.OrganizationAccountRepository.GetOrgAccountById(Int32 orgAccountId) in C:\FundTrack\FundTrack.DAL\Concrete\OrganizationAccountRepository.cs:line 106
   at FundTrack.BLL.Concrete.OrganizationAccountService.GetBankAccountIdByOrgAccountId(Int32 orgAccountId) in C:\FundTrack\FundTrack.BLL\Concrete\OrganizationAccountService.cs:line 416
   at FundTrack.WebUI.Controllers.OrgAccountController.GetBankAccountId(Int32 orgAccountId) in C:\FundTrack\FundTrack.WebUI\Controllers\OrgAccountController.cs:line 94
   at lambda_method(Closure , Object , Object[] )
   at Microsoft.AspNetCore.Mvc.Internal.ControllerActionInvoker.<InvokeActionMethodAsync>d__27.MoveNext()
--- End of stack trace from previous location where exception was thrown ---
   at System.Runtime.ExceptionServices.ExceptionDispatchInfo.Throw()
   at System.Runtime.CompilerServices.TaskAwaiter.HandleNonSuccessAndDebuggerNotification(Task task)
   at Microsoft.AspNetCore.Mvc.Internal.ControllerActionInvoker.<InvokeNextActionFilterAsync>d__25.MoveNext()
--- End of stack trace from previous location where exception was thrown ---
   at System.Runtime.ExceptionServices.ExceptionDispatchInfo.Throw()
   at Microsoft.AspNetCore.Mvc.Internal.ControllerActionInvoker.Rethrow(ActionExecutedContext context)
   at Microsoft.AspNetCore.Mvc.Internal.ControllerActionInvoker.Next(State& next, Scope& scope, Object& state, Boolean& isCompleted)
   at Microsoft.AspNetCore.Mvc.Internal.ControllerActionInvoker.<InvokeNextResourceFilter>d__22.MoveNext()
--- End of stack trace from previous location where exception was thrown ---
   at System.Runtime.ExceptionServices.ExceptionDispatchInfo.Throw()
   at Microsoft.AspNetCore.Mvc.Internal.ControllerActionInvoker.Rethrow(ResourceExecutedContext context)
   at Microsoft.AspNetCore.Mvc.Internal.ControllerActionInvoker.Next(State& next, Scope& scope, Object& state, Boolean& isCompleted)
   at Microsoft.AspNetCore.Mvc.Internal.ControllerActionInvoker.<InvokeAsync>d__20.MoveNext()
--- End of stack trace from previous location where exception was thrown ---
   at System.Runtime.ExceptionServices.ExceptionDispatchInfo.Throw()
   at System.Runtime.CompilerServices.TaskAwaiter.HandleNonSuccessAndDebuggerNotification(Task task)
   at Microsoft.AspNetCore.Builder.RouterMiddleware.<Invoke>d__4.MoveNext()
--- End of stack trace from previous location where exception was thrown ---
   at System.Runtime.ExceptionServices.ExceptionDispatchInfo.Throw()
   at System.Runtime.CompilerServices.TaskAwaiter.HandleNonSuccessAndDebuggerNotification(Task task)
   at Microsoft.AspNetCore.SpaServices.Webpack.ConditionalProxyMiddleware.<Invoke>d__5.MoveNext()
--- End of stack trace from previous location where exception was thrown ---
   at System.Runtime.ExceptionServices.ExceptionDispatchInfo.Throw()
   at System.Runtime.CompilerServices.TaskAwaiter.HandleNonSuccessAndDebuggerNotification(Task task)
   at Microsoft.AspNetCore.SpaServices.Webpack.ConditionalProxyMiddleware.<Invoke>d__5.MoveNext()
--- End of stack trace from previous location where exception was thrown ---
   at System.Runtime.ExceptionServices.ExceptionDispatchInfo.Throw()
   at System.Runtime.CompilerServices.TaskAwaiter.HandleNonSuccessAndDebuggerNotification(Task task)
   at Microsoft.AspNetCore.Authentication.AuthenticationMiddleware`1.<Invoke>d__18.MoveNext()
--- End of stack trace from previous location where exception was thrown ---
   at System.Runtime.ExceptionServices.ExceptionDispatchInfo.Throw()
   at Microsoft.AspNetCore.Authentication.AuthenticationMiddleware`1.<Invoke>d__18.MoveNext()
--- End of stack trace from previous location where exception was thrown ---
   at System.Runtime.ExceptionServices.ExceptionDispatchInfo.Throw()
   at System.Runtime.CompilerServices.TaskAwaiter.HandleNonSuccessAndDebuggerNotification(Task task)
   at System.Runtime.CompilerServices.TaskAwaiter.GetResult()
   at FundTrack.WebUI.Middlewares.GlobalErrorHandlingMiddleware.<Invoke>d__4.MoveNext() in C:\FundTrack\FundTrack.WebUI\Middlewares\GlobalErrorHandlingMiddleware.cs:line 33
____________________________________________________________________________________________________________________________________________

Date and time:  01.11.2017 10:30:55
Error message:  An exception has been raised that is likely due to a transient failure. If you are connecting to a SQL Azure database consider using SqlAzureExecutionStrategy.
Source:  Microsoft.EntityFrameworkCore.SqlServer
InnerException:  System.Data.SqlClient.SqlException: A connection was successfully established with the server, but then an error occurred during the pre-login handshake. (provider: TCP Provider, error: 0 - An existing connection was forcibly closed by the remote host.) ---> System.ComponentModel.Win32Exception: An existing connection was forcibly closed by the remote host
   --- End of inner exception stack trace ---
   at System.Data.ProviderBase.DbConnectionPool.TryGetConnection(DbConnection owningObject, UInt32 waitForMultipleObjectsTimeout, Boolean allowCreate, Boolean onlyOneCheckConnection, DbConnectionOptions userOptions, DbConnectionInternal& connection)
   at System.Data.ProviderBase.DbConnectionPool.TryGetConnection(DbConnection owningObject, TaskCompletionSource`1 retry, DbConnectionOptions userOptions, DbConnectionInternal& connection)
   at System.Data.ProviderBase.DbConnectionFactory.TryGetConnection(DbConnection owningConnection, TaskCompletionSource`1 retry, DbConnectionOptions userOptions, DbConnectionInternal oldConnection, DbConnectionInternal& connection)
   at System.Data.ProviderBase.DbConnectionInternal.TryOpenConnectionInternal(DbConnection outerConnection, DbConnectionFactory connectionFactory, TaskCompletionSource`1 retry, DbConnectionOptions userOptions)
   at System.Data.SqlClient.SqlConnection.TryOpen(TaskCompletionSource`1 retry)
   at System.Data.SqlClient.SqlConnection.Open()
   at Microsoft.EntityFrameworkCore.Storage.RelationalConnection.Open()
   at Microsoft.EntityFrameworkCore.Query.Internal.QueryingEnumerable.Enumerator.BufferlessMoveNext(Boolean buffer)
   at Microsoft.EntityFrameworkCore.Storage.Internal.SqlServerExecutionStrategy.Execute[TState,TResult](Func`2 operation, Func`2 verifySucceeded, TState state)
ClientConnectionId:1964128b-77fe-4362-8607-fc9c24c1979e
Error Number:10054,State:0,Class:20
StackTrace:     at Microsoft.EntityFrameworkCore.Storage.Internal.SqlServerExecutionStrategy.Execute[TState,TResult](Func`2 operation, Func`2 verifySucceeded, TState state)
   at Microsoft.EntityFrameworkCore.Query.QueryMethodProvider.<_ShapedQuery>d__3`1.MoveNext()
   at Microsoft.EntityFrameworkCore.Query.QueryMethodProvider.<_Include>d__30`1.MoveNext()
   at System.Linq.Enumerable.FirstOrDefault[TSource](IEnumerable`1 source)
   at lambda_method(Closure , QueryContext )
   at Microsoft.EntityFrameworkCore.Query.Internal.QueryCompiler.<>c__DisplayClass20_0`1.<CompileQueryCore>b__0(QueryContext qc)
   at System.Linq.Queryable.FirstOrDefault[TSource](IQueryable`1 source, Expression`1 predicate)
   at FundTrack.DAL.Concrete.OrganizationAccountRepository.GetOrgAccountById(Int32 orgAccountId) in C:\FundTrack\FundTrack.DAL\Concrete\OrganizationAccountRepository.cs:line 106
   at FundTrack.BLL.Concrete.OrganizationAccountService.IsExtractsConnected(Int32 orgAccountId) in C:\FundTrack\FundTrack.BLL\Concrete\OrganizationAccountService.cs:line 546
   at FundTrack.WebUI.Controllers.OrgAccountController.ExtractStatus(Int32 orgAccountId) in C:\FundTrack\FundTrack.WebUI\Controllers\OrgAccountController.cs:line 139
   at lambda_method(Closure , Object , Object[] )
   at Microsoft.AspNetCore.Mvc.Internal.ControllerActionInvoker.<InvokeActionMethodAsync>d__27.MoveNext()
--- End of stack trace from previous location where exception was thrown ---
   at System.Runtime.ExceptionServices.ExceptionDispatchInfo.Throw()
   at System.Runtime.CompilerServices.TaskAwaiter.HandleNonSuccessAndDebuggerNotification(Task task)
   at Microsoft.AspNetCore.Mvc.Internal.ControllerActionInvoker.<InvokeNextActionFilterAsync>d__25.MoveNext()
--- End of stack trace from previous location where exception was thrown ---
   at System.Runtime.ExceptionServices.ExceptionDispatchInfo.Throw()
   at Microsoft.AspNetCore.Mvc.Internal.ControllerActionInvoker.Rethrow(ActionExecutedContext context)
   at Microsoft.AspNetCore.Mvc.Internal.ControllerActionInvoker.Next(State& next, Scope& scope, Object& state, Boolean& isCompleted)
   at Microsoft.AspNetCore.Mvc.Internal.ControllerActionInvoker.<InvokeNextResourceFilter>d__22.MoveNext()
--- End of stack trace from previous location where exception was thrown ---
   at System.Runtime.ExceptionServices.ExceptionDispatchInfo.Throw()
   at Microsoft.AspNetCore.Mvc.Internal.ControllerActionInvoker.Rethrow(ResourceExecutedContext context)
   at Microsoft.AspNetCore.Mvc.Internal.ControllerActionInvoker.Next(State& next, Scope& scope, Object& state, Boolean& isCompleted)
   at Microsoft.AspNetCore.Mvc.Internal.ControllerActionInvoker.<InvokeAsync>d__20.MoveNext()
--- End of stack trace from previous location where exception was thrown ---
   at System.Runtime.ExceptionServices.ExceptionDispatchInfo.Throw()
   at System.Runtime.CompilerServices.TaskAwaiter.HandleNonSuccessAndDebuggerNotification(Task task)
   at Microsoft.AspNetCore.Builder.RouterMiddleware.<Invoke>d__4.MoveNext()
--- End of stack trace from previous location where exception was thrown ---
   at System.Runtime.ExceptionServices.ExceptionDispatchInfo.Throw()
   at System.Runtime.CompilerServices.TaskAwaiter.HandleNonSuccessAndDebuggerNotification(Task task)
   at Microsoft.AspNetCore.SpaServices.Webpack.ConditionalProxyMiddleware.<Invoke>d__5.MoveNext()
--- End of stack trace from previous location where exception was thrown ---
   at System.Runtime.ExceptionServices.ExceptionDispatchInfo.Throw()
   at System.Runtime.CompilerServices.TaskAwaiter.HandleNonSuccessAndDebuggerNotification(Task task)
   at Microsoft.AspNetCore.SpaServices.Webpack.ConditionalProxyMiddleware.<Invoke>d__5.MoveNext()
--- End of stack trace from previous location where exception was thrown ---
   at System.Runtime.ExceptionServices.ExceptionDispatchInfo.Throw()
   at System.Runtime.CompilerServices.TaskAwaiter.HandleNonSuccessAndDebuggerNotification(Task task)
   at Microsoft.AspNetCore.Authentication.AuthenticationMiddleware`1.<Invoke>d__18.MoveNext()
--- End of stack trace from previous location where exception was thrown ---
   at System.Runtime.ExceptionServices.ExceptionDispatchInfo.Throw()
   at Microsoft.AspNetCore.Authentication.AuthenticationMiddleware`1.<Invoke>d__18.MoveNext()
--- End of stack trace from previous location where exception was thrown ---
   at System.Runtime.ExceptionServices.ExceptionDispatchInfo.Throw()
   at System.Runtime.CompilerServices.TaskAwaiter.HandleNonSuccessAndDebuggerNotification(Task task)
   at System.Runtime.CompilerServices.TaskAwaiter.GetResult()
   at FundTrack.WebUI.Middlewares.GlobalErrorHandlingMiddleware.<Invoke>d__4.MoveNext() in C:\FundTrack\FundTrack.WebUI\Middlewares\GlobalErrorHandlingMiddleware.cs:line 33
____________________________________________________________________________________________________________________________________________

Date and time:  01.11.2017 10:53:07
Error message:  Неможливо виконати фінансову операцію "Розхід"
Source:  FundTrack.BLL
InnerException:  FundTrack.BLL.Concrete.BusinessLogicException: Неможливо виконати фінансову операцію "Розхід" ---> System.NullReferenceException: Object reference not set to an instance of an object.
   at FundTrack.BLL.Concrete.FinOpService.CreateSpending(FinOpViewModel finOpModel) in C:\FundTrack\FundTrack.BLL\Concrete\FinOpService.cs:line 124
   --- End of inner exception stack trace ---
   at FundTrack.BLL.Concrete.FinOpService.CreateSpending(FinOpViewModel finOpModel) in C:\FundTrack\FundTrack.BLL\Concrete\FinOpService.cs:line 146
   at FundTrack.BLL.Concrete.FinOpService.CreateFinOp(FinOpFromBankViewModel finOpModel) in C:\FundTrack\FundTrack.BLL\Concrete\FinOpService.cs:line 44
StackTrace:     at FundTrack.BLL.Concrete.FinOpService.CreateFinOp(FinOpFromBankViewModel finOpModel) in C:\FundTrack\FundTrack.BLL\Concrete\FinOpService.cs:line 60
   at FundTrack.WebUI.Controllers.FinOpController.CreateFinOp(FinOpFromBankViewModel finOpModel) in C:\FundTrack\FundTrack.WebUI\Controllers\FinOpController.cs:line 51
   at lambda_method(Closure , Object , Object[] )
   at Microsoft.AspNetCore.Mvc.Internal.ControllerActionInvoker.<InvokeActionMethodAsync>d__27.MoveNext()
--- End of stack trace from previous location where exception was thrown ---
   at System.Runtime.ExceptionServices.ExceptionDispatchInfo.Throw()
   at System.Runtime.CompilerServices.TaskAwaiter.HandleNonSuccessAndDebuggerNotification(Task task)
   at Microsoft.AspNetCore.Mvc.Internal.ControllerActionInvoker.<InvokeNextActionFilterAsync>d__25.MoveNext()
--- End of stack trace from previous location where exception was thrown ---
   at System.Runtime.ExceptionServices.ExceptionDispatchInfo.Throw()
   at Microsoft.AspNetCore.Mvc.Internal.ControllerActionInvoker.Rethrow(ActionExecutedContext context)
   at Microsoft.AspNetCore.Mvc.Internal.ControllerActionInvoker.Next(State& next, Scope& scope, Object& state, Boolean& isCompleted)
   at Microsoft.AspNetCore.Mvc.Internal.ControllerActionInvoker.<InvokeNextResourceFilter>d__22.MoveNext()
--- End of stack trace from previous location where exception was thrown ---
   at System.Runtime.ExceptionServices.ExceptionDispatchInfo.Throw()
   at Microsoft.AspNetCore.Mvc.Internal.ControllerActionInvoker.Rethrow(ResourceExecutedContext context)
   at Microsoft.AspNetCore.Mvc.Internal.ControllerActionInvoker.Next(State& next, Scope& scope, Object& state, Boolean& isCompleted)
   at Microsoft.AspNetCore.Mvc.Internal.ControllerActionInvoker.<InvokeAsync>d__20.MoveNext()
--- End of stack trace from previous location where exception was thrown ---
   at System.Runtime.ExceptionServices.ExceptionDispatchInfo.Throw()
   at System.Runtime.CompilerServices.TaskAwaiter.HandleNonSuccessAndDebuggerNotification(Task task)
   at Microsoft.AspNetCore.Builder.RouterMiddleware.<Invoke>d__4.MoveNext()
--- End of stack trace from previous location where exception was thrown ---
   at System.Runtime.ExceptionServices.ExceptionDispatchInfo.Throw()
   at System.Runtime.CompilerServices.TaskAwaiter.HandleNonSuccessAndDebuggerNotification(Task task)
   at Microsoft.AspNetCore.SpaServices.Webpack.ConditionalProxyMiddleware.<Invoke>d__5.MoveNext()
--- End of stack trace from previous location where exception was thrown ---
   at System.Runtime.ExceptionServices.ExceptionDispatchInfo.Throw()
   at System.Runtime.CompilerServices.TaskAwaiter.HandleNonSuccessAndDebuggerNotification(Task task)
   at Microsoft.AspNetCore.SpaServices.Webpack.ConditionalProxyMiddleware.<Invoke>d__5.MoveNext()
--- End of stack trace from previous location where exception was thrown ---
   at System.Runtime.ExceptionServices.ExceptionDispatchInfo.Throw()
   at System.Runtime.CompilerServices.TaskAwaiter.HandleNonSuccessAndDebuggerNotification(Task task)
   at Microsoft.AspNetCore.Authentication.AuthenticationMiddleware`1.<Invoke>d__18.MoveNext()
--- End of stack trace from previous location where exception was thrown ---
   at System.Runtime.ExceptionServices.ExceptionDispatchInfo.Throw()
   at Microsoft.AspNetCore.Authentication.AuthenticationMiddleware`1.<Invoke>d__18.MoveNext()
--- End of stack trace from previous location where exception was thrown ---
   at System.Runtime.ExceptionServices.ExceptionDispatchInfo.Throw()
   at System.Runtime.CompilerServices.TaskAwaiter.HandleNonSuccessAndDebuggerNotification(Task task)
   at System.Runtime.CompilerServices.TaskAwaiter.GetResult()
   at FundTrack.WebUI.Middlewares.GlobalErrorHandlingMiddleware.<Invoke>d__4.MoveNext() in C:\FundTrack\FundTrack.WebUI\Middlewares\GlobalErrorHandlingMiddleware.cs:line 33
____________________________________________________________________________________________________________________________________________

Date and time:  01.11.2017 10:53:09
Error message:  Неможливо виконати фінансову операцію "Розхід"
Source:  FundTrack.BLL
InnerException:  FundTrack.BLL.Concrete.BusinessLogicException: Неможливо виконати фінансову операцію "Розхід" ---> System.NullReferenceException: Object reference not set to an instance of an object.
   at FundTrack.BLL.Concrete.FinOpService.CreateSpending(FinOpViewModel finOpModel) in C:\FundTrack\FundTrack.BLL\Concrete\FinOpService.cs:line 124
   --- End of inner exception stack trace ---
   at FundTrack.BLL.Concrete.FinOpService.CreateSpending(FinOpViewModel finOpModel) in C:\FundTrack\FundTrack.BLL\Concrete\FinOpService.cs:line 146
   at FundTrack.BLL.Concrete.FinOpService.CreateFinOp(FinOpFromBankViewModel finOpModel) in C:\FundTrack\FundTrack.BLL\Concrete\FinOpService.cs:line 44
StackTrace:     at FundTrack.BLL.Concrete.FinOpService.CreateFinOp(FinOpFromBankViewModel finOpModel) in C:\FundTrack\FundTrack.BLL\Concrete\FinOpService.cs:line 60
   at FundTrack.WebUI.Controllers.FinOpController.CreateFinOp(FinOpFromBankViewModel finOpModel) in C:\FundTrack\FundTrack.WebUI\Controllers\FinOpController.cs:line 51
   at lambda_method(Closure , Object , Object[] )
   at Microsoft.AspNetCore.Mvc.Internal.ControllerActionInvoker.<InvokeActionMethodAsync>d__27.MoveNext()
--- End of stack trace from previous location where exception was thrown ---
   at System.Runtime.ExceptionServices.ExceptionDispatchInfo.Throw()
   at System.Runtime.CompilerServices.TaskAwaiter.HandleNonSuccessAndDebuggerNotification(Task task)
   at Microsoft.AspNetCore.Mvc.Internal.ControllerActionInvoker.<InvokeNextActionFilterAsync>d__25.MoveNext()
--- End of stack trace from previous location where exception was thrown ---
   at System.Runtime.ExceptionServices.ExceptionDispatchInfo.Throw()
   at Microsoft.AspNetCore.Mvc.Internal.ControllerActionInvoker.Rethrow(ActionExecutedContext context)
   at Microsoft.AspNetCore.Mvc.Internal.ControllerActionInvoker.Next(State& next, Scope& scope, Object& state, Boolean& isCompleted)
   at Microsoft.AspNetCore.Mvc.Internal.ControllerActionInvoker.<InvokeNextResourceFilter>d__22.MoveNext()
--- End of stack trace from previous location where exception was thrown ---
   at System.Runtime.ExceptionServices.ExceptionDispatchInfo.Throw()
   at Microsoft.AspNetCore.Mvc.Internal.ControllerActionInvoker.Rethrow(ResourceExecutedContext context)
   at Microsoft.AspNetCore.Mvc.Internal.ControllerActionInvoker.Next(State& next, Scope& scope, Object& state, Boolean& isCompleted)
   at Microsoft.AspNetCore.Mvc.Internal.ControllerActionInvoker.<InvokeAsync>d__20.MoveNext()
--- End of stack trace from previous location where exception was thrown ---
   at System.Runtime.ExceptionServices.ExceptionDispatchInfo.Throw()
   at System.Runtime.CompilerServices.TaskAwaiter.HandleNonSuccessAndDebuggerNotification(Task task)
   at Microsoft.AspNetCore.Builder.RouterMiddleware.<Invoke>d__4.MoveNext()
--- End of stack trace from previous location where exception was thrown ---
   at System.Runtime.ExceptionServices.ExceptionDispatchInfo.Throw()
   at System.Runtime.CompilerServices.TaskAwaiter.HandleNonSuccessAndDebuggerNotification(Task task)
   at Microsoft.AspNetCore.SpaServices.Webpack.ConditionalProxyMiddleware.<Invoke>d__5.MoveNext()
--- End of stack trace from previous location where exception was thrown ---
   at System.Runtime.ExceptionServices.ExceptionDispatchInfo.Throw()
   at System.Runtime.CompilerServices.TaskAwaiter.HandleNonSuccessAndDebuggerNotification(Task task)
   at Microsoft.AspNetCore.SpaServices.Webpack.ConditionalProxyMiddleware.<Invoke>d__5.MoveNext()
--- End of stack trace from previous location where exception was thrown ---
   at System.Runtime.ExceptionServices.ExceptionDispatchInfo.Throw()
   at System.Runtime.CompilerServices.TaskAwaiter.HandleNonSuccessAndDebuggerNotification(Task task)
   at Microsoft.AspNetCore.Authentication.AuthenticationMiddleware`1.<Invoke>d__18.MoveNext()
--- End of stack trace from previous location where exception was thrown ---
   at System.Runtime.ExceptionServices.ExceptionDispatchInfo.Throw()
   at Microsoft.AspNetCore.Authentication.AuthenticationMiddleware`1.<Invoke>d__18.MoveNext()
--- End of stack trace from previous location where exception was thrown ---
   at System.Runtime.ExceptionServices.ExceptionDispatchInfo.Throw()
   at System.Runtime.CompilerServices.TaskAwaiter.HandleNonSuccessAndDebuggerNotification(Task task)
   at System.Runtime.CompilerServices.TaskAwaiter.GetResult()
   at FundTrack.WebUI.Middlewares.GlobalErrorHandlingMiddleware.<Invoke>d__4.MoveNext() in C:\FundTrack\FundTrack.WebUI\Middlewares\GlobalErrorHandlingMiddleware.cs:line 33
____________________________________________________________________________________________________________________________________________

Date and time:  01.11.2017 10:53:10
Error message:  Неможливо виконати фінансову операцію "Розхід"
Source:  FundTrack.BLL
InnerException:  FundTrack.BLL.Concrete.BusinessLogicException: Неможливо виконати фінансову операцію "Розхід" ---> System.NullReferenceException: Object reference not set to an instance of an object.
   at FundTrack.BLL.Concrete.FinOpService.CreateSpending(FinOpViewModel finOpModel) in C:\FundTrack\FundTrack.BLL\Concrete\FinOpService.cs:line 124
   --- End of inner exception stack trace ---
   at FundTrack.BLL.Concrete.FinOpService.CreateSpending(FinOpViewModel finOpModel) in C:\FundTrack\FundTrack.BLL\Concrete\FinOpService.cs:line 146
   at FundTrack.BLL.Concrete.FinOpService.CreateFinOp(FinOpFromBankViewModel finOpModel) in C:\FundTrack\FundTrack.BLL\Concrete\FinOpService.cs:line 44
StackTrace:     at FundTrack.BLL.Concrete.FinOpService.CreateFinOp(FinOpFromBankViewModel finOpModel) in C:\FundTrack\FundTrack.BLL\Concrete\FinOpService.cs:line 60
   at FundTrack.WebUI.Controllers.FinOpController.CreateFinOp(FinOpFromBankViewModel finOpModel) in C:\FundTrack\FundTrack.WebUI\Controllers\FinOpController.cs:line 51
   at lambda_method(Closure , Object , Object[] )
   at Microsoft.AspNetCore.Mvc.Internal.ControllerActionInvoker.<InvokeActionMethodAsync>d__27.MoveNext()
--- End of stack trace from previous location where exception was thrown ---
   at System.Runtime.ExceptionServices.ExceptionDispatchInfo.Throw()
   at System.Runtime.CompilerServices.TaskAwaiter.HandleNonSuccessAndDebuggerNotification(Task task)
   at Microsoft.AspNetCore.Mvc.Internal.ControllerActionInvoker.<InvokeNextActionFilterAsync>d__25.MoveNext()
--- End of stack trace from previous location where exception was thrown ---
   at System.Runtime.ExceptionServices.ExceptionDispatchInfo.Throw()
   at Microsoft.AspNetCore.Mvc.Internal.ControllerActionInvoker.Rethrow(ActionExecutedContext context)
   at Microsoft.AspNetCore.Mvc.Internal.ControllerActionInvoker.Next(State& next, Scope& scope, Object& state, Boolean& isCompleted)
   at Microsoft.AspNetCore.Mvc.Internal.ControllerActionInvoker.<InvokeNextResourceFilter>d__22.MoveNext()
--- End of stack trace from previous location where exception was thrown ---
   at System.Runtime.ExceptionServices.ExceptionDispatchInfo.Throw()
   at Microsoft.AspNetCore.Mvc.Internal.ControllerActionInvoker.Rethrow(ResourceExecutedContext context)
   at Microsoft.AspNetCore.Mvc.Internal.ControllerActionInvoker.Next(State& next, Scope& scope, Object& state, Boolean& isCompleted)
   at Microsoft.AspNetCore.Mvc.Internal.ControllerActionInvoker.<InvokeAsync>d__20.MoveNext()
--- End of stack trace from previous location where exception was thrown ---
   at System.Runtime.ExceptionServices.ExceptionDispatchInfo.Throw()
   at System.Runtime.CompilerServices.TaskAwaiter.HandleNonSuccessAndDebuggerNotification(Task task)
   at Microsoft.AspNetCore.Builder.RouterMiddleware.<Invoke>d__4.MoveNext()
--- End of stack trace from previous location where exception was thrown ---
   at System.Runtime.ExceptionServices.ExceptionDispatchInfo.Throw()
   at System.Runtime.CompilerServices.TaskAwaiter.HandleNonSuccessAndDebuggerNotification(Task task)
   at Microsoft.AspNetCore.SpaServices.Webpack.ConditionalProxyMiddleware.<Invoke>d__5.MoveNext()
--- End of stack trace from previous location where exception was thrown ---
   at System.Runtime.ExceptionServices.ExceptionDispatchInfo.Throw()
   at System.Runtime.CompilerServices.TaskAwaiter.HandleNonSuccessAndDebuggerNotification(Task task)
   at Microsoft.AspNetCore.SpaServices.Webpack.ConditionalProxyMiddleware.<Invoke>d__5.MoveNext()
--- End of stack trace from previous location where exception was thrown ---
   at System.Runtime.ExceptionServices.ExceptionDispatchInfo.Throw()
   at System.Runtime.CompilerServices.TaskAwaiter.HandleNonSuccessAndDebuggerNotification(Task task)
   at Microsoft.AspNetCore.Authentication.AuthenticationMiddleware`1.<Invoke>d__18.MoveNext()
--- End of stack trace from previous location where exception was thrown ---
   at System.Runtime.ExceptionServices.ExceptionDispatchInfo.Throw()
   at Microsoft.AspNetCore.Authentication.AuthenticationMiddleware`1.<Invoke>d__18.MoveNext()
--- End of stack trace from previous location where exception was thrown ---
   at System.Runtime.ExceptionServices.ExceptionDispatchInfo.Throw()
   at System.Runtime.CompilerServices.TaskAwaiter.HandleNonSuccessAndDebuggerNotification(Task task)
   at System.Runtime.CompilerServices.TaskAwaiter.GetResult()
   at FundTrack.WebUI.Middlewares.GlobalErrorHandlingMiddleware.<Invoke>d__4.MoveNext() in C:\FundTrack\FundTrack.WebUI\Middlewares\GlobalErrorHandlingMiddleware.cs:line 33
____________________________________________________________________________________________________________________________________________

Date and time:  01.11.2017 10:55:30
Error message:  Неможливо виконати фінансову операцію "Розхід"
Source:  FundTrack.BLL
InnerException:  FundTrack.BLL.Concrete.BusinessLogicException: Неможливо виконати фінансову операцію "Розхід" ---> System.NullReferenceException: Object reference not set to an instance of an object.
   at FundTrack.BLL.Concrete.FinOpService.CreateSpending(FinOpViewModel finOpModel) in C:\FundTrack\FundTrack.BLL\Concrete\FinOpService.cs:line 124
   --- End of inner exception stack trace ---
   at FundTrack.BLL.Concrete.FinOpService.CreateSpending(FinOpViewModel finOpModel) in C:\FundTrack\FundTrack.BLL\Concrete\FinOpService.cs:line 146
   at FundTrack.BLL.Concrete.FinOpService.CreateFinOp(FinOpFromBankViewModel finOpModel) in C:\FundTrack\FundTrack.BLL\Concrete\FinOpService.cs:line 44
StackTrace:     at FundTrack.BLL.Concrete.FinOpService.CreateFinOp(FinOpFromBankViewModel finOpModel) in C:\FundTrack\FundTrack.BLL\Concrete\FinOpService.cs:line 60
   at FundTrack.WebUI.Controllers.FinOpController.CreateFinOp(FinOpFromBankViewModel finOpModel) in C:\FundTrack\FundTrack.WebUI\Controllers\FinOpController.cs:line 51
   at lambda_method(Closure , Object , Object[] )
   at Microsoft.AspNetCore.Mvc.Internal.ControllerActionInvoker.<InvokeActionMethodAsync>d__27.MoveNext()
--- End of stack trace from previous location where exception was thrown ---
   at System.Runtime.ExceptionServices.ExceptionDispatchInfo.Throw()
   at System.Runtime.CompilerServices.TaskAwaiter.HandleNonSuccessAndDebuggerNotification(Task task)
   at Microsoft.AspNetCore.Mvc.Internal.ControllerActionInvoker.<InvokeNextActionFilterAsync>d__25.MoveNext()
--- End of stack trace from previous location where exception was thrown ---
   at System.Runtime.ExceptionServices.ExceptionDispatchInfo.Throw()
   at Microsoft.AspNetCore.Mvc.Internal.ControllerActionInvoker.Rethrow(ActionExecutedContext context)
   at Microsoft.AspNetCore.Mvc.Internal.ControllerActionInvoker.Next(State& next, Scope& scope, Object& state, Boolean& isCompleted)
   at Microsoft.AspNetCore.Mvc.Internal.ControllerActionInvoker.<InvokeNextResourceFilter>d__22.MoveNext()
--- End of stack trace from previous location where exception was thrown ---
   at System.Runtime.ExceptionServices.ExceptionDispatchInfo.Throw()
   at Microsoft.AspNetCore.Mvc.Internal.ControllerActionInvoker.Rethrow(ResourceExecutedContext context)
   at Microsoft.AspNetCore.Mvc.Internal.ControllerActionInvoker.Next(State& next, Scope& scope, Object& state, Boolean& isCompleted)
   at Microsoft.AspNetCore.Mvc.Internal.ControllerActionInvoker.<InvokeAsync>d__20.MoveNext()
--- End of stack trace from previous location where exception was thrown ---
   at System.Runtime.ExceptionServices.ExceptionDispatchInfo.Throw()
   at System.Runtime.CompilerServices.TaskAwaiter.HandleNonSuccessAndDebuggerNotification(Task task)
   at Microsoft.AspNetCore.Builder.RouterMiddleware.<Invoke>d__4.MoveNext()
--- End of stack trace from previous location where exception was thrown ---
   at System.Runtime.ExceptionServices.ExceptionDispatchInfo.Throw()
   at System.Runtime.CompilerServices.TaskAwaiter.HandleNonSuccessAndDebuggerNotification(Task task)
   at Microsoft.AspNetCore.SpaServices.Webpack.ConditionalProxyMiddleware.<Invoke>d__5.MoveNext()
--- End of stack trace from previous location where exception was thrown ---
   at System.Runtime.ExceptionServices.ExceptionDispatchInfo.Throw()
   at System.Runtime.CompilerServices.TaskAwaiter.HandleNonSuccessAndDebuggerNotification(Task task)
   at Microsoft.AspNetCore.SpaServices.Webpack.ConditionalProxyMiddleware.<Invoke>d__5.MoveNext()
--- End of stack trace from previous location where exception was thrown ---
   at System.Runtime.ExceptionServices.ExceptionDispatchInfo.Throw()
   at System.Runtime.CompilerServices.TaskAwaiter.HandleNonSuccessAndDebuggerNotification(Task task)
   at Microsoft.AspNetCore.Authentication.AuthenticationMiddleware`1.<Invoke>d__18.MoveNext()
--- End of stack trace from previous location where exception was thrown ---
   at System.Runtime.ExceptionServices.ExceptionDispatchInfo.Throw()
   at Microsoft.AspNetCore.Authentication.AuthenticationMiddleware`1.<Invoke>d__18.MoveNext()
--- End of stack trace from previous location where exception was thrown ---
   at System.Runtime.ExceptionServices.ExceptionDispatchInfo.Throw()
   at System.Runtime.CompilerServices.TaskAwaiter.HandleNonSuccessAndDebuggerNotification(Task task)
   at System.Runtime.CompilerServices.TaskAwaiter.GetResult()
   at FundTrack.WebUI.Middlewares.GlobalErrorHandlingMiddleware.<Invoke>d__4.MoveNext() in C:\FundTrack\FundTrack.WebUI\Middlewares\GlobalErrorHandlingMiddleware.cs:line 33
____________________________________________________________________________________________________________________________________________

Date and time:  01.11.2017 11:02:22
Error message:  Неможливо виконати фінансову операцію "Розхід"
Source:  FundTrack.BLL
InnerException:  FundTrack.BLL.Concrete.BusinessLogicException: Неможливо виконати фінансову операцію "Розхід" ---> System.NullReferenceException: Object reference not set to an instance of an object.
   at FundTrack.BLL.Concrete.FinOpService.CreateSpending(FinOpViewModel finOpModel) in C:\FundTrack\FundTrack.BLL\Concrete\FinOpService.cs:line 124
   --- End of inner exception stack trace ---
   at FundTrack.BLL.Concrete.FinOpService.CreateSpending(FinOpViewModel finOpModel) in C:\FundTrack\FundTrack.BLL\Concrete\FinOpService.cs:line 146
   at FundTrack.BLL.Concrete.FinOpService.CreateFinOp(FinOpFromBankViewModel finOpModel) in C:\FundTrack\FundTrack.BLL\Concrete\FinOpService.cs:line 44
StackTrace:     at FundTrack.BLL.Concrete.FinOpService.CreateFinOp(FinOpFromBankViewModel finOpModel) in C:\FundTrack\FundTrack.BLL\Concrete\FinOpService.cs:line 60
   at FundTrack.WebUI.Controllers.FinOpController.CreateFinOp(FinOpFromBankViewModel finOpModel) in C:\FundTrack\FundTrack.WebUI\Controllers\FinOpController.cs:line 51
   at lambda_method(Closure , Object , Object[] )
   at Microsoft.AspNetCore.Mvc.Internal.ControllerActionInvoker.<InvokeActionMethodAsync>d__27.MoveNext()
--- End of stack trace from previous location where exception was thrown ---
   at System.Runtime.ExceptionServices.ExceptionDispatchInfo.Throw()
   at System.Runtime.CompilerServices.TaskAwaiter.HandleNonSuccessAndDebuggerNotification(Task task)
   at Microsoft.AspNetCore.Mvc.Internal.ControllerActionInvoker.<InvokeNextActionFilterAsync>d__25.MoveNext()
--- End of stack trace from previous location where exception was thrown ---
   at System.Runtime.ExceptionServices.ExceptionDispatchInfo.Throw()
   at Microsoft.AspNetCore.Mvc.Internal.ControllerActionInvoker.Rethrow(ActionExecutedContext context)
   at Microsoft.AspNetCore.Mvc.Internal.ControllerActionInvoker.Next(State& next, Scope& scope, Object& state, Boolean& isCompleted)
   at Microsoft.AspNetCore.Mvc.Internal.ControllerActionInvoker.<InvokeNextResourceFilter>d__22.MoveNext()
--- End of stack trace from previous location where exception was thrown ---
   at System.Runtime.ExceptionServices.ExceptionDispatchInfo.Throw()
   at Microsoft.AspNetCore.Mvc.Internal.ControllerActionInvoker.Rethrow(ResourceExecutedContext context)
   at Microsoft.AspNetCore.Mvc.Internal.ControllerActionInvoker.Next(State& next, Scope& scope, Object& state, Boolean& isCompleted)
   at Microsoft.AspNetCore.Mvc.Internal.ControllerActionInvoker.<InvokeAsync>d__20.MoveNext()
--- End of stack trace from previous location where exception was thrown ---
   at System.Runtime.ExceptionServices.ExceptionDispatchInfo.Throw()
   at System.Runtime.CompilerServices.TaskAwaiter.HandleNonSuccessAndDebuggerNotification(Task task)
   at Microsoft.AspNetCore.Builder.RouterMiddleware.<Invoke>d__4.MoveNext()
--- End of stack trace from previous location where exception was thrown ---
   at System.Runtime.ExceptionServices.ExceptionDispatchInfo.Throw()
   at System.Runtime.CompilerServices.TaskAwaiter.HandleNonSuccessAndDebuggerNotification(Task task)
   at Microsoft.AspNetCore.SpaServices.Webpack.ConditionalProxyMiddleware.<Invoke>d__5.MoveNext()
--- End of stack trace from previous location where exception was thrown ---
   at System.Runtime.ExceptionServices.ExceptionDispatchInfo.Throw()
   at System.Runtime.CompilerServices.TaskAwaiter.HandleNonSuccessAndDebuggerNotification(Task task)
   at Microsoft.AspNetCore.SpaServices.Webpack.ConditionalProxyMiddleware.<Invoke>d__5.MoveNext()
--- End of stack trace from previous location where exception was thrown ---
   at System.Runtime.ExceptionServices.ExceptionDispatchInfo.Throw()
   at System.Runtime.CompilerServices.TaskAwaiter.HandleNonSuccessAndDebuggerNotification(Task task)
   at Microsoft.AspNetCore.Authentication.AuthenticationMiddleware`1.<Invoke>d__18.MoveNext()
--- End of stack trace from previous location where exception was thrown ---
   at System.Runtime.ExceptionServices.ExceptionDispatchInfo.Throw()
   at Microsoft.AspNetCore.Authentication.AuthenticationMiddleware`1.<Invoke>d__18.MoveNext()
--- End of stack trace from previous location where exception was thrown ---
   at System.Runtime.ExceptionServices.ExceptionDispatchInfo.Throw()
   at System.Runtime.CompilerServices.TaskAwaiter.HandleNonSuccessAndDebuggerNotification(Task task)
   at System.Runtime.CompilerServices.TaskAwaiter.GetResult()
   at FundTrack.WebUI.Middlewares.GlobalErrorHandlingMiddleware.<Invoke>d__4.MoveNext() in C:\FundTrack\FundTrack.WebUI\Middlewares\GlobalErrorHandlingMiddleware.cs:line 33
____________________________________________________________________________________________________________________________________________

