Date and time:  15.11.2017 17:12:09
Error message:  Неможливо виконати фінансову операцію "Прихід"
Source:  FundTrack.BLL
InnerException:  System.ArgumentException: An item with the same key has already been added. Key: 1
   at System.ThrowHelper.ThrowAddingDuplicateWithKeyArgumentException(Object key)
   at System.Collections.Generic.Dictionary`2.TryInsert(TKey key, TValue value, InsertionBehavior behavior)
   at Microsoft.EntityFrameworkCore.Storage.Internal.InMemoryTable`1.Create(IUpdateEntry entry)
   at Microsoft.EntityFrameworkCore.Storage.Internal.InMemoryStore.ExecuteTransaction(IEnumerable`1 entries, ILogger`1 logger)
   at Microsoft.EntityFrameworkCore.ChangeTracking.Internal.StateManager.SaveChanges(IReadOnlyList`1 entriesToSave)
   at Microsoft.EntityFrameworkCore.ChangeTracking.Internal.StateManager.SaveChanges(Boolean acceptAllChangesOnSuccess)
   at Microsoft.EntityFrameworkCore.DbContext.SaveChanges(Boolean acceptAllChangesOnSuccess)
   at FundTrack.DAL.Concrete.UnitOfWork.SaveChanges() in C:\FundTrack\FundTrack.DAL\Concrete\UnitOfWork.cs:line 470
   at FundTrack.BLL.Concrete.FinOpService.CreateIncome(FinOpViewModel finOpModel) in C:\FundTrack\FundTrack.BLL\Concrete\FinOpService.cs:line 147
StackTrace:     at FundTrack.BLL.Concrete.FinOpService.CreateIncome(FinOpViewModel finOpModel) in C:\FundTrack\FundTrack.BLL\Concrete\FinOpService.cs:line 152
   at FundTrack.WebUI.Controllers.FinOpController.Income(FinOpViewModel incomeModel) in C:\FundTrack\FundTrack.WebUI\Controllers\FinOpController.cs:line 130
   at lambda_method(Closure , Object , Object[] )
   at Microsoft.AspNetCore.Mvc.Internal.ControllerActionInvoker.<InvokeActionMethodAsync>d__27.MoveNext()
--- End of stack trace from previous location where exception was thrown ---
   at System.Runtime.ExceptionServices.ExceptionDispatchInfo.Throw()
   at System.Runtime.CompilerServices.TaskAwaiter.HandleNonSuccessAndDebuggerNotification(Task task)
   at Microsoft.AspNetCore.Mvc.Internal.ControllerActionInvoker.<InvokeNextActionFilterAsync>d__25.MoveNext()
--- End of stack trace from previous location where exception was thrown ---
   at System.Runtime.ExceptionServices.ExceptionDispatchInfo.Throw()
   at Microsoft.AspNetCore.Mvc.Internal.ControllerActionInvoker.Rethrow(ActionExecutedContext context)
   at Microsoft.AspNetCore.Mvc.Internal.ControllerActionInvoker.Next(State& next, Scope& scope, Object& state, Boolean& isCompleted)
   at Microsoft.AspNetCore.Mvc.Internal.ControllerActionInvoker.<InvokeNextResourceFilter>d__22.MoveNext()
--- End of stack trace from previous location where exception was thrown ---
   at System.Runtime.ExceptionServices.ExceptionDispatchInfo.Throw()
   at Microsoft.AspNetCore.Mvc.Internal.ControllerActionInvoker.Rethrow(ResourceExecutedContext context)
   at Microsoft.AspNetCore.Mvc.Internal.ControllerActionInvoker.Next(State& next, Scope& scope, Object& state, Boolean& isCompleted)
   at Microsoft.AspNetCore.Mvc.Internal.ControllerActionInvoker.<InvokeAsync>d__20.MoveNext()
--- End of stack trace from previous location where exception was thrown ---
   at System.Runtime.ExceptionServices.ExceptionDispatchInfo.Throw()
   at System.Runtime.CompilerServices.TaskAwaiter.HandleNonSuccessAndDebuggerNotification(Task task)
   at Microsoft.AspNetCore.Builder.RouterMiddleware.<Invoke>d__4.MoveNext()
--- End of stack trace from previous location where exception was thrown ---
   at System.Runtime.ExceptionServices.ExceptionDispatchInfo.Throw()
   at System.Runtime.CompilerServices.TaskAwaiter.HandleNonSuccessAndDebuggerNotification(Task task)
   at Microsoft.AspNetCore.Authentication.AuthenticationMiddleware`1.<Invoke>d__18.MoveNext()
--- End of stack trace from previous location where exception was thrown ---
   at System.Runtime.ExceptionServices.ExceptionDispatchInfo.Throw()
   at Microsoft.AspNetCore.Authentication.AuthenticationMiddleware`1.<Invoke>d__18.MoveNext()
--- End of stack trace from previous location where exception was thrown ---
   at System.Runtime.ExceptionServices.ExceptionDispatchInfo.Throw()
   at System.Runtime.CompilerServices.TaskAwaiter.HandleNonSuccessAndDebuggerNotification(Task task)
   at FundTrack.WebUI.Middlewares.GlobalErrorHandlingMiddleware.<Invoke>d__4.MoveNext() in C:\FundTrack\FundTrack.WebUI\Middlewares\GlobalErrorHandlingMiddleware.cs:line 33
____________________________________________________________________________________________________________________________________________

Date and time:  15.11.2017 17:20:14
Error message:  Неможливо виконати фінансову операцію "Прихід"
Source:  FundTrack.BLL
InnerException:  System.ArgumentException: An item with the same key has already been added. Key: 1
   at System.ThrowHelper.ThrowAddingDuplicateWithKeyArgumentException(Object key)
   at System.Collections.Generic.Dictionary`2.TryInsert(TKey key, TValue value, InsertionBehavior behavior)
   at Microsoft.EntityFrameworkCore.Storage.Internal.InMemoryTable`1.Create(IUpdateEntry entry)
   at Microsoft.EntityFrameworkCore.Storage.Internal.InMemoryStore.ExecuteTransaction(IEnumerable`1 entries, ILogger`1 logger)
   at Microsoft.EntityFrameworkCore.ChangeTracking.Internal.StateManager.SaveChanges(IReadOnlyList`1 entriesToSave)
   at Microsoft.EntityFrameworkCore.ChangeTracking.Internal.StateManager.SaveChanges(Boolean acceptAllChangesOnSuccess)
   at Microsoft.EntityFrameworkCore.DbContext.SaveChanges(Boolean acceptAllChangesOnSuccess)
   at FundTrack.DAL.Concrete.UnitOfWork.SaveChanges() in C:\FundTrack\FundTrack.DAL\Concrete\UnitOfWork.cs:line 470
   at FundTrack.BLL.Concrete.FinOpService.CreateIncome(FinOpViewModel finOpModel) in C:\FundTrack\FundTrack.BLL\Concrete\FinOpService.cs:line 147
StackTrace:     at FundTrack.BLL.Concrete.FinOpService.CreateIncome(FinOpViewModel finOpModel) in C:\FundTrack\FundTrack.BLL\Concrete\FinOpService.cs:line 152
   at FundTrack.WebUI.Controllers.FinOpController.Income(FinOpViewModel incomeModel) in C:\FundTrack\FundTrack.WebUI\Controllers\FinOpController.cs:line 130
   at lambda_method(Closure , Object , Object[] )
   at Microsoft.AspNetCore.Mvc.Internal.ControllerActionInvoker.<InvokeActionMethodAsync>d__27.MoveNext()
--- End of stack trace from previous location where exception was thrown ---
   at System.Runtime.ExceptionServices.ExceptionDispatchInfo.Throw()
   at System.Runtime.CompilerServices.TaskAwaiter.HandleNonSuccessAndDebuggerNotification(Task task)
   at Microsoft.AspNetCore.Mvc.Internal.ControllerActionInvoker.<InvokeNextActionFilterAsync>d__25.MoveNext()
--- End of stack trace from previous location where exception was thrown ---
   at System.Runtime.ExceptionServices.ExceptionDispatchInfo.Throw()
   at Microsoft.AspNetCore.Mvc.Internal.ControllerActionInvoker.Rethrow(ActionExecutedContext context)
   at Microsoft.AspNetCore.Mvc.Internal.ControllerActionInvoker.Next(State& next, Scope& scope, Object& state, Boolean& isCompleted)
   at Microsoft.AspNetCore.Mvc.Internal.ControllerActionInvoker.<InvokeNextResourceFilter>d__22.MoveNext()
--- End of stack trace from previous location where exception was thrown ---
   at System.Runtime.ExceptionServices.ExceptionDispatchInfo.Throw()
   at Microsoft.AspNetCore.Mvc.Internal.ControllerActionInvoker.Rethrow(ResourceExecutedContext context)
   at Microsoft.AspNetCore.Mvc.Internal.ControllerActionInvoker.Next(State& next, Scope& scope, Object& state, Boolean& isCompleted)
   at Microsoft.AspNetCore.Mvc.Internal.ControllerActionInvoker.<InvokeAsync>d__20.MoveNext()
--- End of stack trace from previous location where exception was thrown ---
   at System.Runtime.ExceptionServices.ExceptionDispatchInfo.Throw()
   at System.Runtime.CompilerServices.TaskAwaiter.HandleNonSuccessAndDebuggerNotification(Task task)
   at Microsoft.AspNetCore.Builder.RouterMiddleware.<Invoke>d__4.MoveNext()
--- End of stack trace from previous location where exception was thrown ---
   at System.Runtime.ExceptionServices.ExceptionDispatchInfo.Throw()
   at System.Runtime.CompilerServices.TaskAwaiter.HandleNonSuccessAndDebuggerNotification(Task task)
   at Microsoft.AspNetCore.Authentication.AuthenticationMiddleware`1.<Invoke>d__18.MoveNext()
--- End of stack trace from previous location where exception was thrown ---
   at System.Runtime.ExceptionServices.ExceptionDispatchInfo.Throw()
   at Microsoft.AspNetCore.Authentication.AuthenticationMiddleware`1.<Invoke>d__18.MoveNext()
--- End of stack trace from previous location where exception was thrown ---
   at System.Runtime.ExceptionServices.ExceptionDispatchInfo.Throw()
   at System.Runtime.CompilerServices.TaskAwaiter.HandleNonSuccessAndDebuggerNotification(Task task)
   at FundTrack.WebUI.Middlewares.GlobalErrorHandlingMiddleware.<Invoke>d__4.MoveNext() in C:\FundTrack\FundTrack.WebUI\Middlewares\GlobalErrorHandlingMiddleware.cs:line 33
____________________________________________________________________________________________________________________________________________

Date and time:  15.11.2017 17:26:21
Error message:  Неможливо виконати фінансову операцію "Прихід"
Source:  FundTrack.BLL
InnerException:  System.ArgumentException: An item with the same key has already been added. Key: 1
   at System.ThrowHelper.ThrowAddingDuplicateWithKeyArgumentException(Object key)
   at System.Collections.Generic.Dictionary`2.TryInsert(TKey key, TValue value, InsertionBehavior behavior)
   at Microsoft.EntityFrameworkCore.Storage.Internal.InMemoryTable`1.Create(IUpdateEntry entry)
   at Microsoft.EntityFrameworkCore.Storage.Internal.InMemoryStore.ExecuteTransaction(IEnumerable`1 entries, ILogger`1 logger)
   at Microsoft.EntityFrameworkCore.ChangeTracking.Internal.StateManager.SaveChanges(IReadOnlyList`1 entriesToSave)
   at Microsoft.EntityFrameworkCore.ChangeTracking.Internal.StateManager.SaveChanges(Boolean acceptAllChangesOnSuccess)
   at Microsoft.EntityFrameworkCore.DbContext.SaveChanges(Boolean acceptAllChangesOnSuccess)
   at FundTrack.DAL.Concrete.UnitOfWork.SaveChanges() in C:\FundTrack\FundTrack.DAL\Concrete\UnitOfWork.cs:line 470
   at FundTrack.BLL.Concrete.FinOpService.CreateIncome(FinOpViewModel finOpModel) in C:\FundTrack\FundTrack.BLL\Concrete\FinOpService.cs:line 147
StackTrace:     at FundTrack.BLL.Concrete.FinOpService.CreateIncome(FinOpViewModel finOpModel) in C:\FundTrack\FundTrack.BLL\Concrete\FinOpService.cs:line 152
   at FundTrack.WebUI.Controllers.FinOpController.Income(FinOpViewModel incomeModel) in C:\FundTrack\FundTrack.WebUI\Controllers\FinOpController.cs:line 130
   at lambda_method(Closure , Object , Object[] )
   at Microsoft.AspNetCore.Mvc.Internal.ControllerActionInvoker.<InvokeActionMethodAsync>d__27.MoveNext()
--- End of stack trace from previous location where exception was thrown ---
   at System.Runtime.ExceptionServices.ExceptionDispatchInfo.Throw()
   at System.Runtime.CompilerServices.TaskAwaiter.HandleNonSuccessAndDebuggerNotification(Task task)
   at Microsoft.AspNetCore.Mvc.Internal.ControllerActionInvoker.<InvokeNextActionFilterAsync>d__25.MoveNext()
--- End of stack trace from previous location where exception was thrown ---
   at System.Runtime.ExceptionServices.ExceptionDispatchInfo.Throw()
   at Microsoft.AspNetCore.Mvc.Internal.ControllerActionInvoker.Rethrow(ActionExecutedContext context)
   at Microsoft.AspNetCore.Mvc.Internal.ControllerActionInvoker.Next(State& next, Scope& scope, Object& state, Boolean& isCompleted)
   at Microsoft.AspNetCore.Mvc.Internal.ControllerActionInvoker.<InvokeNextResourceFilter>d__22.MoveNext()
--- End of stack trace from previous location where exception was thrown ---
   at System.Runtime.ExceptionServices.ExceptionDispatchInfo.Throw()
   at Microsoft.AspNetCore.Mvc.Internal.ControllerActionInvoker.Rethrow(ResourceExecutedContext context)
   at Microsoft.AspNetCore.Mvc.Internal.ControllerActionInvoker.Next(State& next, Scope& scope, Object& state, Boolean& isCompleted)
   at Microsoft.AspNetCore.Mvc.Internal.ControllerActionInvoker.<InvokeAsync>d__20.MoveNext()
--- End of stack trace from previous location where exception was thrown ---
   at System.Runtime.ExceptionServices.ExceptionDispatchInfo.Throw()
   at System.Runtime.CompilerServices.TaskAwaiter.HandleNonSuccessAndDebuggerNotification(Task task)
   at Microsoft.AspNetCore.Builder.RouterMiddleware.<Invoke>d__4.MoveNext()
--- End of stack trace from previous location where exception was thrown ---
   at System.Runtime.ExceptionServices.ExceptionDispatchInfo.Throw()
   at System.Runtime.CompilerServices.TaskAwaiter.HandleNonSuccessAndDebuggerNotification(Task task)
   at Microsoft.AspNetCore.Authentication.AuthenticationMiddleware`1.<Invoke>d__18.MoveNext()
--- End of stack trace from previous location where exception was thrown ---
   at System.Runtime.ExceptionServices.ExceptionDispatchInfo.Throw()
   at Microsoft.AspNetCore.Authentication.AuthenticationMiddleware`1.<Invoke>d__18.MoveNext()
--- End of stack trace from previous location where exception was thrown ---
   at System.Runtime.ExceptionServices.ExceptionDispatchInfo.Throw()
   at System.Runtime.CompilerServices.TaskAwaiter.HandleNonSuccessAndDebuggerNotification(Task task)
   at FundTrack.WebUI.Middlewares.GlobalErrorHandlingMiddleware.<Invoke>d__4.MoveNext() in C:\FundTrack\FundTrack.WebUI\Middlewares\GlobalErrorHandlingMiddleware.cs:line 33
____________________________________________________________________________________________________________________________________________

Date and time:  15.11.2017 17:41:48
Error message:  Неможливо виконати фінансову операцію "Прихід"
Source:  FundTrack.BLL
InnerException:  System.InvalidOperationException: The instance of entity type 'FinOp' cannot be tracked because another instance of this type with the same key is already being tracked. When adding new entities, for most key types a unique temporary key value will be created if no key is set (i.e. if the key property is assigned the default value for its type). If you are explicitly setting key values for new entities, ensure they do not collide with existing entities or temporary values generated for other new entities. When attaching existing entities, ensure that only one entity instance with a given key value is attached to the context.
   at Microsoft.EntityFrameworkCore.ChangeTracking.Internal.IdentityMap`1.Add(TKey key, InternalEntityEntry entry)
   at Microsoft.EntityFrameworkCore.ChangeTracking.Internal.StateManager.StartTracking(InternalEntityEntry entry)
   at Microsoft.EntityFrameworkCore.ChangeTracking.Internal.InternalEntityEntry.SetEntityState(EntityState oldState, EntityState newState, Boolean acceptChanges)
   at Microsoft.EntityFrameworkCore.ChangeTracking.Internal.EntityGraphAttacher.PaintAction(EntityEntryGraphNode node)
   at Microsoft.EntityFrameworkCore.ChangeTracking.Internal.EntityEntryGraphIterator.TraverseGraph(EntityEntryGraphNode node, Func`2 handleNode)
   at Microsoft.EntityFrameworkCore.DbContext.SetEntityState[TEntity](TEntity entity, EntityState entityState)
   at FundTrack.DAL.Concrete.FinOpRepository.Create(FinOp finOp) in C:\FundTrack\FundTrack.DAL\Concrete\FinOpRepository.cs:line 28
   at FundTrack.BLL.Concrete.FinOpService.CreateIncome(FinOpViewModel finOpModel) in C:\FundTrack\FundTrack.BLL\Concrete\FinOpService.cs:line 144
StackTrace:     at FundTrack.BLL.Concrete.FinOpService.CreateIncome(FinOpViewModel finOpModel) in C:\FundTrack\FundTrack.BLL\Concrete\FinOpService.cs:line 152
   at FundTrack.WebUI.Controllers.FinOpController.Income(FinOpViewModel incomeModel) in C:\FundTrack\FundTrack.WebUI\Controllers\FinOpController.cs:line 130
   at lambda_method(Closure , Object , Object[] )
   at Microsoft.AspNetCore.Mvc.Internal.ControllerActionInvoker.<InvokeActionMethodAsync>d__27.MoveNext()
--- End of stack trace from previous location where exception was thrown ---
   at System.Runtime.ExceptionServices.ExceptionDispatchInfo.Throw()
   at System.Runtime.CompilerServices.TaskAwaiter.HandleNonSuccessAndDebuggerNotification(Task task)
   at Microsoft.AspNetCore.Mvc.Internal.ControllerActionInvoker.<InvokeNextActionFilterAsync>d__25.MoveNext()
--- End of stack trace from previous location where exception was thrown ---
   at System.Runtime.ExceptionServices.ExceptionDispatchInfo.Throw()
   at Microsoft.AspNetCore.Mvc.Internal.ControllerActionInvoker.Rethrow(ActionExecutedContext context)
   at Microsoft.AspNetCore.Mvc.Internal.ControllerActionInvoker.Next(State& next, Scope& scope, Object& state, Boolean& isCompleted)
   at Microsoft.AspNetCore.Mvc.Internal.ControllerActionInvoker.<InvokeNextResourceFilter>d__22.MoveNext()
--- End of stack trace from previous location where exception was thrown ---
   at System.Runtime.ExceptionServices.ExceptionDispatchInfo.Throw()
   at Microsoft.AspNetCore.Mvc.Internal.ControllerActionInvoker.Rethrow(ResourceExecutedContext context)
   at Microsoft.AspNetCore.Mvc.Internal.ControllerActionInvoker.Next(State& next, Scope& scope, Object& state, Boolean& isCompleted)
   at Microsoft.AspNetCore.Mvc.Internal.ControllerActionInvoker.<InvokeAsync>d__20.MoveNext()
--- End of stack trace from previous location where exception was thrown ---
   at System.Runtime.ExceptionServices.ExceptionDispatchInfo.Throw()
   at System.Runtime.CompilerServices.TaskAwaiter.HandleNonSuccessAndDebuggerNotification(Task task)
   at Microsoft.AspNetCore.Builder.RouterMiddleware.<Invoke>d__4.MoveNext()
--- End of stack trace from previous location where exception was thrown ---
   at System.Runtime.ExceptionServices.ExceptionDispatchInfo.Throw()
   at System.Runtime.CompilerServices.TaskAwaiter.HandleNonSuccessAndDebuggerNotification(Task task)
   at Microsoft.AspNetCore.Authentication.AuthenticationMiddleware`1.<Invoke>d__18.MoveNext()
--- End of stack trace from previous location where exception was thrown ---
   at System.Runtime.ExceptionServices.ExceptionDispatchInfo.Throw()
   at Microsoft.AspNetCore.Authentication.AuthenticationMiddleware`1.<Invoke>d__18.MoveNext()
--- End of stack trace from previous location where exception was thrown ---
   at System.Runtime.ExceptionServices.ExceptionDispatchInfo.Throw()
   at System.Runtime.CompilerServices.TaskAwaiter.HandleNonSuccessAndDebuggerNotification(Task task)
   at FundTrack.WebUI.Middlewares.GlobalErrorHandlingMiddleware.<Invoke>d__4.MoveNext() in C:\FundTrack\FundTrack.WebUI\Middlewares\GlobalErrorHandlingMiddleware.cs:line 33
____________________________________________________________________________________________________________________________________________

Date and time:  15.11.2017 17:42:13
Error message:  Неможливо виконати фінансову операцію "Прихід"
Source:  FundTrack.BLL
InnerException:  System.ArgumentException: An item with the same key has already been added. Key: 1
   at System.ThrowHelper.ThrowAddingDuplicateWithKeyArgumentException(Object key)
   at System.Collections.Generic.Dictionary`2.TryInsert(TKey key, TValue value, InsertionBehavior behavior)
   at Microsoft.EntityFrameworkCore.Storage.Internal.InMemoryTable`1.Create(IUpdateEntry entry)
   at Microsoft.EntityFrameworkCore.Storage.Internal.InMemoryStore.ExecuteTransaction(IEnumerable`1 entries, ILogger`1 logger)
   at Microsoft.EntityFrameworkCore.ChangeTracking.Internal.StateManager.SaveChanges(IReadOnlyList`1 entriesToSave)
   at Microsoft.EntityFrameworkCore.ChangeTracking.Internal.StateManager.SaveChanges(Boolean acceptAllChangesOnSuccess)
   at Microsoft.EntityFrameworkCore.DbContext.SaveChanges(Boolean acceptAllChangesOnSuccess)
   at FundTrack.DAL.Concrete.UnitOfWork.SaveChanges() in C:\FundTrack\FundTrack.DAL\Concrete\UnitOfWork.cs:line 470
   at FundTrack.BLL.Concrete.FinOpService.CreateIncome(FinOpViewModel finOpModel) in C:\FundTrack\FundTrack.BLL\Concrete\FinOpService.cs:line 147
StackTrace:     at FundTrack.BLL.Concrete.FinOpService.CreateIncome(FinOpViewModel finOpModel) in C:\FundTrack\FundTrack.BLL\Concrete\FinOpService.cs:line 152
   at FundTrack.WebUI.Controllers.FinOpController.Income(FinOpViewModel incomeModel) in C:\FundTrack\FundTrack.WebUI\Controllers\FinOpController.cs:line 130
   at lambda_method(Closure , Object , Object[] )
   at Microsoft.AspNetCore.Mvc.Internal.ControllerActionInvoker.<InvokeActionMethodAsync>d__27.MoveNext()
--- End of stack trace from previous location where exception was thrown ---
   at System.Runtime.ExceptionServices.ExceptionDispatchInfo.Throw()
   at System.Runtime.CompilerServices.TaskAwaiter.HandleNonSuccessAndDebuggerNotification(Task task)
   at Microsoft.AspNetCore.Mvc.Internal.ControllerActionInvoker.<InvokeNextActionFilterAsync>d__25.MoveNext()
--- End of stack trace from previous location where exception was thrown ---
   at System.Runtime.ExceptionServices.ExceptionDispatchInfo.Throw()
   at Microsoft.AspNetCore.Mvc.Internal.ControllerActionInvoker.Rethrow(ActionExecutedContext context)
   at Microsoft.AspNetCore.Mvc.Internal.ControllerActionInvoker.Next(State& next, Scope& scope, Object& state, Boolean& isCompleted)
   at Microsoft.AspNetCore.Mvc.Internal.ControllerActionInvoker.<InvokeNextResourceFilter>d__22.MoveNext()
--- End of stack trace from previous location where exception was thrown ---
   at System.Runtime.ExceptionServices.ExceptionDispatchInfo.Throw()
   at Microsoft.AspNetCore.Mvc.Internal.ControllerActionInvoker.Rethrow(ResourceExecutedContext context)
   at Microsoft.AspNetCore.Mvc.Internal.ControllerActionInvoker.Next(State& next, Scope& scope, Object& state, Boolean& isCompleted)
   at Microsoft.AspNetCore.Mvc.Internal.ControllerActionInvoker.<InvokeAsync>d__20.MoveNext()
--- End of stack trace from previous location where exception was thrown ---
   at System.Runtime.ExceptionServices.ExceptionDispatchInfo.Throw()
   at System.Runtime.CompilerServices.TaskAwaiter.HandleNonSuccessAndDebuggerNotification(Task task)
   at Microsoft.AspNetCore.Builder.RouterMiddleware.<Invoke>d__4.MoveNext()
--- End of stack trace from previous location where exception was thrown ---
   at System.Runtime.ExceptionServices.ExceptionDispatchInfo.Throw()
   at System.Runtime.CompilerServices.TaskAwaiter.HandleNonSuccessAndDebuggerNotification(Task task)
   at Microsoft.AspNetCore.Authentication.AuthenticationMiddleware`1.<Invoke>d__18.MoveNext()
--- End of stack trace from previous location where exception was thrown ---
   at System.Runtime.ExceptionServices.ExceptionDispatchInfo.Throw()
   at Microsoft.AspNetCore.Authentication.AuthenticationMiddleware`1.<Invoke>d__18.MoveNext()
--- End of stack trace from previous location where exception was thrown ---
   at System.Runtime.ExceptionServices.ExceptionDispatchInfo.Throw()
   at System.Runtime.CompilerServices.TaskAwaiter.HandleNonSuccessAndDebuggerNotification(Task task)
   at FundTrack.WebUI.Middlewares.GlobalErrorHandlingMiddleware.<Invoke>d__4.MoveNext() in C:\FundTrack\FundTrack.WebUI\Middlewares\GlobalErrorHandlingMiddleware.cs:line 33
____________________________________________________________________________________________________________________________________________

Date and time:  15.11.2017 18:00:11
Error message:  The request was aborted or the pipeline has finished
Source:  Microsoft.AspNetCore.TestHost
InnerException:  
StackTrace:     at Microsoft.AspNetCore.TestHost.ResponseStream.CheckNotComplete()
   at Microsoft.AspNetCore.TestHost.ResponseStream.Write(Byte[] buffer, Int32 offset, Int32 count)
   at Microsoft.AspNetCore.TestHost.ResponseStream.WriteAsync(Byte[] buffer, Int32 offset, Int32 count, CancellationToken cancellationToken)
   at Microsoft.AspNetCore.WebUtilities.HttpResponseStreamWriter.<FlushInternalAsync>d__26.MoveNext()
--- End of stack trace from previous location where exception was thrown ---
   at System.Runtime.ExceptionServices.ExceptionDispatchInfo.Throw()
   at System.Runtime.CompilerServices.TaskAwaiter.HandleNonSuccessAndDebuggerNotification(Task task)
   at Microsoft.AspNetCore.Mvc.Formatters.JsonOutputFormatter.<WriteResponseBodyAsync>d__11.MoveNext()
--- End of stack trace from previous location where exception was thrown ---
   at System.Runtime.ExceptionServices.ExceptionDispatchInfo.Throw()
   at System.Runtime.CompilerServices.TaskAwaiter.HandleNonSuccessAndDebuggerNotification(Task task)
   at Microsoft.AspNetCore.Mvc.Internal.ControllerActionInvoker.<InvokeResultAsync>d__30.MoveNext()
--- End of stack trace from previous location where exception was thrown ---
   at System.Runtime.ExceptionServices.ExceptionDispatchInfo.Throw()
   at System.Runtime.CompilerServices.TaskAwaiter.HandleNonSuccessAndDebuggerNotification(Task task)
   at Microsoft.AspNetCore.Mvc.Internal.ControllerActionInvoker.<InvokeNextResultFilterAsync>d__28.MoveNext()
--- End of stack trace from previous location where exception was thrown ---
   at System.Runtime.ExceptionServices.ExceptionDispatchInfo.Throw()
   at Microsoft.AspNetCore.Mvc.Internal.ControllerActionInvoker.Rethrow(ResultExecutedContext context)
   at Microsoft.AspNetCore.Mvc.Internal.ControllerActionInvoker.Next(State& next, Scope& scope, Object& state, Boolean& isCompleted)
   at Microsoft.AspNetCore.Mvc.Internal.ControllerActionInvoker.<InvokeNextResourceFilter>d__22.MoveNext()
--- End of stack trace from previous location where exception was thrown ---
   at System.Runtime.ExceptionServices.ExceptionDispatchInfo.Throw()
   at Microsoft.AspNetCore.Mvc.Internal.ControllerActionInvoker.Rethrow(ResourceExecutedContext context)
   at Microsoft.AspNetCore.Mvc.Internal.ControllerActionInvoker.Next(State& next, Scope& scope, Object& state, Boolean& isCompleted)
   at Microsoft.AspNetCore.Mvc.Internal.ControllerActionInvoker.<InvokeAsync>d__20.MoveNext()
--- End of stack trace from previous location where exception was thrown ---
   at System.Runtime.ExceptionServices.ExceptionDispatchInfo.Throw()
   at System.Runtime.CompilerServices.TaskAwaiter.HandleNonSuccessAndDebuggerNotification(Task task)
   at Microsoft.AspNetCore.Builder.RouterMiddleware.<Invoke>d__4.MoveNext()
--- End of stack trace from previous location where exception was thrown ---
   at System.Runtime.ExceptionServices.ExceptionDispatchInfo.Throw()
   at System.Runtime.CompilerServices.TaskAwaiter.HandleNonSuccessAndDebuggerNotification(Task task)
   at Microsoft.AspNetCore.Authentication.AuthenticationMiddleware`1.<Invoke>d__18.MoveNext()
--- End of stack trace from previous location where exception was thrown ---
   at System.Runtime.ExceptionServices.ExceptionDispatchInfo.Throw()
   at Microsoft.AspNetCore.Authentication.AuthenticationMiddleware`1.<Invoke>d__18.MoveNext()
--- End of stack trace from previous location where exception was thrown ---
   at System.Runtime.ExceptionServices.ExceptionDispatchInfo.Throw()
   at System.Runtime.CompilerServices.TaskAwaiter.HandleNonSuccessAndDebuggerNotification(Task task)
   at FundTrack.WebUI.Middlewares.GlobalErrorHandlingMiddleware.<Invoke>d__4.MoveNext() in C:\FundTrack\FundTrack.WebUI\Middlewares\GlobalErrorHandlingMiddleware.cs:line 33
____________________________________________________________________________________________________________________________________________

