Date and time:  16.11.2017 11:24:35
Error message:  The request was aborted or the pipeline has finished
Source:  Microsoft.AspNetCore.TestHost
InnerException:  
StackTrace:     at Microsoft.AspNetCore.TestHost.ResponseStream.CheckNotComplete()
   at Microsoft.AspNetCore.TestHost.ResponseStream.Write(Byte[] buffer, Int32 offset, Int32 count)
   at Microsoft.AspNetCore.TestHost.ResponseStream.WriteAsync(Byte[] buffer, Int32 offset, Int32 count, CancellationToken cancellationToken)
   at Microsoft.AspNetCore.WebUtilities.HttpResponseStreamWriter.<FlushInternalAsync>d__26.MoveNext()
--- End of stack trace from previous location where exception was thrown ---
   at System.Runtime.ExceptionServices.ExceptionDispatchInfo.Throw()
   at System.Runtime.CompilerServices.TaskAwaiter.HandleNonSuccessAndDebuggerNotification(Task task)
   at Microsoft.AspNetCore.Mvc.Formatters.JsonOutputFormatter.<WriteResponseBodyAsync>d__11.MoveNext()
--- End of stack trace from previous location where exception was thrown ---
   at System.Runtime.ExceptionServices.ExceptionDispatchInfo.Throw()
   at System.Runtime.CompilerServices.TaskAwaiter.HandleNonSuccessAndDebuggerNotification(Task task)
   at Microsoft.AspNetCore.Mvc.Internal.ControllerActionInvoker.<InvokeResultAsync>d__30.MoveNext()
--- End of stack trace from previous location where exception was thrown ---
   at System.Runtime.ExceptionServices.ExceptionDispatchInfo.Throw()
   at System.Runtime.CompilerServices.TaskAwaiter.HandleNonSuccessAndDebuggerNotification(Task task)
   at Microsoft.AspNetCore.Mvc.Internal.ControllerActionInvoker.<InvokeNextResultFilterAsync>d__28.MoveNext()
--- End of stack trace from previous location where exception was thrown ---
   at System.Runtime.ExceptionServices.ExceptionDispatchInfo.Throw()
   at Microsoft.AspNetCore.Mvc.Internal.ControllerActionInvoker.Rethrow(ResultExecutedContext context)
   at Microsoft.AspNetCore.Mvc.Internal.ControllerActionInvoker.Next(State& next, Scope& scope, Object& state, Boolean& isCompleted)
   at Microsoft.AspNetCore.Mvc.Internal.ControllerActionInvoker.<InvokeNextResourceFilter>d__22.MoveNext()
--- End of stack trace from previous location where exception was thrown ---
   at System.Runtime.ExceptionServices.ExceptionDispatchInfo.Throw()
   at Microsoft.AspNetCore.Mvc.Internal.ControllerActionInvoker.Rethrow(ResourceExecutedContext context)
   at Microsoft.AspNetCore.Mvc.Internal.ControllerActionInvoker.Next(State& next, Scope& scope, Object& state, Boolean& isCompleted)
   at Microsoft.AspNetCore.Mvc.Internal.ControllerActionInvoker.<InvokeAsync>d__20.MoveNext()
--- End of stack trace from previous location where exception was thrown ---
   at System.Runtime.ExceptionServices.ExceptionDispatchInfo.Throw()
   at System.Runtime.CompilerServices.TaskAwaiter.HandleNonSuccessAndDebuggerNotification(Task task)
   at Microsoft.AspNetCore.Builder.RouterMiddleware.<Invoke>d__4.MoveNext()
--- End of stack trace from previous location where exception was thrown ---
   at System.Runtime.ExceptionServices.ExceptionDispatchInfo.Throw()
   at System.Runtime.CompilerServices.TaskAwaiter.HandleNonSuccessAndDebuggerNotification(Task task)
   at Microsoft.AspNetCore.Authentication.AuthenticationMiddleware`1.<Invoke>d__18.MoveNext()
--- End of stack trace from previous location where exception was thrown ---
   at System.Runtime.ExceptionServices.ExceptionDispatchInfo.Throw()
   at Microsoft.AspNetCore.Authentication.AuthenticationMiddleware`1.<Invoke>d__18.MoveNext()
--- End of stack trace from previous location where exception was thrown ---
   at System.Runtime.ExceptionServices.ExceptionDispatchInfo.Throw()
   at System.Runtime.CompilerServices.TaskAwaiter.HandleNonSuccessAndDebuggerNotification(Task task)
   at FundTrack.WebUI.Middlewares.GlobalErrorHandlingMiddleware.<Invoke>d__4.MoveNext() in C:\FundTrack\FundTrack.WebUI\Middlewares\GlobalErrorHandlingMiddleware.cs:line 33
____________________________________________________________________________________________________________________________________________

Date and time:  16.11.2017 11:32:28
Error message:  The request was aborted or the pipeline has finished
Source:  Microsoft.AspNetCore.TestHost
InnerException:  
StackTrace:     at Microsoft.AspNetCore.TestHost.ResponseStream.CheckNotComplete()
   at Microsoft.AspNetCore.TestHost.ResponseStream.Write(Byte[] buffer, Int32 offset, Int32 count)
   at Microsoft.AspNetCore.TestHost.ResponseStream.WriteAsync(Byte[] buffer, Int32 offset, Int32 count, CancellationToken cancellationToken)
   at Microsoft.AspNetCore.WebUtilities.HttpResponseStreamWriter.<FlushInternalAsync>d__26.MoveNext()
--- End of stack trace from previous location where exception was thrown ---
   at System.Runtime.ExceptionServices.ExceptionDispatchInfo.Throw()
   at System.Runtime.CompilerServices.TaskAwaiter.HandleNonSuccessAndDebuggerNotification(Task task)
   at Microsoft.AspNetCore.Mvc.Formatters.JsonOutputFormatter.<WriteResponseBodyAsync>d__11.MoveNext()
--- End of stack trace from previous location where exception was thrown ---
   at System.Runtime.ExceptionServices.ExceptionDispatchInfo.Throw()
   at System.Runtime.CompilerServices.TaskAwaiter.HandleNonSuccessAndDebuggerNotification(Task task)
   at Microsoft.AspNetCore.Mvc.Internal.ControllerActionInvoker.<InvokeResultAsync>d__30.MoveNext()
--- End of stack trace from previous location where exception was thrown ---
   at System.Runtime.ExceptionServices.ExceptionDispatchInfo.Throw()
   at System.Runtime.CompilerServices.TaskAwaiter.HandleNonSuccessAndDebuggerNotification(Task task)
   at Microsoft.AspNetCore.Mvc.Internal.ControllerActionInvoker.<InvokeNextResultFilterAsync>d__28.MoveNext()
--- End of stack trace from previous location where exception was thrown ---
   at System.Runtime.ExceptionServices.ExceptionDispatchInfo.Throw()
   at Microsoft.AspNetCore.Mvc.Internal.ControllerActionInvoker.Rethrow(ResultExecutedContext context)
   at Microsoft.AspNetCore.Mvc.Internal.ControllerActionInvoker.Next(State& next, Scope& scope, Object& state, Boolean& isCompleted)
   at Microsoft.AspNetCore.Mvc.Internal.ControllerActionInvoker.<InvokeNextResourceFilter>d__22.MoveNext()
--- End of stack trace from previous location where exception was thrown ---
   at System.Runtime.ExceptionServices.ExceptionDispatchInfo.Throw()
   at Microsoft.AspNetCore.Mvc.Internal.ControllerActionInvoker.Rethrow(ResourceExecutedContext context)
   at Microsoft.AspNetCore.Mvc.Internal.ControllerActionInvoker.Next(State& next, Scope& scope, Object& state, Boolean& isCompleted)
   at Microsoft.AspNetCore.Mvc.Internal.ControllerActionInvoker.<InvokeAsync>d__20.MoveNext()
--- End of stack trace from previous location where exception was thrown ---
   at System.Runtime.ExceptionServices.ExceptionDispatchInfo.Throw()
   at System.Runtime.CompilerServices.TaskAwaiter.HandleNonSuccessAndDebuggerNotification(Task task)
   at Microsoft.AspNetCore.Builder.RouterMiddleware.<Invoke>d__4.MoveNext()
--- End of stack trace from previous location where exception was thrown ---
   at System.Runtime.ExceptionServices.ExceptionDispatchInfo.Throw()
   at System.Runtime.CompilerServices.TaskAwaiter.HandleNonSuccessAndDebuggerNotification(Task task)
   at Microsoft.AspNetCore.Authentication.AuthenticationMiddleware`1.<Invoke>d__18.MoveNext()
--- End of stack trace from previous location where exception was thrown ---
   at System.Runtime.ExceptionServices.ExceptionDispatchInfo.Throw()
   at Microsoft.AspNetCore.Authentication.AuthenticationMiddleware`1.<Invoke>d__18.MoveNext()
--- End of stack trace from previous location where exception was thrown ---
   at System.Runtime.ExceptionServices.ExceptionDispatchInfo.Throw()
   at System.Runtime.CompilerServices.TaskAwaiter.HandleNonSuccessAndDebuggerNotification(Task task)
   at FundTrack.WebUI.Middlewares.GlobalErrorHandlingMiddleware.<Invoke>d__4.MoveNext() in C:\FundTrack\FundTrack.WebUI\Middlewares\GlobalErrorHandlingMiddleware.cs:line 33
____________________________________________________________________________________________________________________________________________

Date and time:  16.11.2017 12:19:37
Error message:  The view 'Index' was not found. The following locations were searched:
/Views/Home/Index.cshtml
/Views/Shared/Index.cshtml
Source:  Microsoft.AspNetCore.Mvc.ViewFeatures
InnerException:  
StackTrace:     at Microsoft.AspNetCore.Mvc.ViewEngines.ViewEngineResult.EnsureSuccessful(IEnumerable`1 originalLocations)
   at Microsoft.AspNetCore.Mvc.ViewResult.<ExecuteResultAsync>d__26.MoveNext()
--- End of stack trace from previous location where exception was thrown ---
   at System.Runtime.ExceptionServices.ExceptionDispatchInfo.Throw()
   at System.Runtime.CompilerServices.TaskAwaiter.HandleNonSuccessAndDebuggerNotification(Task task)
   at Microsoft.AspNetCore.Mvc.Internal.ControllerActionInvoker.<InvokeResultAsync>d__30.MoveNext()
--- End of stack trace from previous location where exception was thrown ---
   at System.Runtime.ExceptionServices.ExceptionDispatchInfo.Throw()
   at System.Runtime.CompilerServices.TaskAwaiter.HandleNonSuccessAndDebuggerNotification(Task task)
   at Microsoft.AspNetCore.Mvc.Internal.ControllerActionInvoker.<InvokeNextResultFilterAsync>d__28.MoveNext()
--- End of stack trace from previous location where exception was thrown ---
   at System.Runtime.ExceptionServices.ExceptionDispatchInfo.Throw()
   at Microsoft.AspNetCore.Mvc.Internal.ControllerActionInvoker.Rethrow(ResultExecutedContext context)
   at Microsoft.AspNetCore.Mvc.Internal.ControllerActionInvoker.Next(State& next, Scope& scope, Object& state, Boolean& isCompleted)
   at Microsoft.AspNetCore.Mvc.Internal.ControllerActionInvoker.<InvokeNextResourceFilter>d__22.MoveNext()
--- End of stack trace from previous location where exception was thrown ---
   at System.Runtime.ExceptionServices.ExceptionDispatchInfo.Throw()
   at Microsoft.AspNetCore.Mvc.Internal.ControllerActionInvoker.Rethrow(ResourceExecutedContext context)
   at Microsoft.AspNetCore.Mvc.Internal.ControllerActionInvoker.Next(State& next, Scope& scope, Object& state, Boolean& isCompleted)
   at Microsoft.AspNetCore.Mvc.Internal.ControllerActionInvoker.<InvokeAsync>d__20.MoveNext()
--- End of stack trace from previous location where exception was thrown ---
   at System.Runtime.ExceptionServices.ExceptionDispatchInfo.Throw()
   at System.Runtime.CompilerServices.TaskAwaiter.HandleNonSuccessAndDebuggerNotification(Task task)
   at Microsoft.AspNetCore.Builder.RouterMiddleware.<Invoke>d__4.MoveNext()
--- End of stack trace from previous location where exception was thrown ---
   at System.Runtime.ExceptionServices.ExceptionDispatchInfo.Throw()
   at System.Runtime.CompilerServices.TaskAwaiter.HandleNonSuccessAndDebuggerNotification(Task task)
   at Microsoft.AspNetCore.Authentication.AuthenticationMiddleware`1.<Invoke>d__18.MoveNext()
--- End of stack trace from previous location where exception was thrown ---
   at System.Runtime.ExceptionServices.ExceptionDispatchInfo.Throw()
   at Microsoft.AspNetCore.Authentication.AuthenticationMiddleware`1.<Invoke>d__18.MoveNext()
--- End of stack trace from previous location where exception was thrown ---
   at System.Runtime.ExceptionServices.ExceptionDispatchInfo.Throw()
   at System.Runtime.CompilerServices.TaskAwaiter.HandleNonSuccessAndDebuggerNotification(Task task)
   at FundTrack.WebUI.Middlewares.GlobalErrorHandlingMiddleware.<Invoke>d__4.MoveNext() in C:\FundTrack\FundTrack.WebUI\Middlewares\GlobalErrorHandlingMiddleware.cs:line 33
____________________________________________________________________________________________________________________________________________

Date and time:  16.11.2017 12:21:40
Error message:  The view 'Index' was not found. The following locations were searched:
/Views/Home/Index.cshtml
/Views/Shared/Index.cshtml
Source:  Microsoft.AspNetCore.Mvc.ViewFeatures
InnerException:  
StackTrace:     at Microsoft.AspNetCore.Mvc.ViewEngines.ViewEngineResult.EnsureSuccessful(IEnumerable`1 originalLocations)
   at Microsoft.AspNetCore.Mvc.ViewResult.<ExecuteResultAsync>d__26.MoveNext()
--- End of stack trace from previous location where exception was thrown ---
   at System.Runtime.ExceptionServices.ExceptionDispatchInfo.Throw()
   at System.Runtime.CompilerServices.TaskAwaiter.HandleNonSuccessAndDebuggerNotification(Task task)
   at Microsoft.AspNetCore.Mvc.Internal.ControllerActionInvoker.<InvokeResultAsync>d__30.MoveNext()
--- End of stack trace from previous location where exception was thrown ---
   at System.Runtime.ExceptionServices.ExceptionDispatchInfo.Throw()
   at System.Runtime.CompilerServices.TaskAwaiter.HandleNonSuccessAndDebuggerNotification(Task task)
   at Microsoft.AspNetCore.Mvc.Internal.ControllerActionInvoker.<InvokeNextResultFilterAsync>d__28.MoveNext()
--- End of stack trace from previous location where exception was thrown ---
   at System.Runtime.ExceptionServices.ExceptionDispatchInfo.Throw()
   at Microsoft.AspNetCore.Mvc.Internal.ControllerActionInvoker.Rethrow(ResultExecutedContext context)
   at Microsoft.AspNetCore.Mvc.Internal.ControllerActionInvoker.Next(State& next, Scope& scope, Object& state, Boolean& isCompleted)
   at Microsoft.AspNetCore.Mvc.Internal.ControllerActionInvoker.<InvokeNextResourceFilter>d__22.MoveNext()
--- End of stack trace from previous location where exception was thrown ---
   at System.Runtime.ExceptionServices.ExceptionDispatchInfo.Throw()
   at Microsoft.AspNetCore.Mvc.Internal.ControllerActionInvoker.Rethrow(ResourceExecutedContext context)
   at Microsoft.AspNetCore.Mvc.Internal.ControllerActionInvoker.Next(State& next, Scope& scope, Object& state, Boolean& isCompleted)
   at Microsoft.AspNetCore.Mvc.Internal.ControllerActionInvoker.<InvokeAsync>d__20.MoveNext()
--- End of stack trace from previous location where exception was thrown ---
   at System.Runtime.ExceptionServices.ExceptionDispatchInfo.Throw()
   at System.Runtime.CompilerServices.TaskAwaiter.HandleNonSuccessAndDebuggerNotification(Task task)
   at Microsoft.AspNetCore.Builder.RouterMiddleware.<Invoke>d__4.MoveNext()
--- End of stack trace from previous location where exception was thrown ---
   at System.Runtime.ExceptionServices.ExceptionDispatchInfo.Throw()
   at System.Runtime.CompilerServices.TaskAwaiter.HandleNonSuccessAndDebuggerNotification(Task task)
   at Microsoft.AspNetCore.Authentication.AuthenticationMiddleware`1.<Invoke>d__18.MoveNext()
--- End of stack trace from previous location where exception was thrown ---
   at System.Runtime.ExceptionServices.ExceptionDispatchInfo.Throw()
   at Microsoft.AspNetCore.Authentication.AuthenticationMiddleware`1.<Invoke>d__18.MoveNext()
--- End of stack trace from previous location where exception was thrown ---
   at System.Runtime.ExceptionServices.ExceptionDispatchInfo.Throw()
   at System.Runtime.CompilerServices.TaskAwaiter.HandleNonSuccessAndDebuggerNotification(Task task)
   at FundTrack.WebUI.Middlewares.GlobalErrorHandlingMiddleware.<Invoke>d__4.MoveNext() in C:\FundTrack\FundTrack.WebUI\Middlewares\GlobalErrorHandlingMiddleware.cs:line 33
____________________________________________________________________________________________________________________________________________

Date and time:  16.11.2017 14:20:44
Error message:  Неможливо виконати фінансову операцію "Розхід"
Source:  FundTrack.BLL
InnerException:  System.NullReferenceException: Object reference not set to an instance of an object.
   at FundTrack.BLL.Concrete.FinOpService.CreateSpending(FinOpViewModel finOpModel) in C:\FundTrack\FundTrack.BLL\Concrete\FinOpService.cs:line 162
StackTrace:     at FundTrack.BLL.Concrete.FinOpService.CreateSpending(FinOpViewModel finOpModel) in C:\FundTrack\FundTrack.BLL\Concrete\FinOpService.cs:line 185
   at FundTrack.WebUI.Controllers.FinOpController.Spending(FinOpViewModel spendingModel) in C:\FundTrack\FundTrack.WebUI\Controllers\FinOpController.cs:line 146
   at lambda_method(Closure , Object , Object[] )
   at Microsoft.AspNetCore.Mvc.Internal.ControllerActionInvoker.<InvokeActionMethodAsync>d__27.MoveNext()
--- End of stack trace from previous location where exception was thrown ---
   at System.Runtime.ExceptionServices.ExceptionDispatchInfo.Throw()
   at System.Runtime.CompilerServices.TaskAwaiter.HandleNonSuccessAndDebuggerNotification(Task task)
   at Microsoft.AspNetCore.Mvc.Internal.ControllerActionInvoker.<InvokeNextActionFilterAsync>d__25.MoveNext()
--- End of stack trace from previous location where exception was thrown ---
   at System.Runtime.ExceptionServices.ExceptionDispatchInfo.Throw()
   at Microsoft.AspNetCore.Mvc.Internal.ControllerActionInvoker.Rethrow(ActionExecutedContext context)
   at Microsoft.AspNetCore.Mvc.Internal.ControllerActionInvoker.Next(State& next, Scope& scope, Object& state, Boolean& isCompleted)
   at Microsoft.AspNetCore.Mvc.Internal.ControllerActionInvoker.<InvokeNextResourceFilter>d__22.MoveNext()
--- End of stack trace from previous location where exception was thrown ---
   at System.Runtime.ExceptionServices.ExceptionDispatchInfo.Throw()
   at Microsoft.AspNetCore.Mvc.Internal.ControllerActionInvoker.Rethrow(ResourceExecutedContext context)
   at Microsoft.AspNetCore.Mvc.Internal.ControllerActionInvoker.Next(State& next, Scope& scope, Object& state, Boolean& isCompleted)
   at Microsoft.AspNetCore.Mvc.Internal.ControllerActionInvoker.<InvokeAsync>d__20.MoveNext()
--- End of stack trace from previous location where exception was thrown ---
   at System.Runtime.ExceptionServices.ExceptionDispatchInfo.Throw()
   at System.Runtime.CompilerServices.TaskAwaiter.HandleNonSuccessAndDebuggerNotification(Task task)
   at Microsoft.AspNetCore.Builder.RouterMiddleware.<Invoke>d__4.MoveNext()
--- End of stack trace from previous location where exception was thrown ---
   at System.Runtime.ExceptionServices.ExceptionDispatchInfo.Throw()
   at System.Runtime.CompilerServices.TaskAwaiter.HandleNonSuccessAndDebuggerNotification(Task task)
   at Microsoft.AspNetCore.Authentication.AuthenticationMiddleware`1.<Invoke>d__18.MoveNext()
--- End of stack trace from previous location where exception was thrown ---
   at System.Runtime.ExceptionServices.ExceptionDispatchInfo.Throw()
   at Microsoft.AspNetCore.Authentication.AuthenticationMiddleware`1.<Invoke>d__18.MoveNext()
--- End of stack trace from previous location where exception was thrown ---
   at System.Runtime.ExceptionServices.ExceptionDispatchInfo.Throw()
   at System.Runtime.CompilerServices.TaskAwaiter.HandleNonSuccessAndDebuggerNotification(Task task)
   at FundTrack.WebUI.Middlewares.GlobalErrorHandlingMiddleware.<Invoke>d__4.MoveNext() in C:\FundTrack\FundTrack.WebUI\Middlewares\GlobalErrorHandlingMiddleware.cs:line 33
____________________________________________________________________________________________________________________________________________

Date and time:  16.11.2017 14:23:17
Error message:  Неможливо виконати фінансову операцію "Розхід"
Source:  FundTrack.BLL
InnerException:  System.NullReferenceException: Object reference not set to an instance of an object.
   at FundTrack.BLL.Concrete.FinOpService.CreateSpending(FinOpViewModel finOpModel) in C:\FundTrack\FundTrack.BLL\Concrete\FinOpService.cs:line 162
StackTrace:     at FundTrack.BLL.Concrete.FinOpService.CreateSpending(FinOpViewModel finOpModel) in C:\FundTrack\FundTrack.BLL\Concrete\FinOpService.cs:line 185
   at FundTrack.WebUI.Controllers.FinOpController.Spending(FinOpViewModel spendingModel) in C:\FundTrack\FundTrack.WebUI\Controllers\FinOpController.cs:line 146
   at lambda_method(Closure , Object , Object[] )
   at Microsoft.AspNetCore.Mvc.Internal.ControllerActionInvoker.<InvokeActionMethodAsync>d__27.MoveNext()
--- End of stack trace from previous location where exception was thrown ---
   at System.Runtime.ExceptionServices.ExceptionDispatchInfo.Throw()
   at System.Runtime.CompilerServices.TaskAwaiter.HandleNonSuccessAndDebuggerNotification(Task task)
   at Microsoft.AspNetCore.Mvc.Internal.ControllerActionInvoker.<InvokeNextActionFilterAsync>d__25.MoveNext()
--- End of stack trace from previous location where exception was thrown ---
   at System.Runtime.ExceptionServices.ExceptionDispatchInfo.Throw()
   at Microsoft.AspNetCore.Mvc.Internal.ControllerActionInvoker.Rethrow(ActionExecutedContext context)
   at Microsoft.AspNetCore.Mvc.Internal.ControllerActionInvoker.Next(State& next, Scope& scope, Object& state, Boolean& isCompleted)
   at Microsoft.AspNetCore.Mvc.Internal.ControllerActionInvoker.<InvokeNextResourceFilter>d__22.MoveNext()
--- End of stack trace from previous location where exception was thrown ---
   at System.Runtime.ExceptionServices.ExceptionDispatchInfo.Throw()
   at Microsoft.AspNetCore.Mvc.Internal.ControllerActionInvoker.Rethrow(ResourceExecutedContext context)
   at Microsoft.AspNetCore.Mvc.Internal.ControllerActionInvoker.Next(State& next, Scope& scope, Object& state, Boolean& isCompleted)
   at Microsoft.AspNetCore.Mvc.Internal.ControllerActionInvoker.<InvokeAsync>d__20.MoveNext()
--- End of stack trace from previous location where exception was thrown ---
   at System.Runtime.ExceptionServices.ExceptionDispatchInfo.Throw()
   at System.Runtime.CompilerServices.TaskAwaiter.HandleNonSuccessAndDebuggerNotification(Task task)
   at Microsoft.AspNetCore.Builder.RouterMiddleware.<Invoke>d__4.MoveNext()
--- End of stack trace from previous location where exception was thrown ---
   at System.Runtime.ExceptionServices.ExceptionDispatchInfo.Throw()
   at System.Runtime.CompilerServices.TaskAwaiter.HandleNonSuccessAndDebuggerNotification(Task task)
   at Microsoft.AspNetCore.Authentication.AuthenticationMiddleware`1.<Invoke>d__18.MoveNext()
--- End of stack trace from previous location where exception was thrown ---
   at System.Runtime.ExceptionServices.ExceptionDispatchInfo.Throw()
   at Microsoft.AspNetCore.Authentication.AuthenticationMiddleware`1.<Invoke>d__18.MoveNext()
--- End of stack trace from previous location where exception was thrown ---
   at System.Runtime.ExceptionServices.ExceptionDispatchInfo.Throw()
   at System.Runtime.CompilerServices.TaskAwaiter.HandleNonSuccessAndDebuggerNotification(Task task)
   at FundTrack.WebUI.Middlewares.GlobalErrorHandlingMiddleware.<Invoke>d__4.MoveNext() in C:\FundTrack\FundTrack.WebUI\Middlewares\GlobalErrorHandlingMiddleware.cs:line 33
____________________________________________________________________________________________________________________________________________

Date and time:  16.11.2017 14:29:31
Error message:  Неможливо виконати фінансову операцію "Розхід"
Source:  FundTrack.BLL
InnerException:  System.NullReferenceException: Object reference not set to an instance of an object.
   at FundTrack.BLL.Concrete.FinOpService.CreateSpending(FinOpViewModel finOpModel) in C:\FundTrack\FundTrack.BLL\Concrete\FinOpService.cs:line 162
StackTrace:     at FundTrack.BLL.Concrete.FinOpService.CreateSpending(FinOpViewModel finOpModel) in C:\FundTrack\FundTrack.BLL\Concrete\FinOpService.cs:line 185
   at FundTrack.WebUI.Controllers.FinOpController.Spending(FinOpViewModel spendingModel) in C:\FundTrack\FundTrack.WebUI\Controllers\FinOpController.cs:line 146
   at lambda_method(Closure , Object , Object[] )
   at Microsoft.AspNetCore.Mvc.Internal.ControllerActionInvoker.<InvokeActionMethodAsync>d__27.MoveNext()
--- End of stack trace from previous location where exception was thrown ---
   at System.Runtime.ExceptionServices.ExceptionDispatchInfo.Throw()
   at System.Runtime.CompilerServices.TaskAwaiter.HandleNonSuccessAndDebuggerNotification(Task task)
   at Microsoft.AspNetCore.Mvc.Internal.ControllerActionInvoker.<InvokeNextActionFilterAsync>d__25.MoveNext()
--- End of stack trace from previous location where exception was thrown ---
   at System.Runtime.ExceptionServices.ExceptionDispatchInfo.Throw()
   at Microsoft.AspNetCore.Mvc.Internal.ControllerActionInvoker.Rethrow(ActionExecutedContext context)
   at Microsoft.AspNetCore.Mvc.Internal.ControllerActionInvoker.Next(State& next, Scope& scope, Object& state, Boolean& isCompleted)
   at Microsoft.AspNetCore.Mvc.Internal.ControllerActionInvoker.<InvokeNextResourceFilter>d__22.MoveNext()
--- End of stack trace from previous location where exception was thrown ---
   at System.Runtime.ExceptionServices.ExceptionDispatchInfo.Throw()
   at Microsoft.AspNetCore.Mvc.Internal.ControllerActionInvoker.Rethrow(ResourceExecutedContext context)
   at Microsoft.AspNetCore.Mvc.Internal.ControllerActionInvoker.Next(State& next, Scope& scope, Object& state, Boolean& isCompleted)
   at Microsoft.AspNetCore.Mvc.Internal.ControllerActionInvoker.<InvokeAsync>d__20.MoveNext()
--- End of stack trace from previous location where exception was thrown ---
   at System.Runtime.ExceptionServices.ExceptionDispatchInfo.Throw()
   at System.Runtime.CompilerServices.TaskAwaiter.HandleNonSuccessAndDebuggerNotification(Task task)
   at Microsoft.AspNetCore.Builder.RouterMiddleware.<Invoke>d__4.MoveNext()
--- End of stack trace from previous location where exception was thrown ---
   at System.Runtime.ExceptionServices.ExceptionDispatchInfo.Throw()
   at System.Runtime.CompilerServices.TaskAwaiter.HandleNonSuccessAndDebuggerNotification(Task task)
   at Microsoft.AspNetCore.Authentication.AuthenticationMiddleware`1.<Invoke>d__18.MoveNext()
--- End of stack trace from previous location where exception was thrown ---
   at System.Runtime.ExceptionServices.ExceptionDispatchInfo.Throw()
   at Microsoft.AspNetCore.Authentication.AuthenticationMiddleware`1.<Invoke>d__18.MoveNext()
--- End of stack trace from previous location where exception was thrown ---
   at System.Runtime.ExceptionServices.ExceptionDispatchInfo.Throw()
   at System.Runtime.CompilerServices.TaskAwaiter.HandleNonSuccessAndDebuggerNotification(Task task)
   at FundTrack.WebUI.Middlewares.GlobalErrorHandlingMiddleware.<Invoke>d__4.MoveNext() in C:\FundTrack\FundTrack.WebUI\Middlewares\GlobalErrorHandlingMiddleware.cs:line 33
____________________________________________________________________________________________________________________________________________

Date and time:  16.11.2017 14:31:09
Error message:  Неможливо виконати фінансову операцію "Розхід"
Source:  FundTrack.BLL
InnerException:  System.NullReferenceException: Object reference not set to an instance of an object.
   at FundTrack.BLL.Concrete.FinOpService.CreateSpending(FinOpViewModel finOpModel) in C:\FundTrack\FundTrack.BLL\Concrete\FinOpService.cs:line 162
StackTrace:     at FundTrack.BLL.Concrete.FinOpService.CreateSpending(FinOpViewModel finOpModel) in C:\FundTrack\FundTrack.BLL\Concrete\FinOpService.cs:line 185
   at FundTrack.WebUI.Controllers.FinOpController.Spending(FinOpViewModel spendingModel) in C:\FundTrack\FundTrack.WebUI\Controllers\FinOpController.cs:line 146
   at lambda_method(Closure , Object , Object[] )
   at Microsoft.AspNetCore.Mvc.Internal.ControllerActionInvoker.<InvokeActionMethodAsync>d__27.MoveNext()
--- End of stack trace from previous location where exception was thrown ---
   at System.Runtime.ExceptionServices.ExceptionDispatchInfo.Throw()
   at System.Runtime.CompilerServices.TaskAwaiter.HandleNonSuccessAndDebuggerNotification(Task task)
   at Microsoft.AspNetCore.Mvc.Internal.ControllerActionInvoker.<InvokeNextActionFilterAsync>d__25.MoveNext()
--- End of stack trace from previous location where exception was thrown ---
   at System.Runtime.ExceptionServices.ExceptionDispatchInfo.Throw()
   at Microsoft.AspNetCore.Mvc.Internal.ControllerActionInvoker.Rethrow(ActionExecutedContext context)
   at Microsoft.AspNetCore.Mvc.Internal.ControllerActionInvoker.Next(State& next, Scope& scope, Object& state, Boolean& isCompleted)
   at Microsoft.AspNetCore.Mvc.Internal.ControllerActionInvoker.<InvokeNextResourceFilter>d__22.MoveNext()
--- End of stack trace from previous location where exception was thrown ---
   at System.Runtime.ExceptionServices.ExceptionDispatchInfo.Throw()
   at Microsoft.AspNetCore.Mvc.Internal.ControllerActionInvoker.Rethrow(ResourceExecutedContext context)
   at Microsoft.AspNetCore.Mvc.Internal.ControllerActionInvoker.Next(State& next, Scope& scope, Object& state, Boolean& isCompleted)
   at Microsoft.AspNetCore.Mvc.Internal.ControllerActionInvoker.<InvokeAsync>d__20.MoveNext()
--- End of stack trace from previous location where exception was thrown ---
   at System.Runtime.ExceptionServices.ExceptionDispatchInfo.Throw()
   at System.Runtime.CompilerServices.TaskAwaiter.HandleNonSuccessAndDebuggerNotification(Task task)
   at Microsoft.AspNetCore.Builder.RouterMiddleware.<Invoke>d__4.MoveNext()
--- End of stack trace from previous location where exception was thrown ---
   at System.Runtime.ExceptionServices.ExceptionDispatchInfo.Throw()
   at System.Runtime.CompilerServices.TaskAwaiter.HandleNonSuccessAndDebuggerNotification(Task task)
   at Microsoft.AspNetCore.Authentication.AuthenticationMiddleware`1.<Invoke>d__18.MoveNext()
--- End of stack trace from previous location where exception was thrown ---
   at System.Runtime.ExceptionServices.ExceptionDispatchInfo.Throw()
   at Microsoft.AspNetCore.Authentication.AuthenticationMiddleware`1.<Invoke>d__18.MoveNext()
--- End of stack trace from previous location where exception was thrown ---
   at System.Runtime.ExceptionServices.ExceptionDispatchInfo.Throw()
   at System.Runtime.CompilerServices.TaskAwaiter.HandleNonSuccessAndDebuggerNotification(Task task)
   at FundTrack.WebUI.Middlewares.GlobalErrorHandlingMiddleware.<Invoke>d__4.MoveNext() in C:\FundTrack\FundTrack.WebUI\Middlewares\GlobalErrorHandlingMiddleware.cs:line 33
____________________________________________________________________________________________________________________________________________

Date and time:  16.11.2017 14:33:08
Error message:  Неможливо виконати фінансову операцію "Розхід"
Source:  FundTrack.BLL
InnerException:  System.FormatException: Invalid length for a Base-64 char array or string.
   at System.Convert.FromBase64_Decode(Char* startInputPtr, Int32 inputLength, Byte* startDestPtr, Int32 destLength)
   at System.Convert.FromBase64CharPtr(Char* inputPtr, Int32 inputLength)
   at System.Convert.FromBase64String(String s)
   at FundTrack.BLL.Concrete.FinOpService.UploadImagesToStorage(IEnumerable`1 images) in C:\FundTrack\FundTrack.BLL\Concrete\FinOpService.cs:line 197
   at FundTrack.BLL.Concrete.FinOpService.CreateSpending(FinOpViewModel finOpModel) in C:\FundTrack\FundTrack.BLL\Concrete\FinOpService.cs:line 176
StackTrace:     at FundTrack.BLL.Concrete.FinOpService.CreateSpending(FinOpViewModel finOpModel) in C:\FundTrack\FundTrack.BLL\Concrete\FinOpService.cs:line 185
   at FundTrack.WebUI.Controllers.FinOpController.Spending(FinOpViewModel spendingModel) in C:\FundTrack\FundTrack.WebUI\Controllers\FinOpController.cs:line 146
   at lambda_method(Closure , Object , Object[] )
   at Microsoft.AspNetCore.Mvc.Internal.ControllerActionInvoker.<InvokeActionMethodAsync>d__27.MoveNext()
--- End of stack trace from previous location where exception was thrown ---
   at System.Runtime.ExceptionServices.ExceptionDispatchInfo.Throw()
   at System.Runtime.CompilerServices.TaskAwaiter.HandleNonSuccessAndDebuggerNotification(Task task)
   at Microsoft.AspNetCore.Mvc.Internal.ControllerActionInvoker.<InvokeNextActionFilterAsync>d__25.MoveNext()
--- End of stack trace from previous location where exception was thrown ---
   at System.Runtime.ExceptionServices.ExceptionDispatchInfo.Throw()
   at Microsoft.AspNetCore.Mvc.Internal.ControllerActionInvoker.Rethrow(ActionExecutedContext context)
   at Microsoft.AspNetCore.Mvc.Internal.ControllerActionInvoker.Next(State& next, Scope& scope, Object& state, Boolean& isCompleted)
   at Microsoft.AspNetCore.Mvc.Internal.ControllerActionInvoker.<InvokeNextResourceFilter>d__22.MoveNext()
--- End of stack trace from previous location where exception was thrown ---
   at System.Runtime.ExceptionServices.ExceptionDispatchInfo.Throw()
   at Microsoft.AspNetCore.Mvc.Internal.ControllerActionInvoker.Rethrow(ResourceExecutedContext context)
   at Microsoft.AspNetCore.Mvc.Internal.ControllerActionInvoker.Next(State& next, Scope& scope, Object& state, Boolean& isCompleted)
   at Microsoft.AspNetCore.Mvc.Internal.ControllerActionInvoker.<InvokeAsync>d__20.MoveNext()
--- End of stack trace from previous location where exception was thrown ---
   at System.Runtime.ExceptionServices.ExceptionDispatchInfo.Throw()
   at System.Runtime.CompilerServices.TaskAwaiter.HandleNonSuccessAndDebuggerNotification(Task task)
   at Microsoft.AspNetCore.Builder.RouterMiddleware.<Invoke>d__4.MoveNext()
--- End of stack trace from previous location where exception was thrown ---
   at System.Runtime.ExceptionServices.ExceptionDispatchInfo.Throw()
   at System.Runtime.CompilerServices.TaskAwaiter.HandleNonSuccessAndDebuggerNotification(Task task)
   at Microsoft.AspNetCore.Authentication.AuthenticationMiddleware`1.<Invoke>d__18.MoveNext()
--- End of stack trace from previous location where exception was thrown ---
   at System.Runtime.ExceptionServices.ExceptionDispatchInfo.Throw()
   at Microsoft.AspNetCore.Authentication.AuthenticationMiddleware`1.<Invoke>d__18.MoveNext()
--- End of stack trace from previous location where exception was thrown ---
   at System.Runtime.ExceptionServices.ExceptionDispatchInfo.Throw()
   at System.Runtime.CompilerServices.TaskAwaiter.HandleNonSuccessAndDebuggerNotification(Task task)
   at FundTrack.WebUI.Middlewares.GlobalErrorHandlingMiddleware.<Invoke>d__4.MoveNext() in C:\FundTrack\FundTrack.WebUI\Middlewares\GlobalErrorHandlingMiddleware.cs:line 33
____________________________________________________________________________________________________________________________________________

Date and time:  16.11.2017 15:06:21
Error message:  Список фінансових операцій порожній
Source:  FundTrack.BLL
InnerException:  System.NullReferenceException: Object reference not set to an instance of an object.
   at FundTrack.BLL.Concrete.FinOpService.GetFinOpsById(Int32 id) in C:\FundTrack\FundTrack.BLL\Concrete\FinOpService.cs:line 390
StackTrace:     at FundTrack.BLL.Concrete.FinOpService.GetFinOpsById(Int32 id) in C:\FundTrack\FundTrack.BLL\Concrete\FinOpService.cs:line 408
   at FundTrack.WebUI.Controllers.FinOpController.GetFinOpsById(Int32 id) in C:\FundTrack\FundTrack.WebUI\Controllers\FinOpController.cs:line 94
   at lambda_method(Closure , Object , Object[] )
   at Microsoft.AspNetCore.Mvc.Internal.ControllerActionInvoker.<InvokeActionMethodAsync>d__27.MoveNext()
--- End of stack trace from previous location where exception was thrown ---
   at System.Runtime.ExceptionServices.ExceptionDispatchInfo.Throw()
   at System.Runtime.CompilerServices.TaskAwaiter.HandleNonSuccessAndDebuggerNotification(Task task)
   at Microsoft.AspNetCore.Mvc.Internal.ControllerActionInvoker.<InvokeNextActionFilterAsync>d__25.MoveNext()
--- End of stack trace from previous location where exception was thrown ---
   at System.Runtime.ExceptionServices.ExceptionDispatchInfo.Throw()
   at Microsoft.AspNetCore.Mvc.Internal.ControllerActionInvoker.Rethrow(ActionExecutedContext context)
   at Microsoft.AspNetCore.Mvc.Internal.ControllerActionInvoker.Next(State& next, Scope& scope, Object& state, Boolean& isCompleted)
   at Microsoft.AspNetCore.Mvc.Internal.ControllerActionInvoker.<InvokeNextResourceFilter>d__22.MoveNext()
--- End of stack trace from previous location where exception was thrown ---
   at System.Runtime.ExceptionServices.ExceptionDispatchInfo.Throw()
   at Microsoft.AspNetCore.Mvc.Internal.ControllerActionInvoker.Rethrow(ResourceExecutedContext context)
   at Microsoft.AspNetCore.Mvc.Internal.ControllerActionInvoker.Next(State& next, Scope& scope, Object& state, Boolean& isCompleted)
   at Microsoft.AspNetCore.Mvc.Internal.ControllerActionInvoker.<InvokeAsync>d__20.MoveNext()
--- End of stack trace from previous location where exception was thrown ---
   at System.Runtime.ExceptionServices.ExceptionDispatchInfo.Throw()
   at System.Runtime.CompilerServices.TaskAwaiter.HandleNonSuccessAndDebuggerNotification(Task task)
   at Microsoft.AspNetCore.Builder.RouterMiddleware.<Invoke>d__4.MoveNext()
--- End of stack trace from previous location where exception was thrown ---
   at System.Runtime.ExceptionServices.ExceptionDispatchInfo.Throw()
   at System.Runtime.CompilerServices.TaskAwaiter.HandleNonSuccessAndDebuggerNotification(Task task)
   at Microsoft.AspNetCore.Authentication.AuthenticationMiddleware`1.<Invoke>d__18.MoveNext()
--- End of stack trace from previous location where exception was thrown ---
   at System.Runtime.ExceptionServices.ExceptionDispatchInfo.Throw()
   at Microsoft.AspNetCore.Authentication.AuthenticationMiddleware`1.<Invoke>d__18.MoveNext()
--- End of stack trace from previous location where exception was thrown ---
   at System.Runtime.ExceptionServices.ExceptionDispatchInfo.Throw()
   at System.Runtime.CompilerServices.TaskAwaiter.HandleNonSuccessAndDebuggerNotification(Task task)
   at FundTrack.WebUI.Middlewares.GlobalErrorHandlingMiddleware.<Invoke>d__4.MoveNext() in C:\FundTrack\FundTrack.WebUI\Middlewares\GlobalErrorHandlingMiddleware.cs:line 33
____________________________________________________________________________________________________________________________________________

Date and time:  16.11.2017 15:07:16
Error message:  Список фінансових операцій порожній
Source:  FundTrack.BLL
InnerException:  System.NullReferenceException: Object reference not set to an instance of an object.
   at FundTrack.BLL.Concrete.FinOpService.GetFinOpsById(Int32 id) in C:\FundTrack\FundTrack.BLL\Concrete\FinOpService.cs:line 390
StackTrace:     at FundTrack.BLL.Concrete.FinOpService.GetFinOpsById(Int32 id) in C:\FundTrack\FundTrack.BLL\Concrete\FinOpService.cs:line 408
   at FundTrack.WebUI.Controllers.FinOpController.GetFinOpsById(Int32 id) in C:\FundTrack\FundTrack.WebUI\Controllers\FinOpController.cs:line 94
   at lambda_method(Closure , Object , Object[] )
   at Microsoft.AspNetCore.Mvc.Internal.ControllerActionInvoker.<InvokeActionMethodAsync>d__27.MoveNext()
--- End of stack trace from previous location where exception was thrown ---
   at System.Runtime.ExceptionServices.ExceptionDispatchInfo.Throw()
   at System.Runtime.CompilerServices.TaskAwaiter.HandleNonSuccessAndDebuggerNotification(Task task)
   at Microsoft.AspNetCore.Mvc.Internal.ControllerActionInvoker.<InvokeNextActionFilterAsync>d__25.MoveNext()
--- End of stack trace from previous location where exception was thrown ---
   at System.Runtime.ExceptionServices.ExceptionDispatchInfo.Throw()
   at Microsoft.AspNetCore.Mvc.Internal.ControllerActionInvoker.Rethrow(ActionExecutedContext context)
   at Microsoft.AspNetCore.Mvc.Internal.ControllerActionInvoker.Next(State& next, Scope& scope, Object& state, Boolean& isCompleted)
   at Microsoft.AspNetCore.Mvc.Internal.ControllerActionInvoker.<InvokeNextResourceFilter>d__22.MoveNext()
--- End of stack trace from previous location where exception was thrown ---
   at System.Runtime.ExceptionServices.ExceptionDispatchInfo.Throw()
   at Microsoft.AspNetCore.Mvc.Internal.ControllerActionInvoker.Rethrow(ResourceExecutedContext context)
   at Microsoft.AspNetCore.Mvc.Internal.ControllerActionInvoker.Next(State& next, Scope& scope, Object& state, Boolean& isCompleted)
   at Microsoft.AspNetCore.Mvc.Internal.ControllerActionInvoker.<InvokeAsync>d__20.MoveNext()
--- End of stack trace from previous location where exception was thrown ---
   at System.Runtime.ExceptionServices.ExceptionDispatchInfo.Throw()
   at System.Runtime.CompilerServices.TaskAwaiter.HandleNonSuccessAndDebuggerNotification(Task task)
   at Microsoft.AspNetCore.Builder.RouterMiddleware.<Invoke>d__4.MoveNext()
--- End of stack trace from previous location where exception was thrown ---
   at System.Runtime.ExceptionServices.ExceptionDispatchInfo.Throw()
   at System.Runtime.CompilerServices.TaskAwaiter.HandleNonSuccessAndDebuggerNotification(Task task)
   at Microsoft.AspNetCore.Authentication.AuthenticationMiddleware`1.<Invoke>d__18.MoveNext()
--- End of stack trace from previous location where exception was thrown ---
   at System.Runtime.ExceptionServices.ExceptionDispatchInfo.Throw()
   at Microsoft.AspNetCore.Authentication.AuthenticationMiddleware`1.<Invoke>d__18.MoveNext()
--- End of stack trace from previous location where exception was thrown ---
   at System.Runtime.ExceptionServices.ExceptionDispatchInfo.Throw()
   at System.Runtime.CompilerServices.TaskAwaiter.HandleNonSuccessAndDebuggerNotification(Task task)
   at FundTrack.WebUI.Middlewares.GlobalErrorHandlingMiddleware.<Invoke>d__4.MoveNext() in C:\FundTrack\FundTrack.WebUI\Middlewares\GlobalErrorHandlingMiddleware.cs:line 33
____________________________________________________________________________________________________________________________________________

Date and time:  16.11.2017 15:17:11
Error message:  Список фінансових операцій порожній
Source:  FundTrack.BLL
InnerException:  System.NullReferenceException: Object reference not set to an instance of an object.
   at FundTrack.BLL.Concrete.FinOpService.GetFinOpsById(Int32 id) in C:\FundTrack\FundTrack.BLL\Concrete\FinOpService.cs:line 390
StackTrace:     at FundTrack.BLL.Concrete.FinOpService.GetFinOpsById(Int32 id) in C:\FundTrack\FundTrack.BLL\Concrete\FinOpService.cs:line 408
   at FundTrack.WebUI.Controllers.FinOpController.GetFinOpsById(Int32 id) in C:\FundTrack\FundTrack.WebUI\Controllers\FinOpController.cs:line 94
   at lambda_method(Closure , Object , Object[] )
   at Microsoft.AspNetCore.Mvc.Internal.ControllerActionInvoker.<InvokeActionMethodAsync>d__27.MoveNext()
--- End of stack trace from previous location where exception was thrown ---
   at System.Runtime.ExceptionServices.ExceptionDispatchInfo.Throw()
   at System.Runtime.CompilerServices.TaskAwaiter.HandleNonSuccessAndDebuggerNotification(Task task)
   at Microsoft.AspNetCore.Mvc.Internal.ControllerActionInvoker.<InvokeNextActionFilterAsync>d__25.MoveNext()
--- End of stack trace from previous location where exception was thrown ---
   at System.Runtime.ExceptionServices.ExceptionDispatchInfo.Throw()
   at Microsoft.AspNetCore.Mvc.Internal.ControllerActionInvoker.Rethrow(ActionExecutedContext context)
   at Microsoft.AspNetCore.Mvc.Internal.ControllerActionInvoker.Next(State& next, Scope& scope, Object& state, Boolean& isCompleted)
   at Microsoft.AspNetCore.Mvc.Internal.ControllerActionInvoker.<InvokeNextResourceFilter>d__22.MoveNext()
--- End of stack trace from previous location where exception was thrown ---
   at System.Runtime.ExceptionServices.ExceptionDispatchInfo.Throw()
   at Microsoft.AspNetCore.Mvc.Internal.ControllerActionInvoker.Rethrow(ResourceExecutedContext context)
   at Microsoft.AspNetCore.Mvc.Internal.ControllerActionInvoker.Next(State& next, Scope& scope, Object& state, Boolean& isCompleted)
   at Microsoft.AspNetCore.Mvc.Internal.ControllerActionInvoker.<InvokeAsync>d__20.MoveNext()
--- End of stack trace from previous location where exception was thrown ---
   at System.Runtime.ExceptionServices.ExceptionDispatchInfo.Throw()
   at System.Runtime.CompilerServices.TaskAwaiter.HandleNonSuccessAndDebuggerNotification(Task task)
   at Microsoft.AspNetCore.Builder.RouterMiddleware.<Invoke>d__4.MoveNext()
--- End of stack trace from previous location where exception was thrown ---
   at System.Runtime.ExceptionServices.ExceptionDispatchInfo.Throw()
   at System.Runtime.CompilerServices.TaskAwaiter.HandleNonSuccessAndDebuggerNotification(Task task)
   at Microsoft.AspNetCore.Authentication.AuthenticationMiddleware`1.<Invoke>d__18.MoveNext()
--- End of stack trace from previous location where exception was thrown ---
   at System.Runtime.ExceptionServices.ExceptionDispatchInfo.Throw()
   at Microsoft.AspNetCore.Authentication.AuthenticationMiddleware`1.<Invoke>d__18.MoveNext()
--- End of stack trace from previous location where exception was thrown ---
   at System.Runtime.ExceptionServices.ExceptionDispatchInfo.Throw()
   at System.Runtime.CompilerServices.TaskAwaiter.HandleNonSuccessAndDebuggerNotification(Task task)
   at FundTrack.WebUI.Middlewares.GlobalErrorHandlingMiddleware.<Invoke>d__4.MoveNext() in C:\FundTrack\FundTrack.WebUI\Middlewares\GlobalErrorHandlingMiddleware.cs:line 33
____________________________________________________________________________________________________________________________________________

