Date and time:  30.10.2017 3:03:54
Error message:  An exception has been raised that is likely due to a transient failure. If you are connecting to a SQL Azure database consider using SqlAzureExecutionStrategy.
Source:  Microsoft.EntityFrameworkCore.SqlServer
InnerException:  System.Data.SqlClient.SqlException: A connection was successfully established with the server, but then an error occurred during the login process. (provider: SSL Provider, error: 0 - An existing connection was forcibly closed by the remote host.) ---> System.ComponentModel.Win32Exception: An existing connection was forcibly closed by the remote host
   --- End of inner exception stack trace ---
   at System.Data.SqlClient.SqlInternalConnectionTds..ctor(DbConnectionPoolIdentity identity, SqlConnectionString connectionOptions, Object providerInfo, Boolean redirectedUserInstance, SqlConnectionString userConnectionOptions, SessionData reconnectSessionData, Boolean applyTransientFaultHandling)
   at System.Data.SqlClient.SqlConnectionFactory.CreateConnection(DbConnectionOptions options, DbConnectionPoolKey poolKey, Object poolGroupProviderInfo, DbConnectionPool pool, DbConnection owningConnection, DbConnectionOptions userOptions)
   at System.Data.ProviderBase.DbConnectionFactory.CreatePooledConnection(DbConnectionPool pool, DbConnection owningObject, DbConnectionOptions options, DbConnectionPoolKey poolKey, DbConnectionOptions userOptions)
   at System.Data.ProviderBase.DbConnectionPool.CreateObject(DbConnection owningObject, DbConnectionOptions userOptions, DbConnectionInternal oldConnection)
   at System.Data.ProviderBase.DbConnectionPool.UserCreateRequest(DbConnection owningObject, DbConnectionOptions userOptions, DbConnectionInternal oldConnection)
   at System.Data.ProviderBase.DbConnectionPool.TryGetConnection(DbConnection owningObject, UInt32 waitForMultipleObjectsTimeout, Boolean allowCreate, Boolean onlyOneCheckConnection, DbConnectionOptions userOptions, DbConnectionInternal& connection)
   at System.Data.ProviderBase.DbConnectionPool.TryGetConnection(DbConnection owningObject, TaskCompletionSource`1 retry, DbConnectionOptions userOptions, DbConnectionInternal& connection)
   at System.Data.ProviderBase.DbConnectionFactory.TryGetConnection(DbConnection owningConnection, TaskCompletionSource`1 retry, DbConnectionOptions userOptions, DbConnectionInternal oldConnection, DbConnectionInternal& connection)
   at System.Data.ProviderBase.DbConnectionInternal.TryOpenConnectionInternal(DbConnection outerConnection, DbConnectionFactory connectionFactory, TaskCompletionSource`1 retry, DbConnectionOptions userOptions)
   at System.Data.SqlClient.SqlConnection.TryOpen(TaskCompletionSource`1 retry)
   at System.Data.SqlClient.SqlConnection.Open()
   at Microsoft.EntityFrameworkCore.Storage.RelationalConnection.Open()
   at Microsoft.EntityFrameworkCore.Query.Internal.QueryingEnumerable.Enumerator.BufferlessMoveNext(Boolean buffer)
   at Microsoft.EntityFrameworkCore.Storage.Internal.SqlServerExecutionStrategy.Execute[TState,TResult](Func`2 operation, Func`2 verifySucceeded, TState state)
ClientConnectionId:dba888b6-b4b9-4298-848f-e49382070501
Error Number:10054,State:0,Class:20
StackTrace:     at Microsoft.EntityFrameworkCore.Storage.Internal.SqlServerExecutionStrategy.Execute[TState,TResult](Func`2 operation, Func`2 verifySucceeded, TState state)
   at Microsoft.EntityFrameworkCore.Query.QueryMethodProvider.<_ShapedQuery>d__3`1.MoveNext()
   at Microsoft.EntityFrameworkCore.Query.QueryMethodProvider.<_Include>d__30`1.MoveNext()
   at Microsoft.EntityFrameworkCore.Query.QueryMethodProvider.<_Include>d__30`1.MoveNext()
   at System.Linq.Enumerable.FirstOrDefault[TSource](IEnumerable`1 source)
   at lambda_method(Closure , QueryContext )
   at Microsoft.EntityFrameworkCore.Query.Internal.QueryCompiler.<>c__DisplayClass20_0`1.<CompileQueryCore>b__0(QueryContext qc)
   at System.Linq.Queryable.FirstOrDefault[TSource](IQueryable`1 source)
   at FundTrack.BLL.Concrete.FixingBalanceService.GetFilteringByAccId(Int32 accountId) in C:\FundTrack\FundTrack.BLL\Concrete\FixingBalanceService.cs:line 32
   at FundTrack.WebUI.Controllers.FixingBalanceController.GetFilterByAccId(Nullable`1 accountId) in C:\FundTrack\FundTrack.WebUI\Controllers\FixingBalanceController.cs:line 32
   at lambda_method(Closure , Object , Object[] )
   at Microsoft.AspNetCore.Mvc.Internal.ControllerActionInvoker.<InvokeActionMethodAsync>d__27.MoveNext()
--- End of stack trace from previous location where exception was thrown ---
   at System.Runtime.ExceptionServices.ExceptionDispatchInfo.Throw()
   at System.Runtime.CompilerServices.TaskAwaiter.HandleNonSuccessAndDebuggerNotification(Task task)
   at Microsoft.AspNetCore.Mvc.Internal.ControllerActionInvoker.<InvokeNextActionFilterAsync>d__25.MoveNext()
--- End of stack trace from previous location where exception was thrown ---
   at System.Runtime.ExceptionServices.ExceptionDispatchInfo.Throw()
   at Microsoft.AspNetCore.Mvc.Internal.ControllerActionInvoker.Rethrow(ActionExecutedContext context)
   at Microsoft.AspNetCore.Mvc.Internal.ControllerActionInvoker.Next(State& next, Scope& scope, Object& state, Boolean& isCompleted)
   at Microsoft.AspNetCore.Mvc.Internal.ControllerActionInvoker.<InvokeNextResourceFilter>d__22.MoveNext()
--- End of stack trace from previous location where exception was thrown ---
   at System.Runtime.ExceptionServices.ExceptionDispatchInfo.Throw()
   at Microsoft.AspNetCore.Mvc.Internal.ControllerActionInvoker.Rethrow(ResourceExecutedContext context)
   at Microsoft.AspNetCore.Mvc.Internal.ControllerActionInvoker.Next(State& next, Scope& scope, Object& state, Boolean& isCompleted)
   at Microsoft.AspNetCore.Mvc.Internal.ControllerActionInvoker.<InvokeAsync>d__20.MoveNext()
--- End of stack trace from previous location where exception was thrown ---
   at System.Runtime.ExceptionServices.ExceptionDispatchInfo.Throw()
   at System.Runtime.CompilerServices.TaskAwaiter.HandleNonSuccessAndDebuggerNotification(Task task)
   at Microsoft.AspNetCore.Builder.RouterMiddleware.<Invoke>d__4.MoveNext()
--- End of stack trace from previous location where exception was thrown ---
   at System.Runtime.ExceptionServices.ExceptionDispatchInfo.Throw()
   at System.Runtime.CompilerServices.TaskAwaiter.HandleNonSuccessAndDebuggerNotification(Task task)
   at Microsoft.AspNetCore.SpaServices.Webpack.ConditionalProxyMiddleware.<Invoke>d__5.MoveNext()
--- End of stack trace from previous location where exception was thrown ---
   at System.Runtime.ExceptionServices.ExceptionDispatchInfo.Throw()
   at System.Runtime.CompilerServices.TaskAwaiter.HandleNonSuccessAndDebuggerNotification(Task task)
   at Microsoft.AspNetCore.SpaServices.Webpack.ConditionalProxyMiddleware.<Invoke>d__5.MoveNext()
--- End of stack trace from previous location where exception was thrown ---
   at System.Runtime.ExceptionServices.ExceptionDispatchInfo.Throw()
   at System.Runtime.CompilerServices.TaskAwaiter.HandleNonSuccessAndDebuggerNotification(Task task)
   at Microsoft.AspNetCore.Authentication.AuthenticationMiddleware`1.<Invoke>d__18.MoveNext()
--- End of stack trace from previous location where exception was thrown ---
   at System.Runtime.ExceptionServices.ExceptionDispatchInfo.Throw()
   at Microsoft.AspNetCore.Authentication.AuthenticationMiddleware`1.<Invoke>d__18.MoveNext()
--- End of stack trace from previous location where exception was thrown ---
   at System.Runtime.ExceptionServices.ExceptionDispatchInfo.Throw()
   at System.Runtime.CompilerServices.TaskAwaiter.HandleNonSuccessAndDebuggerNotification(Task task)
   at System.Runtime.CompilerServices.TaskAwaiter.GetResult()
   at FundTrack.WebUI.Middlewares.GlobalErrorHandlingMiddleware.<Invoke>d__4.MoveNext() in C:\FundTrack\FundTrack.WebUI\Middlewares\GlobalErrorHandlingMiddleware.cs:line 28
____________________________________________________________________________________________________________________________________________

Date and time:  30.10.2017 8:59:09
Error message:  An exception has been raised that is likely due to a transient failure. If you are connecting to a SQL Azure database consider using SqlAzureExecutionStrategy.
Source:  Microsoft.EntityFrameworkCore.SqlServer
InnerException:  System.Data.SqlClient.SqlException: The client was unable to establish a connection because of an error during connection initialization process before login. Possible causes include the following:  the client tried to connect to an unsupported version of SQL Server; the server was too busy to accept new connections; or there was a resource limitation (insufficient memory or maximum allowed connections) on the server. (provider: TCP Provider, error: 0 - An existing connection was forcibly closed by the remote host.) ---> System.ComponentModel.Win32Exception: An existing connection was forcibly closed by the remote host
   --- End of inner exception stack trace ---
   at System.Data.SqlClient.SqlInternalConnectionTds..ctor(DbConnectionPoolIdentity identity, SqlConnectionString connectionOptions, Object providerInfo, Boolean redirectedUserInstance, SqlConnectionString userConnectionOptions, SessionData reconnectSessionData, Boolean applyTransientFaultHandling)
   at System.Data.SqlClient.SqlConnectionFactory.CreateConnection(DbConnectionOptions options, DbConnectionPoolKey poolKey, Object poolGroupProviderInfo, DbConnectionPool pool, DbConnection owningConnection, DbConnectionOptions userOptions)
   at System.Data.ProviderBase.DbConnectionFactory.CreatePooledConnection(DbConnectionPool pool, DbConnection owningObject, DbConnectionOptions options, DbConnectionPoolKey poolKey, DbConnectionOptions userOptions)
   at System.Data.ProviderBase.DbConnectionPool.CreateObject(DbConnection owningObject, DbConnectionOptions userOptions, DbConnectionInternal oldConnection)
   at System.Data.ProviderBase.DbConnectionPool.UserCreateRequest(DbConnection owningObject, DbConnectionOptions userOptions, DbConnectionInternal oldConnection)
   at System.Data.ProviderBase.DbConnectionPool.TryGetConnection(DbConnection owningObject, UInt32 waitForMultipleObjectsTimeout, Boolean allowCreate, Boolean onlyOneCheckConnection, DbConnectionOptions userOptions, DbConnectionInternal& connection)
   at System.Data.ProviderBase.DbConnectionPool.TryGetConnection(DbConnection owningObject, TaskCompletionSource`1 retry, DbConnectionOptions userOptions, DbConnectionInternal& connection)
   at System.Data.ProviderBase.DbConnectionFactory.TryGetConnection(DbConnection owningConnection, TaskCompletionSource`1 retry, DbConnectionOptions userOptions, DbConnectionInternal oldConnection, DbConnectionInternal& connection)
   at System.Data.ProviderBase.DbConnectionInternal.TryOpenConnectionInternal(DbConnection outerConnection, DbConnectionFactory connectionFactory, TaskCompletionSource`1 retry, DbConnectionOptions userOptions)
   at System.Data.SqlClient.SqlConnection.TryOpen(TaskCompletionSource`1 retry)
   at System.Data.SqlClient.SqlConnection.Open()
   at Microsoft.EntityFrameworkCore.Storage.RelationalConnection.Open()
   at Microsoft.EntityFrameworkCore.Query.Internal.QueryingEnumerable.Enumerator.BufferlessMoveNext(Boolean buffer)
   at Microsoft.EntityFrameworkCore.Storage.Internal.SqlServerExecutionStrategy.Execute[TState,TResult](Func`2 operation, Func`2 verifySucceeded, TState state)
ClientConnectionId:2e9af38c-5dff-4c5d-ae33-663f8f3b1018
Error Number:10054,State:0,Class:20
StackTrace:     at Microsoft.EntityFrameworkCore.Storage.Internal.SqlServerExecutionStrategy.Execute[TState,TResult](Func`2 operation, Func`2 verifySucceeded, TState state)
   at Microsoft.EntityFrameworkCore.Query.QueryMethodProvider.<_ShapedQuery>d__3`1.MoveNext()
   at Microsoft.EntityFrameworkCore.Query.QueryMethodProvider.<_Include>d__30`1.MoveNext()
   at Microsoft.EntityFrameworkCore.Query.QueryMethodProvider.<_Include>d__30`1.MoveNext()
   at System.Linq.Enumerable.FirstOrDefault[TSource](IEnumerable`1 source)
   at lambda_method(Closure , QueryContext )
   at Microsoft.EntityFrameworkCore.Query.Internal.QueryCompiler.<>c__DisplayClass20_0`1.<CompileQueryCore>b__0(QueryContext qc)
   at System.Linq.Queryable.FirstOrDefault[TSource](IQueryable`1 source)
   at FundTrack.BLL.Concrete.FixingBalanceService.GetFilteringByAccId(Int32 accountId) in C:\FundTrack\FundTrack.BLL\Concrete\FixingBalanceService.cs:line 32
   at FundTrack.WebUI.Controllers.FixingBalanceController.GetFilterByAccId(Nullable`1 accountId) in C:\FundTrack\FundTrack.WebUI\Controllers\FixingBalanceController.cs:line 32
   at lambda_method(Closure , Object , Object[] )
   at Microsoft.AspNetCore.Mvc.Internal.ControllerActionInvoker.<InvokeActionMethodAsync>d__27.MoveNext()
--- End of stack trace from previous location where exception was thrown ---
   at System.Runtime.ExceptionServices.ExceptionDispatchInfo.Throw()
   at System.Runtime.CompilerServices.TaskAwaiter.HandleNonSuccessAndDebuggerNotification(Task task)
   at Microsoft.AspNetCore.Mvc.Internal.ControllerActionInvoker.<InvokeNextActionFilterAsync>d__25.MoveNext()
--- End of stack trace from previous location where exception was thrown ---
   at System.Runtime.ExceptionServices.ExceptionDispatchInfo.Throw()
   at Microsoft.AspNetCore.Mvc.Internal.ControllerActionInvoker.Rethrow(ActionExecutedContext context)
   at Microsoft.AspNetCore.Mvc.Internal.ControllerActionInvoker.Next(State& next, Scope& scope, Object& state, Boolean& isCompleted)
   at Microsoft.AspNetCore.Mvc.Internal.ControllerActionInvoker.<InvokeNextResourceFilter>d__22.MoveNext()
--- End of stack trace from previous location where exception was thrown ---
   at System.Runtime.ExceptionServices.ExceptionDispatchInfo.Throw()
   at Microsoft.AspNetCore.Mvc.Internal.ControllerActionInvoker.Rethrow(ResourceExecutedContext context)
   at Microsoft.AspNetCore.Mvc.Internal.ControllerActionInvoker.Next(State& next, Scope& scope, Object& state, Boolean& isCompleted)
   at Microsoft.AspNetCore.Mvc.Internal.ControllerActionInvoker.<InvokeAsync>d__20.MoveNext()
--- End of stack trace from previous location where exception was thrown ---
   at System.Runtime.ExceptionServices.ExceptionDispatchInfo.Throw()
   at System.Runtime.CompilerServices.TaskAwaiter.HandleNonSuccessAndDebuggerNotification(Task task)
   at Microsoft.AspNetCore.Builder.RouterMiddleware.<Invoke>d__4.MoveNext()
--- End of stack trace from previous location where exception was thrown ---
   at System.Runtime.ExceptionServices.ExceptionDispatchInfo.Throw()
   at System.Runtime.CompilerServices.TaskAwaiter.HandleNonSuccessAndDebuggerNotification(Task task)
   at Microsoft.AspNetCore.SpaServices.Webpack.ConditionalProxyMiddleware.<Invoke>d__5.MoveNext()
--- End of stack trace from previous location where exception was thrown ---
   at System.Runtime.ExceptionServices.ExceptionDispatchInfo.Throw()
   at System.Runtime.CompilerServices.TaskAwaiter.HandleNonSuccessAndDebuggerNotification(Task task)
   at Microsoft.AspNetCore.SpaServices.Webpack.ConditionalProxyMiddleware.<Invoke>d__5.MoveNext()
--- End of stack trace from previous location where exception was thrown ---
   at System.Runtime.ExceptionServices.ExceptionDispatchInfo.Throw()
   at System.Runtime.CompilerServices.TaskAwaiter.HandleNonSuccessAndDebuggerNotification(Task task)
   at Microsoft.AspNetCore.Authentication.AuthenticationMiddleware`1.<Invoke>d__18.MoveNext()
--- End of stack trace from previous location where exception was thrown ---
   at System.Runtime.ExceptionServices.ExceptionDispatchInfo.Throw()
   at Microsoft.AspNetCore.Authentication.AuthenticationMiddleware`1.<Invoke>d__18.MoveNext()
--- End of stack trace from previous location where exception was thrown ---
   at System.Runtime.ExceptionServices.ExceptionDispatchInfo.Throw()
   at System.Runtime.CompilerServices.TaskAwaiter.HandleNonSuccessAndDebuggerNotification(Task task)
   at System.Runtime.CompilerServices.TaskAwaiter.GetResult()
   at FundTrack.WebUI.Middlewares.GlobalErrorHandlingMiddleware.<Invoke>d__4.MoveNext() in C:\FundTrack\FundTrack.WebUI\Middlewares\GlobalErrorHandlingMiddleware.cs:line 28
____________________________________________________________________________________________________________________________________________

Date and time:  30.10.2017 9:03:01
Error message:  Список фінансових операцій порожній
Source:  FundTrack.BLL
InnerException:  FundTrack.BLL.Concrete.BusinessLogicException: Список фінансових операцій порожній ---> System.InvalidOperationException: A second operation started on this context before a previous operation completed. Any instance members are not guaranteed to be thread safe.
   at Microsoft.EntityFrameworkCore.Internal.ConcurrencyDetector.EnterCriticalSection()
   at Microsoft.EntityFrameworkCore.Query.Internal.LinqOperatorProvider.ExceptionInterceptor`1.EnumeratorExceptionInterceptor.MoveNext()
   at System.Collections.Generic.List`1..ctor(IEnumerable`1 collection)
   at System.Linq.Enumerable.ToList[TSource](IEnumerable`1 source)
   at FundTrack.BLL.Concrete.FinOpService.InitializeFinOps(IQueryable`1 finOps) in C:\FundTrack\FundTrack.BLL\Concrete\FinOpService.cs:line 227
   --- End of inner exception stack trace ---
   at FundTrack.BLL.Concrete.FinOpService.InitializeFinOps(IQueryable`1 finOps) in C:\FundTrack\FundTrack.BLL\Concrete\FinOpService.cs:line 246
   at FundTrack.BLL.Concrete.FinOpService.GetFinOpByOrgAccountIdForPage(Int32 orgAccountId, Int32 currentPage, Int32 itemsPerPage, Int32 finOpType) in C:\FundTrack\FundTrack.BLL\Concrete\FinOpService.cs:line 209
StackTrace:     at FundTrack.BLL.Concrete.FinOpService.GetFinOpByOrgAccountIdForPage(Int32 orgAccountId, Int32 currentPage, Int32 itemsPerPage, Int32 finOpType) in C:\FundTrack\FundTrack.BLL\Concrete\FinOpService.cs:line 219
   at FundTrack.WebUI.Controllers.FinOpController.GetFinOpsByIdForPage(Int32 accountId, Int32 currentPage, Int32 pageSize, Int32 finOpType) in C:\FundTrack\FundTrack.WebUI\Controllers\FinOpController.cs:line 88
   at lambda_method(Closure , Object , Object[] )
   at Microsoft.AspNetCore.Mvc.Internal.ControllerActionInvoker.<InvokeActionMethodAsync>d__27.MoveNext()
--- End of stack trace from previous location where exception was thrown ---
   at System.Runtime.ExceptionServices.ExceptionDispatchInfo.Throw()
   at System.Runtime.CompilerServices.TaskAwaiter.HandleNonSuccessAndDebuggerNotification(Task task)
   at Microsoft.AspNetCore.Mvc.Internal.ControllerActionInvoker.<InvokeNextActionFilterAsync>d__25.MoveNext()
--- End of stack trace from previous location where exception was thrown ---
   at System.Runtime.ExceptionServices.ExceptionDispatchInfo.Throw()
   at Microsoft.AspNetCore.Mvc.Internal.ControllerActionInvoker.Rethrow(ActionExecutedContext context)
   at Microsoft.AspNetCore.Mvc.Internal.ControllerActionInvoker.Next(State& next, Scope& scope, Object& state, Boolean& isCompleted)
   at Microsoft.AspNetCore.Mvc.Internal.ControllerActionInvoker.<InvokeNextResourceFilter>d__22.MoveNext()
--- End of stack trace from previous location where exception was thrown ---
   at System.Runtime.ExceptionServices.ExceptionDispatchInfo.Throw()
   at Microsoft.AspNetCore.Mvc.Internal.ControllerActionInvoker.Rethrow(ResourceExecutedContext context)
   at Microsoft.AspNetCore.Mvc.Internal.ControllerActionInvoker.Next(State& next, Scope& scope, Object& state, Boolean& isCompleted)
   at Microsoft.AspNetCore.Mvc.Internal.ControllerActionInvoker.<InvokeAsync>d__20.MoveNext()
--- End of stack trace from previous location where exception was thrown ---
   at System.Runtime.ExceptionServices.ExceptionDispatchInfo.Throw()
   at System.Runtime.CompilerServices.TaskAwaiter.HandleNonSuccessAndDebuggerNotification(Task task)
   at Microsoft.AspNetCore.Builder.RouterMiddleware.<Invoke>d__4.MoveNext()
--- End of stack trace from previous location where exception was thrown ---
   at System.Runtime.ExceptionServices.ExceptionDispatchInfo.Throw()
   at System.Runtime.CompilerServices.TaskAwaiter.HandleNonSuccessAndDebuggerNotification(Task task)
   at Microsoft.AspNetCore.SpaServices.Webpack.ConditionalProxyMiddleware.<Invoke>d__5.MoveNext()
--- End of stack trace from previous location where exception was thrown ---
   at System.Runtime.ExceptionServices.ExceptionDispatchInfo.Throw()
   at System.Runtime.CompilerServices.TaskAwaiter.HandleNonSuccessAndDebuggerNotification(Task task)
   at Microsoft.AspNetCore.SpaServices.Webpack.ConditionalProxyMiddleware.<Invoke>d__5.MoveNext()
--- End of stack trace from previous location where exception was thrown ---
   at System.Runtime.ExceptionServices.ExceptionDispatchInfo.Throw()
   at System.Runtime.CompilerServices.TaskAwaiter.HandleNonSuccessAndDebuggerNotification(Task task)
   at Microsoft.AspNetCore.Authentication.AuthenticationMiddleware`1.<Invoke>d__18.MoveNext()
--- End of stack trace from previous location where exception was thrown ---
   at System.Runtime.ExceptionServices.ExceptionDispatchInfo.Throw()
   at Microsoft.AspNetCore.Authentication.AuthenticationMiddleware`1.<Invoke>d__18.MoveNext()
--- End of stack trace from previous location where exception was thrown ---
   at System.Runtime.ExceptionServices.ExceptionDispatchInfo.Throw()
   at System.Runtime.CompilerServices.TaskAwaiter.HandleNonSuccessAndDebuggerNotification(Task task)
   at System.Runtime.CompilerServices.TaskAwaiter.GetResult()
   at FundTrack.WebUI.Middlewares.GlobalErrorHandlingMiddleware.<Invoke>d__4.MoveNext() in C:\FundTrack\FundTrack.WebUI\Middlewares\GlobalErrorHandlingMiddleware.cs:line 28
____________________________________________________________________________________________________________________________________________

Date and time:  30.10.2017 9:09:51
Error message:  An exception has been raised that is likely due to a transient failure. If you are connecting to a SQL Azure database consider using SqlAzureExecutionStrategy.
Source:  Microsoft.EntityFrameworkCore.SqlServer
InnerException:  System.Data.SqlClient.SqlException: A connection was successfully established with the server, but then an error occurred during the login process. (provider: SSL Provider, error: 0 - An existing connection was forcibly closed by the remote host.) ---> System.ComponentModel.Win32Exception: An existing connection was forcibly closed by the remote host
   --- End of inner exception stack trace ---
   at System.Data.SqlClient.SqlInternalConnectionTds..ctor(DbConnectionPoolIdentity identity, SqlConnectionString connectionOptions, Object providerInfo, Boolean redirectedUserInstance, SqlConnectionString userConnectionOptions, SessionData reconnectSessionData, Boolean applyTransientFaultHandling)
   at System.Data.SqlClient.SqlConnectionFactory.CreateConnection(DbConnectionOptions options, DbConnectionPoolKey poolKey, Object poolGroupProviderInfo, DbConnectionPool pool, DbConnection owningConnection, DbConnectionOptions userOptions)
   at System.Data.ProviderBase.DbConnectionFactory.CreatePooledConnection(DbConnectionPool pool, DbConnection owningObject, DbConnectionOptions options, DbConnectionPoolKey poolKey, DbConnectionOptions userOptions)
   at System.Data.ProviderBase.DbConnectionPool.CreateObject(DbConnection owningObject, DbConnectionOptions userOptions, DbConnectionInternal oldConnection)
   at System.Data.ProviderBase.DbConnectionPool.UserCreateRequest(DbConnection owningObject, DbConnectionOptions userOptions, DbConnectionInternal oldConnection)
   at System.Data.ProviderBase.DbConnectionPool.TryGetConnection(DbConnection owningObject, UInt32 waitForMultipleObjectsTimeout, Boolean allowCreate, Boolean onlyOneCheckConnection, DbConnectionOptions userOptions, DbConnectionInternal& connection)
   at System.Data.ProviderBase.DbConnectionPool.TryGetConnection(DbConnection owningObject, TaskCompletionSource`1 retry, DbConnectionOptions userOptions, DbConnectionInternal& connection)
   at System.Data.ProviderBase.DbConnectionFactory.TryGetConnection(DbConnection owningConnection, TaskCompletionSource`1 retry, DbConnectionOptions userOptions, DbConnectionInternal oldConnection, DbConnectionInternal& connection)
   at System.Data.ProviderBase.DbConnectionInternal.TryOpenConnectionInternal(DbConnection outerConnection, DbConnectionFactory connectionFactory, TaskCompletionSource`1 retry, DbConnectionOptions userOptions)
   at System.Data.SqlClient.SqlConnection.TryOpen(TaskCompletionSource`1 retry)
   at System.Data.SqlClient.SqlConnection.Open()
   at Microsoft.EntityFrameworkCore.Storage.RelationalConnection.Open()
   at Microsoft.EntityFrameworkCore.Query.Internal.QueryingEnumerable.Enumerator.BufferlessMoveNext(Boolean buffer)
   at Microsoft.EntityFrameworkCore.Storage.Internal.SqlServerExecutionStrategy.Execute[TState,TResult](Func`2 operation, Func`2 verifySucceeded, TState state)
ClientConnectionId:80dce3d7-f87c-4ae3-a3cd-8330445f627a
Error Number:10054,State:0,Class:20
StackTrace:     at Microsoft.EntityFrameworkCore.Storage.Internal.SqlServerExecutionStrategy.Execute[TState,TResult](Func`2 operation, Func`2 verifySucceeded, TState state)
   at Microsoft.EntityFrameworkCore.Query.QueryMethodProvider.<_ShapedQuery>d__3`1.MoveNext()
   at Microsoft.EntityFrameworkCore.Query.QueryMethodProvider.<_Include>d__30`1.MoveNext()
   at System.Linq.Enumerable.FirstOrDefault[TSource](IEnumerable`1 source)
   at lambda_method(Closure , QueryContext )
   at Microsoft.EntityFrameworkCore.Query.Internal.QueryCompiler.<>c__DisplayClass20_0`1.<CompileQueryCore>b__0(QueryContext qc)
   at System.Linq.Queryable.FirstOrDefault[TSource](IQueryable`1 source, Expression`1 predicate)
   at FundTrack.DAL.Concrete.OrganizationAccountRepository.GetOrgAccountById(Int32 orgAccountId) in C:\FundTrack\FundTrack.DAL\Concrete\OrganizationAccountRepository.cs:line 106
   at FundTrack.BLL.Concrete.OrganizationAccountService.IsDonationEnabled(Int32 orgAccountId) in C:\FundTrack\FundTrack.BLL\Concrete\OrganizationAccountService.cs:line 333
   at FundTrack.WebUI.Controllers.OrgAccountController.CheckDonateFunction(Int32 orgAccountId) in C:\FundTrack\FundTrack.WebUI\Controllers\OrgAccountController.cs:line 76
   at lambda_method(Closure , Object , Object[] )
   at Microsoft.AspNetCore.Mvc.Internal.ControllerActionInvoker.<InvokeActionMethodAsync>d__27.MoveNext()
--- End of stack trace from previous location where exception was thrown ---
   at System.Runtime.ExceptionServices.ExceptionDispatchInfo.Throw()
   at System.Runtime.CompilerServices.TaskAwaiter.HandleNonSuccessAndDebuggerNotification(Task task)
   at Microsoft.AspNetCore.Mvc.Internal.ControllerActionInvoker.<InvokeNextActionFilterAsync>d__25.MoveNext()
--- End of stack trace from previous location where exception was thrown ---
   at System.Runtime.ExceptionServices.ExceptionDispatchInfo.Throw()
   at Microsoft.AspNetCore.Mvc.Internal.ControllerActionInvoker.Rethrow(ActionExecutedContext context)
   at Microsoft.AspNetCore.Mvc.Internal.ControllerActionInvoker.Next(State& next, Scope& scope, Object& state, Boolean& isCompleted)
   at Microsoft.AspNetCore.Mvc.Internal.ControllerActionInvoker.<InvokeNextResourceFilter>d__22.MoveNext()
--- End of stack trace from previous location where exception was thrown ---
   at System.Runtime.ExceptionServices.ExceptionDispatchInfo.Throw()
   at Microsoft.AspNetCore.Mvc.Internal.ControllerActionInvoker.Rethrow(ResourceExecutedContext context)
   at Microsoft.AspNetCore.Mvc.Internal.ControllerActionInvoker.Next(State& next, Scope& scope, Object& state, Boolean& isCompleted)
   at Microsoft.AspNetCore.Mvc.Internal.ControllerActionInvoker.<InvokeAsync>d__20.MoveNext()
--- End of stack trace from previous location where exception was thrown ---
   at System.Runtime.ExceptionServices.ExceptionDispatchInfo.Throw()
   at System.Runtime.CompilerServices.TaskAwaiter.HandleNonSuccessAndDebuggerNotification(Task task)
   at Microsoft.AspNetCore.Builder.RouterMiddleware.<Invoke>d__4.MoveNext()
--- End of stack trace from previous location where exception was thrown ---
   at System.Runtime.ExceptionServices.ExceptionDispatchInfo.Throw()
   at System.Runtime.CompilerServices.TaskAwaiter.HandleNonSuccessAndDebuggerNotification(Task task)
   at Microsoft.AspNetCore.SpaServices.Webpack.ConditionalProxyMiddleware.<Invoke>d__5.MoveNext()
--- End of stack trace from previous location where exception was thrown ---
   at System.Runtime.ExceptionServices.ExceptionDispatchInfo.Throw()
   at System.Runtime.CompilerServices.TaskAwaiter.HandleNonSuccessAndDebuggerNotification(Task task)
   at Microsoft.AspNetCore.SpaServices.Webpack.ConditionalProxyMiddleware.<Invoke>d__5.MoveNext()
--- End of stack trace from previous location where exception was thrown ---
   at System.Runtime.ExceptionServices.ExceptionDispatchInfo.Throw()
   at System.Runtime.CompilerServices.TaskAwaiter.HandleNonSuccessAndDebuggerNotification(Task task)
   at Microsoft.AspNetCore.Authentication.AuthenticationMiddleware`1.<Invoke>d__18.MoveNext()
--- End of stack trace from previous location where exception was thrown ---
   at System.Runtime.ExceptionServices.ExceptionDispatchInfo.Throw()
   at Microsoft.AspNetCore.Authentication.AuthenticationMiddleware`1.<Invoke>d__18.MoveNext()
--- End of stack trace from previous location where exception was thrown ---
   at System.Runtime.ExceptionServices.ExceptionDispatchInfo.Throw()
   at System.Runtime.CompilerServices.TaskAwaiter.HandleNonSuccessAndDebuggerNotification(Task task)
   at System.Runtime.CompilerServices.TaskAwaiter.GetResult()
   at FundTrack.WebUI.Middlewares.GlobalErrorHandlingMiddleware.<Invoke>d__4.MoveNext() in C:\FundTrack\FundTrack.WebUI\Middlewares\GlobalErrorHandlingMiddleware.cs:line 28
____________________________________________________________________________________________________________________________________________

Date and time:  30.10.2017 9:13:59
Error message:  Список фінансових операцій порожній
Source:  FundTrack.BLL
InnerException:  FundTrack.BLL.Concrete.BusinessLogicException: Список фінансових операцій порожній ---> System.NullReferenceException: Object reference not set to an instance of an object.
   at FundTrack.BLL.Concrete.FinOpService.<>c.<InitializeFinOps>b__10_0(FinOp f) in C:\FundTrack\FundTrack.BLL\Concrete\FinOpService.cs:line 227
   at System.Linq.Enumerable.SelectListIterator`2.ToList()
   at System.Linq.Enumerable.ToList[TSource](IEnumerable`1 source)
   at FundTrack.BLL.Concrete.FinOpService.SetIsEditableField(IEnumerable`1 finOps) in C:\FundTrack\FundTrack.BLL\Concrete\FinOpService.cs:line 253
   at FundTrack.BLL.Concrete.FinOpService.InitializeFinOps(IEnumerable`1 finOps) in C:\FundTrack\FundTrack.BLL\Concrete\FinOpService.cs:line 241
   --- End of inner exception stack trace ---
   at FundTrack.BLL.Concrete.FinOpService.InitializeFinOps(IEnumerable`1 finOps) in C:\FundTrack\FundTrack.BLL\Concrete\FinOpService.cs:line 246
   at FundTrack.BLL.Concrete.FinOpService.GetFinOpByOrgAccountIdForPage(Int32 orgAccountId, Int32 currentPage, Int32 itemsPerPage, Int32 finOpType) in C:\FundTrack\FundTrack.BLL\Concrete\FinOpService.cs:line 209
StackTrace:     at FundTrack.BLL.Concrete.FinOpService.GetFinOpByOrgAccountIdForPage(Int32 orgAccountId, Int32 currentPage, Int32 itemsPerPage, Int32 finOpType) in C:\FundTrack\FundTrack.BLL\Concrete\FinOpService.cs:line 219
   at FundTrack.WebUI.Controllers.FinOpController.GetFinOpsByIdForPage(Int32 accountId, Int32 currentPage, Int32 pageSize, Int32 finOpType) in C:\FundTrack\FundTrack.WebUI\Controllers\FinOpController.cs:line 88
   at lambda_method(Closure , Object , Object[] )
   at Microsoft.AspNetCore.Mvc.Internal.ControllerActionInvoker.<InvokeActionMethodAsync>d__27.MoveNext()
--- End of stack trace from previous location where exception was thrown ---
   at System.Runtime.ExceptionServices.ExceptionDispatchInfo.Throw()
   at System.Runtime.CompilerServices.TaskAwaiter.HandleNonSuccessAndDebuggerNotification(Task task)
   at Microsoft.AspNetCore.Mvc.Internal.ControllerActionInvoker.<InvokeNextActionFilterAsync>d__25.MoveNext()
--- End of stack trace from previous location where exception was thrown ---
   at System.Runtime.ExceptionServices.ExceptionDispatchInfo.Throw()
   at Microsoft.AspNetCore.Mvc.Internal.ControllerActionInvoker.Rethrow(ActionExecutedContext context)
   at Microsoft.AspNetCore.Mvc.Internal.ControllerActionInvoker.Next(State& next, Scope& scope, Object& state, Boolean& isCompleted)
   at Microsoft.AspNetCore.Mvc.Internal.ControllerActionInvoker.<InvokeNextResourceFilter>d__22.MoveNext()
--- End of stack trace from previous location where exception was thrown ---
   at System.Runtime.ExceptionServices.ExceptionDispatchInfo.Throw()
   at Microsoft.AspNetCore.Mvc.Internal.ControllerActionInvoker.Rethrow(ResourceExecutedContext context)
   at Microsoft.AspNetCore.Mvc.Internal.ControllerActionInvoker.Next(State& next, Scope& scope, Object& state, Boolean& isCompleted)
   at Microsoft.AspNetCore.Mvc.Internal.ControllerActionInvoker.<InvokeAsync>d__20.MoveNext()
--- End of stack trace from previous location where exception was thrown ---
   at System.Runtime.ExceptionServices.ExceptionDispatchInfo.Throw()
   at System.Runtime.CompilerServices.TaskAwaiter.HandleNonSuccessAndDebuggerNotification(Task task)
   at Microsoft.AspNetCore.Builder.RouterMiddleware.<Invoke>d__4.MoveNext()
--- End of stack trace from previous location where exception was thrown ---
   at System.Runtime.ExceptionServices.ExceptionDispatchInfo.Throw()
   at System.Runtime.CompilerServices.TaskAwaiter.HandleNonSuccessAndDebuggerNotification(Task task)
   at Microsoft.AspNetCore.SpaServices.Webpack.ConditionalProxyMiddleware.<Invoke>d__5.MoveNext()
--- End of stack trace from previous location where exception was thrown ---
   at System.Runtime.ExceptionServices.ExceptionDispatchInfo.Throw()
   at System.Runtime.CompilerServices.TaskAwaiter.HandleNonSuccessAndDebuggerNotification(Task task)
   at Microsoft.AspNetCore.SpaServices.Webpack.ConditionalProxyMiddleware.<Invoke>d__5.MoveNext()
--- End of stack trace from previous location where exception was thrown ---
   at System.Runtime.ExceptionServices.ExceptionDispatchInfo.Throw()
   at System.Runtime.CompilerServices.TaskAwaiter.HandleNonSuccessAndDebuggerNotification(Task task)
   at Microsoft.AspNetCore.Authentication.AuthenticationMiddleware`1.<Invoke>d__18.MoveNext()
--- End of stack trace from previous location where exception was thrown ---
   at System.Runtime.ExceptionServices.ExceptionDispatchInfo.Throw()
   at Microsoft.AspNetCore.Authentication.AuthenticationMiddleware`1.<Invoke>d__18.MoveNext()
--- End of stack trace from previous location where exception was thrown ---
   at System.Runtime.ExceptionServices.ExceptionDispatchInfo.Throw()
   at System.Runtime.CompilerServices.TaskAwaiter.HandleNonSuccessAndDebuggerNotification(Task task)
   at System.Runtime.CompilerServices.TaskAwaiter.GetResult()
   at FundTrack.WebUI.Middlewares.GlobalErrorHandlingMiddleware.<Invoke>d__4.MoveNext() in C:\FundTrack\FundTrack.WebUI\Middlewares\GlobalErrorHandlingMiddleware.cs:line 28
____________________________________________________________________________________________________________________________________________

Date and time:  30.10.2017 9:14:07
Error message:  Неможливо отримати інформацію для рахунку
Source:  FundTrack.BLL
InnerException:  System.NullReferenceException: Object reference not set to an instance of an object.
   at FundTrack.BLL.Concrete.OrganizationAccountService.GetDonateCredentials(Int32 orgAccountId) in C:\FundTrack\FundTrack.BLL\Concrete\OrganizationAccountService.cs:line 354
StackTrace:     at FundTrack.BLL.Concrete.OrganizationAccountService.GetDonateCredentials(Int32 orgAccountId) in C:\FundTrack\FundTrack.BLL\Concrete\OrganizationAccountService.cs:line 365
   at FundTrack.WebUI.Controllers.OrgAccountController.GetDonateCredentials(Int32 orgAccountId) in C:\FundTrack\FundTrack.WebUI\Controllers\OrgAccountController.cs:line 82
   at lambda_method(Closure , Object , Object[] )
   at Microsoft.AspNetCore.Mvc.Internal.ControllerActionInvoker.<InvokeActionMethodAsync>d__27.MoveNext()
--- End of stack trace from previous location where exception was thrown ---
   at System.Runtime.ExceptionServices.ExceptionDispatchInfo.Throw()
   at System.Runtime.CompilerServices.TaskAwaiter.HandleNonSuccessAndDebuggerNotification(Task task)
   at Microsoft.AspNetCore.Mvc.Internal.ControllerActionInvoker.<InvokeNextActionFilterAsync>d__25.MoveNext()
--- End of stack trace from previous location where exception was thrown ---
   at System.Runtime.ExceptionServices.ExceptionDispatchInfo.Throw()
   at Microsoft.AspNetCore.Mvc.Internal.ControllerActionInvoker.Rethrow(ActionExecutedContext context)
   at Microsoft.AspNetCore.Mvc.Internal.ControllerActionInvoker.Next(State& next, Scope& scope, Object& state, Boolean& isCompleted)
   at Microsoft.AspNetCore.Mvc.Internal.ControllerActionInvoker.<InvokeNextResourceFilter>d__22.MoveNext()
--- End of stack trace from previous location where exception was thrown ---
   at System.Runtime.ExceptionServices.ExceptionDispatchInfo.Throw()
   at Microsoft.AspNetCore.Mvc.Internal.ControllerActionInvoker.Rethrow(ResourceExecutedContext context)
   at Microsoft.AspNetCore.Mvc.Internal.ControllerActionInvoker.Next(State& next, Scope& scope, Object& state, Boolean& isCompleted)
   at Microsoft.AspNetCore.Mvc.Internal.ControllerActionInvoker.<InvokeAsync>d__20.MoveNext()
--- End of stack trace from previous location where exception was thrown ---
   at System.Runtime.ExceptionServices.ExceptionDispatchInfo.Throw()
   at System.Runtime.CompilerServices.TaskAwaiter.HandleNonSuccessAndDebuggerNotification(Task task)
   at Microsoft.AspNetCore.Builder.RouterMiddleware.<Invoke>d__4.MoveNext()
--- End of stack trace from previous location where exception was thrown ---
   at System.Runtime.ExceptionServices.ExceptionDispatchInfo.Throw()
   at System.Runtime.CompilerServices.TaskAwaiter.HandleNonSuccessAndDebuggerNotification(Task task)
   at Microsoft.AspNetCore.SpaServices.Webpack.ConditionalProxyMiddleware.<Invoke>d__5.MoveNext()
--- End of stack trace from previous location where exception was thrown ---
   at System.Runtime.ExceptionServices.ExceptionDispatchInfo.Throw()
   at System.Runtime.CompilerServices.TaskAwaiter.HandleNonSuccessAndDebuggerNotification(Task task)
   at Microsoft.AspNetCore.SpaServices.Webpack.ConditionalProxyMiddleware.<Invoke>d__5.MoveNext()
--- End of stack trace from previous location where exception was thrown ---
   at System.Runtime.ExceptionServices.ExceptionDispatchInfo.Throw()
   at System.Runtime.CompilerServices.TaskAwaiter.HandleNonSuccessAndDebuggerNotification(Task task)
   at Microsoft.AspNetCore.Authentication.AuthenticationMiddleware`1.<Invoke>d__18.MoveNext()
--- End of stack trace from previous location where exception was thrown ---
   at System.Runtime.ExceptionServices.ExceptionDispatchInfo.Throw()
   at Microsoft.AspNetCore.Authentication.AuthenticationMiddleware`1.<Invoke>d__18.MoveNext()
--- End of stack trace from previous location where exception was thrown ---
   at System.Runtime.ExceptionServices.ExceptionDispatchInfo.Throw()
   at System.Runtime.CompilerServices.TaskAwaiter.HandleNonSuccessAndDebuggerNotification(Task task)
   at System.Runtime.CompilerServices.TaskAwaiter.GetResult()
   at FundTrack.WebUI.Middlewares.GlobalErrorHandlingMiddleware.<Invoke>d__4.MoveNext() in C:\FundTrack\FundTrack.WebUI\Middlewares\GlobalErrorHandlingMiddleware.cs:line 28
____________________________________________________________________________________________________________________________________________

Date and time:  30.10.2017 9:16:33
Error message:  Список фінансових операцій порожній
Source:  FundTrack.BLL
InnerException:  FundTrack.BLL.Concrete.BusinessLogicException: Список фінансових операцій порожній ---> System.NullReferenceException: Object reference not set to an instance of an object.
   at FundTrack.BLL.Concrete.FinOpService.<>c.<InitializeFinOps>b__10_0(FinOp f) in C:\FundTrack\FundTrack.BLL\Concrete\FinOpService.cs:line 227
   at System.Linq.Enumerable.SelectListIterator`2.ToList()
   at System.Linq.Enumerable.ToList[TSource](IEnumerable`1 source)
   at FundTrack.BLL.Concrete.FinOpService.SetIsEditableField(IEnumerable`1 finOps) in C:\FundTrack\FundTrack.BLL\Concrete\FinOpService.cs:line 253
   at FundTrack.BLL.Concrete.FinOpService.InitializeFinOps(IEnumerable`1 finOps) in C:\FundTrack\FundTrack.BLL\Concrete\FinOpService.cs:line 241
   --- End of inner exception stack trace ---
   at FundTrack.BLL.Concrete.FinOpService.InitializeFinOps(IEnumerable`1 finOps) in C:\FundTrack\FundTrack.BLL\Concrete\FinOpService.cs:line 246
   at FundTrack.BLL.Concrete.FinOpService.GetFinOpByOrgAccountIdForPage(Int32 orgAccountId, Int32 currentPage, Int32 itemsPerPage, Int32 finOpType) in C:\FundTrack\FundTrack.BLL\Concrete\FinOpService.cs:line 209
StackTrace:     at FundTrack.BLL.Concrete.FinOpService.GetFinOpByOrgAccountIdForPage(Int32 orgAccountId, Int32 currentPage, Int32 itemsPerPage, Int32 finOpType) in C:\FundTrack\FundTrack.BLL\Concrete\FinOpService.cs:line 219
   at FundTrack.WebUI.Controllers.FinOpController.GetFinOpsByIdForPage(Int32 accountId, Int32 currentPage, Int32 pageSize, Int32 finOpType) in C:\FundTrack\FundTrack.WebUI\Controllers\FinOpController.cs:line 88
   at lambda_method(Closure , Object , Object[] )
   at Microsoft.AspNetCore.Mvc.Internal.ControllerActionInvoker.<InvokeActionMethodAsync>d__27.MoveNext()
--- End of stack trace from previous location where exception was thrown ---
   at System.Runtime.ExceptionServices.ExceptionDispatchInfo.Throw()
   at System.Runtime.CompilerServices.TaskAwaiter.HandleNonSuccessAndDebuggerNotification(Task task)
   at Microsoft.AspNetCore.Mvc.Internal.ControllerActionInvoker.<InvokeNextActionFilterAsync>d__25.MoveNext()
--- End of stack trace from previous location where exception was thrown ---
   at System.Runtime.ExceptionServices.ExceptionDispatchInfo.Throw()
   at Microsoft.AspNetCore.Mvc.Internal.ControllerActionInvoker.Rethrow(ActionExecutedContext context)
   at Microsoft.AspNetCore.Mvc.Internal.ControllerActionInvoker.Next(State& next, Scope& scope, Object& state, Boolean& isCompleted)
   at Microsoft.AspNetCore.Mvc.Internal.ControllerActionInvoker.<InvokeNextResourceFilter>d__22.MoveNext()
--- End of stack trace from previous location where exception was thrown ---
   at System.Runtime.ExceptionServices.ExceptionDispatchInfo.Throw()
   at Microsoft.AspNetCore.Mvc.Internal.ControllerActionInvoker.Rethrow(ResourceExecutedContext context)
   at Microsoft.AspNetCore.Mvc.Internal.ControllerActionInvoker.Next(State& next, Scope& scope, Object& state, Boolean& isCompleted)
   at Microsoft.AspNetCore.Mvc.Internal.ControllerActionInvoker.<InvokeAsync>d__20.MoveNext()
--- End of stack trace from previous location where exception was thrown ---
   at System.Runtime.ExceptionServices.ExceptionDispatchInfo.Throw()
   at System.Runtime.CompilerServices.TaskAwaiter.HandleNonSuccessAndDebuggerNotification(Task task)
   at Microsoft.AspNetCore.Builder.RouterMiddleware.<Invoke>d__4.MoveNext()
--- End of stack trace from previous location where exception was thrown ---
   at System.Runtime.ExceptionServices.ExceptionDispatchInfo.Throw()
   at System.Runtime.CompilerServices.TaskAwaiter.HandleNonSuccessAndDebuggerNotification(Task task)
   at Microsoft.AspNetCore.SpaServices.Webpack.ConditionalProxyMiddleware.<Invoke>d__5.MoveNext()
--- End of stack trace from previous location where exception was thrown ---
   at System.Runtime.ExceptionServices.ExceptionDispatchInfo.Throw()
   at System.Runtime.CompilerServices.TaskAwaiter.HandleNonSuccessAndDebuggerNotification(Task task)
   at Microsoft.AspNetCore.SpaServices.Webpack.ConditionalProxyMiddleware.<Invoke>d__5.MoveNext()
--- End of stack trace from previous location where exception was thrown ---
   at System.Runtime.ExceptionServices.ExceptionDispatchInfo.Throw()
   at System.Runtime.CompilerServices.TaskAwaiter.HandleNonSuccessAndDebuggerNotification(Task task)
   at Microsoft.AspNetCore.Authentication.AuthenticationMiddleware`1.<Invoke>d__18.MoveNext()
--- End of stack trace from previous location where exception was thrown ---
   at System.Runtime.ExceptionServices.ExceptionDispatchInfo.Throw()
   at Microsoft.AspNetCore.Authentication.AuthenticationMiddleware`1.<Invoke>d__18.MoveNext()
--- End of stack trace from previous location where exception was thrown ---
   at System.Runtime.ExceptionServices.ExceptionDispatchInfo.Throw()
   at System.Runtime.CompilerServices.TaskAwaiter.HandleNonSuccessAndDebuggerNotification(Task task)
   at System.Runtime.CompilerServices.TaskAwaiter.GetResult()
   at FundTrack.WebUI.Middlewares.GlobalErrorHandlingMiddleware.<Invoke>d__4.MoveNext() in C:\FundTrack\FundTrack.WebUI\Middlewares\GlobalErrorHandlingMiddleware.cs:line 28
____________________________________________________________________________________________________________________________________________

Date and time:  30.10.2017 9:16:34
Error message:  An exception has been raised that is likely due to a transient failure. If you are connecting to a SQL Azure database consider using SqlAzureExecutionStrategy.
Source:  Microsoft.EntityFrameworkCore.SqlServer
InnerException:  System.Data.SqlClient.SqlException: A connection was successfully established with the server, but then an error occurred during the login process. (provider: TCP Provider, error: 0 - An existing connection was forcibly closed by the remote host.) ---> System.ComponentModel.Win32Exception: An existing connection was forcibly closed by the remote host
   --- End of inner exception stack trace ---
   at System.Data.SqlClient.SqlInternalConnectionTds..ctor(DbConnectionPoolIdentity identity, SqlConnectionString connectionOptions, Object providerInfo, Boolean redirectedUserInstance, SqlConnectionString userConnectionOptions, SessionData reconnectSessionData, Boolean applyTransientFaultHandling)
   at System.Data.SqlClient.SqlConnectionFactory.CreateConnection(DbConnectionOptions options, DbConnectionPoolKey poolKey, Object poolGroupProviderInfo, DbConnectionPool pool, DbConnection owningConnection, DbConnectionOptions userOptions)
   at System.Data.ProviderBase.DbConnectionFactory.CreatePooledConnection(DbConnectionPool pool, DbConnection owningObject, DbConnectionOptions options, DbConnectionPoolKey poolKey, DbConnectionOptions userOptions)
   at System.Data.ProviderBase.DbConnectionPool.CreateObject(DbConnection owningObject, DbConnectionOptions userOptions, DbConnectionInternal oldConnection)
   at System.Data.ProviderBase.DbConnectionPool.UserCreateRequest(DbConnection owningObject, DbConnectionOptions userOptions, DbConnectionInternal oldConnection)
   at System.Data.ProviderBase.DbConnectionPool.TryGetConnection(DbConnection owningObject, UInt32 waitForMultipleObjectsTimeout, Boolean allowCreate, Boolean onlyOneCheckConnection, DbConnectionOptions userOptions, DbConnectionInternal& connection)
   at System.Data.ProviderBase.DbConnectionPool.TryGetConnection(DbConnection owningObject, TaskCompletionSource`1 retry, DbConnectionOptions userOptions, DbConnectionInternal& connection)
   at System.Data.ProviderBase.DbConnectionFactory.TryGetConnection(DbConnection owningConnection, TaskCompletionSource`1 retry, DbConnectionOptions userOptions, DbConnectionInternal oldConnection, DbConnectionInternal& connection)
   at System.Data.ProviderBase.DbConnectionInternal.TryOpenConnectionInternal(DbConnection outerConnection, DbConnectionFactory connectionFactory, TaskCompletionSource`1 retry, DbConnectionOptions userOptions)
   at System.Data.SqlClient.SqlConnection.TryOpen(TaskCompletionSource`1 retry)
   at System.Data.SqlClient.SqlConnection.Open()
   at Microsoft.EntityFrameworkCore.Storage.RelationalConnection.Open()
   at Microsoft.EntityFrameworkCore.Query.Internal.QueryingEnumerable.Enumerator.BufferlessMoveNext(Boolean buffer)
   at Microsoft.EntityFrameworkCore.Storage.Internal.SqlServerExecutionStrategy.Execute[TState,TResult](Func`2 operation, Func`2 verifySucceeded, TState state)
ClientConnectionId:7b0b39ba-40ff-4954-911e-5a8549edd65a
Error Number:10054,State:0,Class:20
StackTrace:     at Microsoft.EntityFrameworkCore.Storage.Internal.SqlServerExecutionStrategy.Execute[TState,TResult](Func`2 operation, Func`2 verifySucceeded, TState state)
   at Microsoft.EntityFrameworkCore.Query.QueryMethodProvider.<_ShapedQuery>d__3`1.MoveNext()
   at Microsoft.EntityFrameworkCore.Query.QueryMethodProvider.<_Include>d__30`1.MoveNext()
   at System.Linq.Enumerable.FirstOrDefault[TSource](IEnumerable`1 source)
   at lambda_method(Closure , QueryContext )
   at Microsoft.EntityFrameworkCore.Query.Internal.QueryCompiler.<>c__DisplayClass20_0`1.<CompileQueryCore>b__0(QueryContext qc)
   at System.Linq.Queryable.FirstOrDefault[TSource](IQueryable`1 source, Expression`1 predicate)
   at FundTrack.DAL.Concrete.OrganizationAccountRepository.GetOrgAccountById(Int32 orgAccountId) in C:\FundTrack\FundTrack.DAL\Concrete\OrganizationAccountRepository.cs:line 106
   at FundTrack.BLL.Concrete.OrganizationAccountService.GetDonateCredentials(Int32 orgAccountId) in C:\FundTrack\FundTrack.BLL\Concrete\OrganizationAccountService.cs:line 350
   at FundTrack.WebUI.Controllers.OrgAccountController.GetDonateCredentials(Int32 orgAccountId) in C:\FundTrack\FundTrack.WebUI\Controllers\OrgAccountController.cs:line 82
   at lambda_method(Closure , Object , Object[] )
   at Microsoft.AspNetCore.Mvc.Internal.ControllerActionInvoker.<InvokeActionMethodAsync>d__27.MoveNext()
--- End of stack trace from previous location where exception was thrown ---
   at System.Runtime.ExceptionServices.ExceptionDispatchInfo.Throw()
   at System.Runtime.CompilerServices.TaskAwaiter.HandleNonSuccessAndDebuggerNotification(Task task)
   at Microsoft.AspNetCore.Mvc.Internal.ControllerActionInvoker.<InvokeNextActionFilterAsync>d__25.MoveNext()
--- End of stack trace from previous location where exception was thrown ---
   at System.Runtime.ExceptionServices.ExceptionDispatchInfo.Throw()
   at Microsoft.AspNetCore.Mvc.Internal.ControllerActionInvoker.Rethrow(ActionExecutedContext context)
   at Microsoft.AspNetCore.Mvc.Internal.ControllerActionInvoker.Next(State& next, Scope& scope, Object& state, Boolean& isCompleted)
   at Microsoft.AspNetCore.Mvc.Internal.ControllerActionInvoker.<InvokeNextResourceFilter>d__22.MoveNext()
--- End of stack trace from previous location where exception was thrown ---
   at System.Runtime.ExceptionServices.ExceptionDispatchInfo.Throw()
   at Microsoft.AspNetCore.Mvc.Internal.ControllerActionInvoker.Rethrow(ResourceExecutedContext context)
   at Microsoft.AspNetCore.Mvc.Internal.ControllerActionInvoker.Next(State& next, Scope& scope, Object& state, Boolean& isCompleted)
   at Microsoft.AspNetCore.Mvc.Internal.ControllerActionInvoker.<InvokeAsync>d__20.MoveNext()
--- End of stack trace from previous location where exception was thrown ---
   at System.Runtime.ExceptionServices.ExceptionDispatchInfo.Throw()
   at System.Runtime.CompilerServices.TaskAwaiter.HandleNonSuccessAndDebuggerNotification(Task task)
   at Microsoft.AspNetCore.Builder.RouterMiddleware.<Invoke>d__4.MoveNext()
--- End of stack trace from previous location where exception was thrown ---
   at System.Runtime.ExceptionServices.ExceptionDispatchInfo.Throw()
   at System.Runtime.CompilerServices.TaskAwaiter.HandleNonSuccessAndDebuggerNotification(Task task)
   at Microsoft.AspNetCore.SpaServices.Webpack.ConditionalProxyMiddleware.<Invoke>d__5.MoveNext()
--- End of stack trace from previous location where exception was thrown ---
   at System.Runtime.ExceptionServices.ExceptionDispatchInfo.Throw()
   at System.Runtime.CompilerServices.TaskAwaiter.HandleNonSuccessAndDebuggerNotification(Task task)
   at Microsoft.AspNetCore.SpaServices.Webpack.ConditionalProxyMiddleware.<Invoke>d__5.MoveNext()
--- End of stack trace from previous location where exception was thrown ---
   at System.Runtime.ExceptionServices.ExceptionDispatchInfo.Throw()
   at System.Runtime.CompilerServices.TaskAwaiter.HandleNonSuccessAndDebuggerNotification(Task task)
   at Microsoft.AspNetCore.Authentication.AuthenticationMiddleware`1.<Invoke>d__18.MoveNext()
--- End of stack trace from previous location where exception was thrown ---
   at System.Runtime.ExceptionServices.ExceptionDispatchInfo.Throw()
   at Microsoft.AspNetCore.Authentication.AuthenticationMiddleware`1.<Invoke>d__18.MoveNext()
--- End of stack trace from previous location where exception was thrown ---
   at System.Runtime.ExceptionServices.ExceptionDispatchInfo.Throw()
   at System.Runtime.CompilerServices.TaskAwaiter.HandleNonSuccessAndDebuggerNotification(Task task)
   at System.Runtime.CompilerServices.TaskAwaiter.GetResult()
   at FundTrack.WebUI.Middlewares.GlobalErrorHandlingMiddleware.<Invoke>d__4.MoveNext() in C:\FundTrack\FundTrack.WebUI\Middlewares\GlobalErrorHandlingMiddleware.cs:line 28
____________________________________________________________________________________________________________________________________________

Date and time:  30.10.2017 9:18:13
Error message:  An exception has been raised that is likely due to a transient failure. If you are connecting to a SQL Azure database consider using SqlAzureExecutionStrategy.
Source:  Microsoft.EntityFrameworkCore.SqlServer
InnerException:  System.Data.SqlClient.SqlException: A connection was successfully established with the server, but then an error occurred during the login process. (provider: SSL Provider, error: 0 - An existing connection was forcibly closed by the remote host.) ---> System.ComponentModel.Win32Exception: An existing connection was forcibly closed by the remote host
   --- End of inner exception stack trace ---
   at System.Data.SqlClient.SqlInternalConnectionTds..ctor(DbConnectionPoolIdentity identity, SqlConnectionString connectionOptions, Object providerInfo, Boolean redirectedUserInstance, SqlConnectionString userConnectionOptions, SessionData reconnectSessionData, Boolean applyTransientFaultHandling)
   at System.Data.SqlClient.SqlConnectionFactory.CreateConnection(DbConnectionOptions options, DbConnectionPoolKey poolKey, Object poolGroupProviderInfo, DbConnectionPool pool, DbConnection owningConnection, DbConnectionOptions userOptions)
   at System.Data.ProviderBase.DbConnectionFactory.CreatePooledConnection(DbConnectionPool pool, DbConnection owningObject, DbConnectionOptions options, DbConnectionPoolKey poolKey, DbConnectionOptions userOptions)
   at System.Data.ProviderBase.DbConnectionPool.CreateObject(DbConnection owningObject, DbConnectionOptions userOptions, DbConnectionInternal oldConnection)
   at System.Data.ProviderBase.DbConnectionPool.UserCreateRequest(DbConnection owningObject, DbConnectionOptions userOptions, DbConnectionInternal oldConnection)
   at System.Data.ProviderBase.DbConnectionPool.TryGetConnection(DbConnection owningObject, UInt32 waitForMultipleObjectsTimeout, Boolean allowCreate, Boolean onlyOneCheckConnection, DbConnectionOptions userOptions, DbConnectionInternal& connection)
   at System.Data.ProviderBase.DbConnectionPool.TryGetConnection(DbConnection owningObject, TaskCompletionSource`1 retry, DbConnectionOptions userOptions, DbConnectionInternal& connection)
   at System.Data.ProviderBase.DbConnectionFactory.TryGetConnection(DbConnection owningConnection, TaskCompletionSource`1 retry, DbConnectionOptions userOptions, DbConnectionInternal oldConnection, DbConnectionInternal& connection)
   at System.Data.ProviderBase.DbConnectionInternal.TryOpenConnectionInternal(DbConnection outerConnection, DbConnectionFactory connectionFactory, TaskCompletionSource`1 retry, DbConnectionOptions userOptions)
   at System.Data.SqlClient.SqlConnection.TryOpen(TaskCompletionSource`1 retry)
   at System.Data.SqlClient.SqlConnection.Open()
   at Microsoft.EntityFrameworkCore.Storage.RelationalConnection.Open()
   at Microsoft.EntityFrameworkCore.Query.Internal.QueryingEnumerable.Enumerator.BufferlessMoveNext(Boolean buffer)
   at Microsoft.EntityFrameworkCore.Storage.Internal.SqlServerExecutionStrategy.Execute[TState,TResult](Func`2 operation, Func`2 verifySucceeded, TState state)
ClientConnectionId:c57659ff-9fde-4205-9f45-9ecaab491b7c
Error Number:10054,State:0,Class:20
StackTrace:     at Microsoft.EntityFrameworkCore.Storage.Internal.SqlServerExecutionStrategy.Execute[TState,TResult](Func`2 operation, Func`2 verifySucceeded, TState state)
   at Microsoft.EntityFrameworkCore.Query.QueryMethodProvider.<_ShapedQuery>d__3`1.MoveNext()
   at Microsoft.EntityFrameworkCore.Query.QueryMethodProvider.<_Include>d__30`1.MoveNext()
   at Microsoft.EntityFrameworkCore.Query.QueryMethodProvider.<_Include>d__30`1.MoveNext()
   at System.Linq.Enumerable.FirstOrDefault[TSource](IEnumerable`1 source)
   at lambda_method(Closure , QueryContext )
   at Microsoft.EntityFrameworkCore.Query.Internal.QueryCompiler.<>c__DisplayClass20_0`1.<CompileQueryCore>b__0(QueryContext qc)
   at System.Linq.Queryable.FirstOrDefault[TSource](IQueryable`1 source)
   at FundTrack.BLL.Concrete.FixingBalanceService.GetFilteringByAccId(Int32 accountId) in C:\FundTrack\FundTrack.BLL\Concrete\FixingBalanceService.cs:line 32
   at FundTrack.WebUI.Controllers.FixingBalanceController.GetFilterByAccId(Nullable`1 accountId) in C:\FundTrack\FundTrack.WebUI\Controllers\FixingBalanceController.cs:line 32
   at lambda_method(Closure , Object , Object[] )
   at Microsoft.AspNetCore.Mvc.Internal.ControllerActionInvoker.<InvokeActionMethodAsync>d__27.MoveNext()
--- End of stack trace from previous location where exception was thrown ---
   at System.Runtime.ExceptionServices.ExceptionDispatchInfo.Throw()
   at System.Runtime.CompilerServices.TaskAwaiter.HandleNonSuccessAndDebuggerNotification(Task task)
   at Microsoft.AspNetCore.Mvc.Internal.ControllerActionInvoker.<InvokeNextActionFilterAsync>d__25.MoveNext()
--- End of stack trace from previous location where exception was thrown ---
   at System.Runtime.ExceptionServices.ExceptionDispatchInfo.Throw()
   at Microsoft.AspNetCore.Mvc.Internal.ControllerActionInvoker.Rethrow(ActionExecutedContext context)
   at Microsoft.AspNetCore.Mvc.Internal.ControllerActionInvoker.Next(State& next, Scope& scope, Object& state, Boolean& isCompleted)
   at Microsoft.AspNetCore.Mvc.Internal.ControllerActionInvoker.<InvokeNextResourceFilter>d__22.MoveNext()
--- End of stack trace from previous location where exception was thrown ---
   at System.Runtime.ExceptionServices.ExceptionDispatchInfo.Throw()
   at Microsoft.AspNetCore.Mvc.Internal.ControllerActionInvoker.Rethrow(ResourceExecutedContext context)
   at Microsoft.AspNetCore.Mvc.Internal.ControllerActionInvoker.Next(State& next, Scope& scope, Object& state, Boolean& isCompleted)
   at Microsoft.AspNetCore.Mvc.Internal.ControllerActionInvoker.<InvokeAsync>d__20.MoveNext()
--- End of stack trace from previous location where exception was thrown ---
   at System.Runtime.ExceptionServices.ExceptionDispatchInfo.Throw()
   at System.Runtime.CompilerServices.TaskAwaiter.HandleNonSuccessAndDebuggerNotification(Task task)
   at Microsoft.AspNetCore.Builder.RouterMiddleware.<Invoke>d__4.MoveNext()
--- End of stack trace from previous location where exception was thrown ---
   at System.Runtime.ExceptionServices.ExceptionDispatchInfo.Throw()
   at System.Runtime.CompilerServices.TaskAwaiter.HandleNonSuccessAndDebuggerNotification(Task task)
   at Microsoft.AspNetCore.SpaServices.Webpack.ConditionalProxyMiddleware.<Invoke>d__5.MoveNext()
--- End of stack trace from previous location where exception was thrown ---
   at System.Runtime.ExceptionServices.ExceptionDispatchInfo.Throw()
   at System.Runtime.CompilerServices.TaskAwaiter.HandleNonSuccessAndDebuggerNotification(Task task)
   at Microsoft.AspNetCore.SpaServices.Webpack.ConditionalProxyMiddleware.<Invoke>d__5.MoveNext()
--- End of stack trace from previous location where exception was thrown ---
   at System.Runtime.ExceptionServices.ExceptionDispatchInfo.Throw()
   at System.Runtime.CompilerServices.TaskAwaiter.HandleNonSuccessAndDebuggerNotification(Task task)
   at Microsoft.AspNetCore.Authentication.AuthenticationMiddleware`1.<Invoke>d__18.MoveNext()
--- End of stack trace from previous location where exception was thrown ---
   at System.Runtime.ExceptionServices.ExceptionDispatchInfo.Throw()
   at Microsoft.AspNetCore.Authentication.AuthenticationMiddleware`1.<Invoke>d__18.MoveNext()
--- End of stack trace from previous location where exception was thrown ---
   at System.Runtime.ExceptionServices.ExceptionDispatchInfo.Throw()
   at System.Runtime.CompilerServices.TaskAwaiter.HandleNonSuccessAndDebuggerNotification(Task task)
   at System.Runtime.CompilerServices.TaskAwaiter.GetResult()
   at FundTrack.WebUI.Middlewares.GlobalErrorHandlingMiddleware.<Invoke>d__4.MoveNext() in C:\FundTrack\FundTrack.WebUI\Middlewares\GlobalErrorHandlingMiddleware.cs:line 28
____________________________________________________________________________________________________________________________________________

Date and time:  30.10.2017 9:22:36
Error message:  An exception has been raised that is likely due to a transient failure. If you are connecting to a SQL Azure database consider using SqlAzureExecutionStrategy.
Source:  Microsoft.EntityFrameworkCore.SqlServer
InnerException:  System.Data.SqlClient.SqlException: A connection was successfully established with the server, but then an error occurred during the login process. (provider: SSL Provider, error: 0 - The specified network name is no longer available.) ---> System.ComponentModel.Win32Exception: The specified network name is no longer available
   --- End of inner exception stack trace ---
   at System.Data.SqlClient.SqlInternalConnectionTds..ctor(DbConnectionPoolIdentity identity, SqlConnectionString connectionOptions, Object providerInfo, Boolean redirectedUserInstance, SqlConnectionString userConnectionOptions, SessionData reconnectSessionData, Boolean applyTransientFaultHandling)
   at System.Data.SqlClient.SqlConnectionFactory.CreateConnection(DbConnectionOptions options, DbConnectionPoolKey poolKey, Object poolGroupProviderInfo, DbConnectionPool pool, DbConnection owningConnection, DbConnectionOptions userOptions)
   at System.Data.ProviderBase.DbConnectionFactory.CreatePooledConnection(DbConnectionPool pool, DbConnection owningObject, DbConnectionOptions options, DbConnectionPoolKey poolKey, DbConnectionOptions userOptions)
   at System.Data.ProviderBase.DbConnectionPool.CreateObject(DbConnection owningObject, DbConnectionOptions userOptions, DbConnectionInternal oldConnection)
   at System.Data.ProviderBase.DbConnectionPool.UserCreateRequest(DbConnection owningObject, DbConnectionOptions userOptions, DbConnectionInternal oldConnection)
   at System.Data.ProviderBase.DbConnectionPool.TryGetConnection(DbConnection owningObject, UInt32 waitForMultipleObjectsTimeout, Boolean allowCreate, Boolean onlyOneCheckConnection, DbConnectionOptions userOptions, DbConnectionInternal& connection)
   at System.Data.ProviderBase.DbConnectionPool.TryGetConnection(DbConnection owningObject, TaskCompletionSource`1 retry, DbConnectionOptions userOptions, DbConnectionInternal& connection)
   at System.Data.ProviderBase.DbConnectionFactory.TryGetConnection(DbConnection owningConnection, TaskCompletionSource`1 retry, DbConnectionOptions userOptions, DbConnectionInternal oldConnection, DbConnectionInternal& connection)
   at System.Data.ProviderBase.DbConnectionInternal.TryOpenConnectionInternal(DbConnection outerConnection, DbConnectionFactory connectionFactory, TaskCompletionSource`1 retry, DbConnectionOptions userOptions)
   at System.Data.SqlClient.SqlConnection.TryOpen(TaskCompletionSource`1 retry)
   at System.Data.SqlClient.SqlConnection.Open()
   at Microsoft.EntityFrameworkCore.Storage.RelationalConnection.Open()
   at Microsoft.EntityFrameworkCore.Query.Internal.QueryingEnumerable.Enumerator.BufferlessMoveNext(Boolean buffer)
   at Microsoft.EntityFrameworkCore.Storage.Internal.SqlServerExecutionStrategy.Execute[TState,TResult](Func`2 operation, Func`2 verifySucceeded, TState state)
ClientConnectionId:465819d7-363f-40e4-898d-178d55346118
Error Number:64,State:0,Class:20
StackTrace:     at Microsoft.EntityFrameworkCore.Storage.Internal.SqlServerExecutionStrategy.Execute[TState,TResult](Func`2 operation, Func`2 verifySucceeded, TState state)
   at Microsoft.EntityFrameworkCore.Query.QueryMethodProvider.<_ShapedQuery>d__3`1.MoveNext()
   at Microsoft.EntityFrameworkCore.Query.QueryMethodProvider.<_Include>d__30`1.MoveNext()
   at Microsoft.EntityFrameworkCore.Query.QueryMethodProvider.<_Include>d__30`1.MoveNext()
   at System.Linq.Enumerable.FirstOrDefault[TSource](IEnumerable`1 source)
   at lambda_method(Closure , QueryContext )
   at Microsoft.EntityFrameworkCore.Query.Internal.QueryCompiler.<>c__DisplayClass20_0`1.<CompileQueryCore>b__0(QueryContext qc)
   at System.Linq.Queryable.FirstOrDefault[TSource](IQueryable`1 source)
   at FundTrack.BLL.Concrete.FixingBalanceService.GetFilteringByAccId(Int32 accountId) in C:\FundTrack\FundTrack.BLL\Concrete\FixingBalanceService.cs:line 32
   at FundTrack.WebUI.Controllers.FixingBalanceController.GetFilterByAccId(Nullable`1 accountId) in C:\FundTrack\FundTrack.WebUI\Controllers\FixingBalanceController.cs:line 32
   at lambda_method(Closure , Object , Object[] )
   at Microsoft.AspNetCore.Mvc.Internal.ControllerActionInvoker.<InvokeActionMethodAsync>d__27.MoveNext()
--- End of stack trace from previous location where exception was thrown ---
   at System.Runtime.ExceptionServices.ExceptionDispatchInfo.Throw()
   at System.Runtime.CompilerServices.TaskAwaiter.HandleNonSuccessAndDebuggerNotification(Task task)
   at Microsoft.AspNetCore.Mvc.Internal.ControllerActionInvoker.<InvokeNextActionFilterAsync>d__25.MoveNext()
--- End of stack trace from previous location where exception was thrown ---
   at System.Runtime.ExceptionServices.ExceptionDispatchInfo.Throw()
   at Microsoft.AspNetCore.Mvc.Internal.ControllerActionInvoker.Rethrow(ActionExecutedContext context)
   at Microsoft.AspNetCore.Mvc.Internal.ControllerActionInvoker.Next(State& next, Scope& scope, Object& state, Boolean& isCompleted)
   at Microsoft.AspNetCore.Mvc.Internal.ControllerActionInvoker.<InvokeNextResourceFilter>d__22.MoveNext()
--- End of stack trace from previous location where exception was thrown ---
   at System.Runtime.ExceptionServices.ExceptionDispatchInfo.Throw()
   at Microsoft.AspNetCore.Mvc.Internal.ControllerActionInvoker.Rethrow(ResourceExecutedContext context)
   at Microsoft.AspNetCore.Mvc.Internal.ControllerActionInvoker.Next(State& next, Scope& scope, Object& state, Boolean& isCompleted)
   at Microsoft.AspNetCore.Mvc.Internal.ControllerActionInvoker.<InvokeAsync>d__20.MoveNext()
--- End of stack trace from previous location where exception was thrown ---
   at System.Runtime.ExceptionServices.ExceptionDispatchInfo.Throw()
   at System.Runtime.CompilerServices.TaskAwaiter.HandleNonSuccessAndDebuggerNotification(Task task)
   at Microsoft.AspNetCore.Builder.RouterMiddleware.<Invoke>d__4.MoveNext()
--- End of stack trace from previous location where exception was thrown ---
   at System.Runtime.ExceptionServices.ExceptionDispatchInfo.Throw()
   at System.Runtime.CompilerServices.TaskAwaiter.HandleNonSuccessAndDebuggerNotification(Task task)
   at Microsoft.AspNetCore.SpaServices.Webpack.ConditionalProxyMiddleware.<Invoke>d__5.MoveNext()
--- End of stack trace from previous location where exception was thrown ---
   at System.Runtime.ExceptionServices.ExceptionDispatchInfo.Throw()
   at System.Runtime.CompilerServices.TaskAwaiter.HandleNonSuccessAndDebuggerNotification(Task task)
   at Microsoft.AspNetCore.SpaServices.Webpack.ConditionalProxyMiddleware.<Invoke>d__5.MoveNext()
--- End of stack trace from previous location where exception was thrown ---
   at System.Runtime.ExceptionServices.ExceptionDispatchInfo.Throw()
   at System.Runtime.CompilerServices.TaskAwaiter.HandleNonSuccessAndDebuggerNotification(Task task)
   at Microsoft.AspNetCore.Authentication.AuthenticationMiddleware`1.<Invoke>d__18.MoveNext()
--- End of stack trace from previous location where exception was thrown ---
   at System.Runtime.ExceptionServices.ExceptionDispatchInfo.Throw()
   at Microsoft.AspNetCore.Authentication.AuthenticationMiddleware`1.<Invoke>d__18.MoveNext()
--- End of stack trace from previous location where exception was thrown ---
   at System.Runtime.ExceptionServices.ExceptionDispatchInfo.Throw()
   at System.Runtime.CompilerServices.TaskAwaiter.HandleNonSuccessAndDebuggerNotification(Task task)
   at System.Runtime.CompilerServices.TaskAwaiter.GetResult()
   at FundTrack.WebUI.Middlewares.GlobalErrorHandlingMiddleware.<Invoke>d__4.MoveNext() in C:\FundTrack\FundTrack.WebUI\Middlewares\GlobalErrorHandlingMiddleware.cs:line 28
____________________________________________________________________________________________________________________________________________

Date and time:  30.10.2017 9:49:47
Error message:  Неможливо отримати інформацію для рахунку
Source:  FundTrack.BLL
InnerException:  System.NullReferenceException: Object reference not set to an instance of an object.
   at FundTrack.BLL.Concrete.OrganizationAccountService.GetDonateCredentials(Int32 orgAccountId) in C:\FundTrack\FundTrack.BLL\Concrete\OrganizationAccountService.cs:line 354
StackTrace:     at FundTrack.BLL.Concrete.OrganizationAccountService.GetDonateCredentials(Int32 orgAccountId) in C:\FundTrack\FundTrack.BLL\Concrete\OrganizationAccountService.cs:line 365
   at FundTrack.WebUI.Controllers.OrgAccountController.GetDonateCredentials(Int32 orgAccountId) in C:\FundTrack\FundTrack.WebUI\Controllers\OrgAccountController.cs:line 82
   at lambda_method(Closure , Object , Object[] )
   at Microsoft.AspNetCore.Mvc.Internal.ControllerActionInvoker.<InvokeActionMethodAsync>d__27.MoveNext()
--- End of stack trace from previous location where exception was thrown ---
   at System.Runtime.ExceptionServices.ExceptionDispatchInfo.Throw()
   at System.Runtime.CompilerServices.TaskAwaiter.HandleNonSuccessAndDebuggerNotification(Task task)
   at Microsoft.AspNetCore.Mvc.Internal.ControllerActionInvoker.<InvokeNextActionFilterAsync>d__25.MoveNext()
--- End of stack trace from previous location where exception was thrown ---
   at System.Runtime.ExceptionServices.ExceptionDispatchInfo.Throw()
   at Microsoft.AspNetCore.Mvc.Internal.ControllerActionInvoker.Rethrow(ActionExecutedContext context)
   at Microsoft.AspNetCore.Mvc.Internal.ControllerActionInvoker.Next(State& next, Scope& scope, Object& state, Boolean& isCompleted)
   at Microsoft.AspNetCore.Mvc.Internal.ControllerActionInvoker.<InvokeNextResourceFilter>d__22.MoveNext()
--- End of stack trace from previous location where exception was thrown ---
   at System.Runtime.ExceptionServices.ExceptionDispatchInfo.Throw()
   at Microsoft.AspNetCore.Mvc.Internal.ControllerActionInvoker.Rethrow(ResourceExecutedContext context)
   at Microsoft.AspNetCore.Mvc.Internal.ControllerActionInvoker.Next(State& next, Scope& scope, Object& state, Boolean& isCompleted)
   at Microsoft.AspNetCore.Mvc.Internal.ControllerActionInvoker.<InvokeAsync>d__20.MoveNext()
--- End of stack trace from previous location where exception was thrown ---
   at System.Runtime.ExceptionServices.ExceptionDispatchInfo.Throw()
   at System.Runtime.CompilerServices.TaskAwaiter.HandleNonSuccessAndDebuggerNotification(Task task)
   at Microsoft.AspNetCore.Builder.RouterMiddleware.<Invoke>d__4.MoveNext()
--- End of stack trace from previous location where exception was thrown ---
   at System.Runtime.ExceptionServices.ExceptionDispatchInfo.Throw()
   at System.Runtime.CompilerServices.TaskAwaiter.HandleNonSuccessAndDebuggerNotification(Task task)
   at Microsoft.AspNetCore.SpaServices.Webpack.ConditionalProxyMiddleware.<Invoke>d__5.MoveNext()
--- End of stack trace from previous location where exception was thrown ---
   at System.Runtime.ExceptionServices.ExceptionDispatchInfo.Throw()
   at System.Runtime.CompilerServices.TaskAwaiter.HandleNonSuccessAndDebuggerNotification(Task task)
   at Microsoft.AspNetCore.SpaServices.Webpack.ConditionalProxyMiddleware.<Invoke>d__5.MoveNext()
--- End of stack trace from previous location where exception was thrown ---
   at System.Runtime.ExceptionServices.ExceptionDispatchInfo.Throw()
   at System.Runtime.CompilerServices.TaskAwaiter.HandleNonSuccessAndDebuggerNotification(Task task)
   at Microsoft.AspNetCore.Authentication.AuthenticationMiddleware`1.<Invoke>d__18.MoveNext()
--- End of stack trace from previous location where exception was thrown ---
   at System.Runtime.ExceptionServices.ExceptionDispatchInfo.Throw()
   at Microsoft.AspNetCore.Authentication.AuthenticationMiddleware`1.<Invoke>d__18.MoveNext()
--- End of stack trace from previous location where exception was thrown ---
   at System.Runtime.ExceptionServices.ExceptionDispatchInfo.Throw()
   at System.Runtime.CompilerServices.TaskAwaiter.HandleNonSuccessAndDebuggerNotification(Task task)
   at System.Runtime.CompilerServices.TaskAwaiter.GetResult()
   at FundTrack.WebUI.Middlewares.GlobalErrorHandlingMiddleware.<Invoke>d__4.MoveNext() in C:\FundTrack\FundTrack.WebUI\Middlewares\GlobalErrorHandlingMiddleware.cs:line 28
____________________________________________________________________________________________________________________________________________

Date and time:  30.10.2017 10:11:23
Error message:  An exception has been raised that is likely due to a transient failure. If you are connecting to a SQL Azure database consider using SqlAzureExecutionStrategy.
Source:  Microsoft.EntityFrameworkCore.SqlServer
InnerException:  System.Data.SqlClient.SqlException: A connection was successfully established with the server, but then an error occurred during the login process. (provider: TCP Provider, error: 0 - An existing connection was forcibly closed by the remote host.) ---> System.ComponentModel.Win32Exception: An existing connection was forcibly closed by the remote host
   --- End of inner exception stack trace ---
   at System.Data.SqlClient.SqlInternalConnectionTds..ctor(DbConnectionPoolIdentity identity, SqlConnectionString connectionOptions, Object providerInfo, Boolean redirectedUserInstance, SqlConnectionString userConnectionOptions, SessionData reconnectSessionData, Boolean applyTransientFaultHandling)
   at System.Data.SqlClient.SqlConnectionFactory.CreateConnection(DbConnectionOptions options, DbConnectionPoolKey poolKey, Object poolGroupProviderInfo, DbConnectionPool pool, DbConnection owningConnection, DbConnectionOptions userOptions)
   at System.Data.ProviderBase.DbConnectionFactory.CreatePooledConnection(DbConnectionPool pool, DbConnection owningObject, DbConnectionOptions options, DbConnectionPoolKey poolKey, DbConnectionOptions userOptions)
   at System.Data.ProviderBase.DbConnectionPool.CreateObject(DbConnection owningObject, DbConnectionOptions userOptions, DbConnectionInternal oldConnection)
   at System.Data.ProviderBase.DbConnectionPool.UserCreateRequest(DbConnection owningObject, DbConnectionOptions userOptions, DbConnectionInternal oldConnection)
   at System.Data.ProviderBase.DbConnectionPool.TryGetConnection(DbConnection owningObject, UInt32 waitForMultipleObjectsTimeout, Boolean allowCreate, Boolean onlyOneCheckConnection, DbConnectionOptions userOptions, DbConnectionInternal& connection)
   at System.Data.ProviderBase.DbConnectionPool.TryGetConnection(DbConnection owningObject, TaskCompletionSource`1 retry, DbConnectionOptions userOptions, DbConnectionInternal& connection)
   at System.Data.ProviderBase.DbConnectionFactory.TryGetConnection(DbConnection owningConnection, TaskCompletionSource`1 retry, DbConnectionOptions userOptions, DbConnectionInternal oldConnection, DbConnectionInternal& connection)
   at System.Data.ProviderBase.DbConnectionInternal.TryOpenConnectionInternal(DbConnection outerConnection, DbConnectionFactory connectionFactory, TaskCompletionSource`1 retry, DbConnectionOptions userOptions)
   at System.Data.SqlClient.SqlConnection.TryOpen(TaskCompletionSource`1 retry)
   at System.Data.SqlClient.SqlConnection.Open()
   at Microsoft.EntityFrameworkCore.Storage.RelationalConnection.Open()
   at Microsoft.EntityFrameworkCore.Query.Internal.QueryingEnumerable.Enumerator.BufferlessMoveNext(Boolean buffer)
   at Microsoft.EntityFrameworkCore.Storage.Internal.SqlServerExecutionStrategy.Execute[TState,TResult](Func`2 operation, Func`2 verifySucceeded, TState state)
ClientConnectionId:6a0e5b78-b352-4c9d-8f46-beaadd08035c
Error Number:10054,State:0,Class:20
StackTrace:     at Microsoft.EntityFrameworkCore.Storage.Internal.SqlServerExecutionStrategy.Execute[TState,TResult](Func`2 operation, Func`2 verifySucceeded, TState state)
   at Microsoft.EntityFrameworkCore.Query.QueryMethodProvider.<_ShapedQuery>d__3`1.MoveNext()
   at Microsoft.EntityFrameworkCore.Query.QueryMethodProvider.<_Include>d__30`1.MoveNext()
   at System.Linq.Enumerable.FirstOrDefault[TSource](IEnumerable`1 source)
   at lambda_method(Closure , QueryContext )
   at Microsoft.EntityFrameworkCore.Query.Internal.QueryCompiler.<>c__DisplayClass20_0`1.<CompileQueryCore>b__0(QueryContext qc)
   at System.Linq.Queryable.FirstOrDefault[TSource](IQueryable`1 source, Expression`1 predicate)
   at FundTrack.DAL.Concrete.OrganizationAccountRepository.GetOrgAccountById(Int32 orgAccountId) in C:\FundTrack\FundTrack.DAL\Concrete\OrganizationAccountRepository.cs:line 106
   at FundTrack.BLL.Concrete.OrganizationAccountService.IsDonationConnected(Int32 orgAccountId) in C:\FundTrack\FundTrack.BLL\Concrete\OrganizationAccountService.cs:line 316
   at FundTrack.WebUI.Controllers.OrgAccountController.GetDonationStatus(Int32 orgAccountId) in C:\FundTrack\FundTrack.WebUI\Controllers\OrgAccountController.cs:line 70
   at lambda_method(Closure , Object , Object[] )
   at Microsoft.AspNetCore.Mvc.Internal.ControllerActionInvoker.<InvokeActionMethodAsync>d__27.MoveNext()
--- End of stack trace from previous location where exception was thrown ---
   at System.Runtime.ExceptionServices.ExceptionDispatchInfo.Throw()
   at System.Runtime.CompilerServices.TaskAwaiter.HandleNonSuccessAndDebuggerNotification(Task task)
   at Microsoft.AspNetCore.Mvc.Internal.ControllerActionInvoker.<InvokeNextActionFilterAsync>d__25.MoveNext()
--- End of stack trace from previous location where exception was thrown ---
   at System.Runtime.ExceptionServices.ExceptionDispatchInfo.Throw()
   at Microsoft.AspNetCore.Mvc.Internal.ControllerActionInvoker.Rethrow(ActionExecutedContext context)
   at Microsoft.AspNetCore.Mvc.Internal.ControllerActionInvoker.Next(State& next, Scope& scope, Object& state, Boolean& isCompleted)
   at Microsoft.AspNetCore.Mvc.Internal.ControllerActionInvoker.<InvokeNextResourceFilter>d__22.MoveNext()
--- End of stack trace from previous location where exception was thrown ---
   at System.Runtime.ExceptionServices.ExceptionDispatchInfo.Throw()
   at Microsoft.AspNetCore.Mvc.Internal.ControllerActionInvoker.Rethrow(ResourceExecutedContext context)
   at Microsoft.AspNetCore.Mvc.Internal.ControllerActionInvoker.Next(State& next, Scope& scope, Object& state, Boolean& isCompleted)
   at Microsoft.AspNetCore.Mvc.Internal.ControllerActionInvoker.<InvokeAsync>d__20.MoveNext()
--- End of stack trace from previous location where exception was thrown ---
   at System.Runtime.ExceptionServices.ExceptionDispatchInfo.Throw()
   at System.Runtime.CompilerServices.TaskAwaiter.HandleNonSuccessAndDebuggerNotification(Task task)
   at Microsoft.AspNetCore.Builder.RouterMiddleware.<Invoke>d__4.MoveNext()
--- End of stack trace from previous location where exception was thrown ---
   at System.Runtime.ExceptionServices.ExceptionDispatchInfo.Throw()
   at System.Runtime.CompilerServices.TaskAwaiter.HandleNonSuccessAndDebuggerNotification(Task task)
   at Microsoft.AspNetCore.SpaServices.Webpack.ConditionalProxyMiddleware.<Invoke>d__5.MoveNext()
--- End of stack trace from previous location where exception was thrown ---
   at System.Runtime.ExceptionServices.ExceptionDispatchInfo.Throw()
   at System.Runtime.CompilerServices.TaskAwaiter.HandleNonSuccessAndDebuggerNotification(Task task)
   at Microsoft.AspNetCore.SpaServices.Webpack.ConditionalProxyMiddleware.<Invoke>d__5.MoveNext()
--- End of stack trace from previous location where exception was thrown ---
   at System.Runtime.ExceptionServices.ExceptionDispatchInfo.Throw()
   at System.Runtime.CompilerServices.TaskAwaiter.HandleNonSuccessAndDebuggerNotification(Task task)
   at Microsoft.AspNetCore.Authentication.AuthenticationMiddleware`1.<Invoke>d__18.MoveNext()
--- End of stack trace from previous location where exception was thrown ---
   at System.Runtime.ExceptionServices.ExceptionDispatchInfo.Throw()
   at Microsoft.AspNetCore.Authentication.AuthenticationMiddleware`1.<Invoke>d__18.MoveNext()
--- End of stack trace from previous location where exception was thrown ---
   at System.Runtime.ExceptionServices.ExceptionDispatchInfo.Throw()
   at System.Runtime.CompilerServices.TaskAwaiter.HandleNonSuccessAndDebuggerNotification(Task task)
   at System.Runtime.CompilerServices.TaskAwaiter.GetResult()
   at FundTrack.WebUI.Middlewares.GlobalErrorHandlingMiddleware.<Invoke>d__4.MoveNext() in C:\FundTrack\FundTrack.WebUI\Middlewares\GlobalErrorHandlingMiddleware.cs:line 28
____________________________________________________________________________________________________________________________________________

Date and time:  30.10.2017 10:11:34
Error message:  Список фінансових операцій порожній
Source:  FundTrack.BLL
InnerException:  FundTrack.BLL.Concrete.BusinessLogicException: Список фінансових операцій порожній ---> System.InvalidOperationException: An exception has been raised that is likely due to a transient failure. If you are connecting to a SQL Azure database consider using SqlAzureExecutionStrategy. ---> System.Data.SqlClient.SqlException: A connection was successfully established with the server, but then an error occurred during the login process. (provider: TCP Provider, error: 0 - An existing connection was forcibly closed by the remote host.) ---> System.ComponentModel.Win32Exception: An existing connection was forcibly closed by the remote host
   --- End of inner exception stack trace ---
   at System.Data.ProviderBase.DbConnectionPool.TryGetConnection(DbConnection owningObject, UInt32 waitForMultipleObjectsTimeout, Boolean allowCreate, Boolean onlyOneCheckConnection, DbConnectionOptions userOptions, DbConnectionInternal& connection)
   at System.Data.ProviderBase.DbConnectionPool.TryGetConnection(DbConnection owningObject, TaskCompletionSource`1 retry, DbConnectionOptions userOptions, DbConnectionInternal& connection)
   at System.Data.ProviderBase.DbConnectionFactory.TryGetConnection(DbConnection owningConnection, TaskCompletionSource`1 retry, DbConnectionOptions userOptions, DbConnectionInternal oldConnection, DbConnectionInternal& connection)
   at System.Data.ProviderBase.DbConnectionInternal.TryOpenConnectionInternal(DbConnection outerConnection, DbConnectionFactory connectionFactory, TaskCompletionSource`1 retry, DbConnectionOptions userOptions)
   at System.Data.SqlClient.SqlConnection.TryOpen(TaskCompletionSource`1 retry)
   at System.Data.SqlClient.SqlConnection.Open()
   at Microsoft.EntityFrameworkCore.Storage.RelationalConnection.Open()
   at Microsoft.EntityFrameworkCore.Query.Internal.QueryingEnumerable.Enumerator.BufferlessMoveNext(Boolean buffer)
   at Microsoft.EntityFrameworkCore.Storage.Internal.SqlServerExecutionStrategy.Execute[TState,TResult](Func`2 operation, Func`2 verifySucceeded, TState state)
   --- End of inner exception stack trace ---
   at Microsoft.EntityFrameworkCore.Storage.Internal.SqlServerExecutionStrategy.Execute[TState,TResult](Func`2 operation, Func`2 verifySucceeded, TState state)
   at Microsoft.EntityFrameworkCore.Query.QueryMethodProvider.<_ShapedQuery>d__3`1.MoveNext()
   at System.Linq.Enumerable.SelectEnumerableIterator`2.MoveNext()
   at Microsoft.EntityFrameworkCore.Query.Internal.LinqOperatorProvider.ExceptionInterceptor`1.EnumeratorExceptionInterceptor.MoveNext()
   at System.Collections.Generic.List`1..ctor(IEnumerable`1 collection)
   at System.Linq.Enumerable.ToList[TSource](IEnumerable`1 source)
   at FundTrack.BLL.Concrete.FinOpService.SetIsEditableField(IEnumerable`1 finOps) in C:\FundTrack\FundTrack.BLL\Concrete\FinOpService.cs:line 256
   at FundTrack.BLL.Concrete.FinOpService.InitializeFinOps(IQueryable`1 finOps) in C:\FundTrack\FundTrack.BLL\Concrete\FinOpService.cs:line 243
   --- End of inner exception stack trace ---
   at FundTrack.BLL.Concrete.FinOpService.InitializeFinOps(IQueryable`1 finOps) in C:\FundTrack\FundTrack.BLL\Concrete\FinOpService.cs:line 248
   at FundTrack.BLL.Concrete.FinOpService.GetFinOpByOrgAccountIdForPage(Int32 orgAccountId, Int32 currentPage, Int32 itemsPerPage, Int32 finOpType) in C:\FundTrack\FundTrack.BLL\Concrete\FinOpService.cs:line 209
StackTrace:     at FundTrack.BLL.Concrete.FinOpService.GetFinOpByOrgAccountIdForPage(Int32 orgAccountId, Int32 currentPage, Int32 itemsPerPage, Int32 finOpType) in C:\FundTrack\FundTrack.BLL\Concrete\FinOpService.cs:line 219
   at FundTrack.WebUI.Controllers.FinOpController.GetFinOpsByIdForPage(Int32 accountId, Int32 currentPage, Int32 pageSize, Int32 finOpType) in C:\FundTrack\FundTrack.WebUI\Controllers\FinOpController.cs:line 88
   at lambda_method(Closure , Object , Object[] )
   at Microsoft.AspNetCore.Mvc.Internal.ControllerActionInvoker.<InvokeActionMethodAsync>d__27.MoveNext()
--- End of stack trace from previous location where exception was thrown ---
   at System.Runtime.ExceptionServices.ExceptionDispatchInfo.Throw()
   at System.Runtime.CompilerServices.TaskAwaiter.HandleNonSuccessAndDebuggerNotification(Task task)
   at Microsoft.AspNetCore.Mvc.Internal.ControllerActionInvoker.<InvokeNextActionFilterAsync>d__25.MoveNext()
--- End of stack trace from previous location where exception was thrown ---
   at System.Runtime.ExceptionServices.ExceptionDispatchInfo.Throw()
   at Microsoft.AspNetCore.Mvc.Internal.ControllerActionInvoker.Rethrow(ActionExecutedContext context)
   at Microsoft.AspNetCore.Mvc.Internal.ControllerActionInvoker.Next(State& next, Scope& scope, Object& state, Boolean& isCompleted)
   at Microsoft.AspNetCore.Mvc.Internal.ControllerActionInvoker.<InvokeNextResourceFilter>d__22.MoveNext()
--- End of stack trace from previous location where exception was thrown ---
   at System.Runtime.ExceptionServices.ExceptionDispatchInfo.Throw()
   at Microsoft.AspNetCore.Mvc.Internal.ControllerActionInvoker.Rethrow(ResourceExecutedContext context)
   at Microsoft.AspNetCore.Mvc.Internal.ControllerActionInvoker.Next(State& next, Scope& scope, Object& state, Boolean& isCompleted)
   at Microsoft.AspNetCore.Mvc.Internal.ControllerActionInvoker.<InvokeAsync>d__20.MoveNext()
--- End of stack trace from previous location where exception was thrown ---
   at System.Runtime.ExceptionServices.ExceptionDispatchInfo.Throw()
   at System.Runtime.CompilerServices.TaskAwaiter.HandleNonSuccessAndDebuggerNotification(Task task)
   at Microsoft.AspNetCore.Builder.RouterMiddleware.<Invoke>d__4.MoveNext()
--- End of stack trace from previous location where exception was thrown ---
   at System.Runtime.ExceptionServices.ExceptionDispatchInfo.Throw()
   at System.Runtime.CompilerServices.TaskAwaiter.HandleNonSuccessAndDebuggerNotification(Task task)
   at Microsoft.AspNetCore.SpaServices.Webpack.ConditionalProxyMiddleware.<Invoke>d__5.MoveNext()
--- End of stack trace from previous location where exception was thrown ---
   at System.Runtime.ExceptionServices.ExceptionDispatchInfo.Throw()
   at System.Runtime.CompilerServices.TaskAwaiter.HandleNonSuccessAndDebuggerNotification(Task task)
   at Microsoft.AspNetCore.SpaServices.Webpack.ConditionalProxyMiddleware.<Invoke>d__5.MoveNext()
--- End of stack trace from previous location where exception was thrown ---
   at System.Runtime.ExceptionServices.ExceptionDispatchInfo.Throw()
   at System.Runtime.CompilerServices.TaskAwaiter.HandleNonSuccessAndDebuggerNotification(Task task)
   at Microsoft.AspNetCore.Authentication.AuthenticationMiddleware`1.<Invoke>d__18.MoveNext()
--- End of stack trace from previous location where exception was thrown ---
   at System.Runtime.ExceptionServices.ExceptionDispatchInfo.Throw()
   at Microsoft.AspNetCore.Authentication.AuthenticationMiddleware`1.<Invoke>d__18.MoveNext()
--- End of stack trace from previous location where exception was thrown ---
   at System.Runtime.ExceptionServices.ExceptionDispatchInfo.Throw()
   at System.Runtime.CompilerServices.TaskAwaiter.HandleNonSuccessAndDebuggerNotification(Task task)
   at System.Runtime.CompilerServices.TaskAwaiter.GetResult()
   at FundTrack.WebUI.Middlewares.GlobalErrorHandlingMiddleware.<Invoke>d__4.MoveNext() in C:\FundTrack\FundTrack.WebUI\Middlewares\GlobalErrorHandlingMiddleware.cs:line 28
____________________________________________________________________________________________________________________________________________

Date and time:  30.10.2017 12:39:47
Error message:  Список фінансових операцій порожній
Source:  FundTrack.BLL
InnerException:  FundTrack.BLL.Concrete.BusinessLogicException: Список фінансових операцій порожній ---> System.NullReferenceException: Object reference not set to an instance of an object.
   at FundTrack.BLL.Concrete.FinOpService.<>c.<InitializeFinOps>b__10_0(FinOp f) in C:\FundTrack\FundTrack.BLL\Concrete\FinOpService.cs:line 228
   at System.Linq.Enumerable.SelectListIterator`2.ToList()
   at System.Linq.Enumerable.ToList[TSource](IEnumerable`1 source)
   at FundTrack.BLL.Concrete.FinOpService.SetIsEditableField(IEnumerable`1 finOps) in C:\FundTrack\FundTrack.BLL\Concrete\FinOpService.cs:line 258
   at FundTrack.BLL.Concrete.FinOpService.InitializeFinOps(IEnumerable`1 finOps) in C:\FundTrack\FundTrack.BLL\Concrete\FinOpService.cs:line 245
   --- End of inner exception stack trace ---
   at FundTrack.BLL.Concrete.FinOpService.InitializeFinOps(IEnumerable`1 finOps) in C:\FundTrack\FundTrack.BLL\Concrete\FinOpService.cs:line 250
   at FundTrack.BLL.Concrete.FinOpService.GetFinOpByOrgAccountIdForPage(Int32 orgAccountId, Int32 currentPage, Int32 itemsPerPage, Int32 finOpType) in C:\FundTrack\FundTrack.BLL\Concrete\FinOpService.cs:line 209
StackTrace:     at FundTrack.BLL.Concrete.FinOpService.GetFinOpByOrgAccountIdForPage(Int32 orgAccountId, Int32 currentPage, Int32 itemsPerPage, Int32 finOpType) in C:\FundTrack\FundTrack.BLL\Concrete\FinOpService.cs:line 219
   at FundTrack.WebUI.Controllers.FinOpController.GetFinOpsByIdForPage(Int32 accountId, Int32 currentPage, Int32 pageSize, Int32 finOpType) in C:\FundTrack\FundTrack.WebUI\Controllers\FinOpController.cs:line 88
   at lambda_method(Closure , Object , Object[] )
   at Microsoft.AspNetCore.Mvc.Internal.ControllerActionInvoker.<InvokeActionMethodAsync>d__27.MoveNext()
--- End of stack trace from previous location where exception was thrown ---
   at System.Runtime.ExceptionServices.ExceptionDispatchInfo.Throw()
   at System.Runtime.CompilerServices.TaskAwaiter.HandleNonSuccessAndDebuggerNotification(Task task)
   at Microsoft.AspNetCore.Mvc.Internal.ControllerActionInvoker.<InvokeNextActionFilterAsync>d__25.MoveNext()
--- End of stack trace from previous location where exception was thrown ---
   at System.Runtime.ExceptionServices.ExceptionDispatchInfo.Throw()
   at Microsoft.AspNetCore.Mvc.Internal.ControllerActionInvoker.Rethrow(ActionExecutedContext context)
   at Microsoft.AspNetCore.Mvc.Internal.ControllerActionInvoker.Next(State& next, Scope& scope, Object& state, Boolean& isCompleted)
   at Microsoft.AspNetCore.Mvc.Internal.ControllerActionInvoker.<InvokeNextResourceFilter>d__22.MoveNext()
--- End of stack trace from previous location where exception was thrown ---
   at System.Runtime.ExceptionServices.ExceptionDispatchInfo.Throw()
   at Microsoft.AspNetCore.Mvc.Internal.ControllerActionInvoker.Rethrow(ResourceExecutedContext context)
   at Microsoft.AspNetCore.Mvc.Internal.ControllerActionInvoker.Next(State& next, Scope& scope, Object& state, Boolean& isCompleted)
   at Microsoft.AspNetCore.Mvc.Internal.ControllerActionInvoker.<InvokeAsync>d__20.MoveNext()
--- End of stack trace from previous location where exception was thrown ---
   at System.Runtime.ExceptionServices.ExceptionDispatchInfo.Throw()
   at System.Runtime.CompilerServices.TaskAwaiter.HandleNonSuccessAndDebuggerNotification(Task task)
   at Microsoft.AspNetCore.Builder.RouterMiddleware.<Invoke>d__4.MoveNext()
--- End of stack trace from previous location where exception was thrown ---
   at System.Runtime.ExceptionServices.ExceptionDispatchInfo.Throw()
   at System.Runtime.CompilerServices.TaskAwaiter.HandleNonSuccessAndDebuggerNotification(Task task)
   at Microsoft.AspNetCore.SpaServices.Webpack.ConditionalProxyMiddleware.<Invoke>d__5.MoveNext()
--- End of stack trace from previous location where exception was thrown ---
   at System.Runtime.ExceptionServices.ExceptionDispatchInfo.Throw()
   at System.Runtime.CompilerServices.TaskAwaiter.HandleNonSuccessAndDebuggerNotification(Task task)
   at Microsoft.AspNetCore.SpaServices.Webpack.ConditionalProxyMiddleware.<Invoke>d__5.MoveNext()
--- End of stack trace from previous location where exception was thrown ---
   at System.Runtime.ExceptionServices.ExceptionDispatchInfo.Throw()
   at System.Runtime.CompilerServices.TaskAwaiter.HandleNonSuccessAndDebuggerNotification(Task task)
   at Microsoft.AspNetCore.Authentication.AuthenticationMiddleware`1.<Invoke>d__18.MoveNext()
--- End of stack trace from previous location where exception was thrown ---
   at System.Runtime.ExceptionServices.ExceptionDispatchInfo.Throw()
   at Microsoft.AspNetCore.Authentication.AuthenticationMiddleware`1.<Invoke>d__18.MoveNext()
--- End of stack trace from previous location where exception was thrown ---
   at System.Runtime.ExceptionServices.ExceptionDispatchInfo.Throw()
   at System.Runtime.CompilerServices.TaskAwaiter.HandleNonSuccessAndDebuggerNotification(Task task)
   at System.Runtime.CompilerServices.TaskAwaiter.GetResult()
   at FundTrack.WebUI.Middlewares.GlobalErrorHandlingMiddleware.<Invoke>d__4.MoveNext() in C:\FundTrack\FundTrack.WebUI\Middlewares\GlobalErrorHandlingMiddleware.cs:line 28
____________________________________________________________________________________________________________________________________________

Date and time:  30.10.2017 12:40:21
Error message:  Список фінансових операцій порожній
Source:  FundTrack.BLL
InnerException:  FundTrack.BLL.Concrete.BusinessLogicException: Список фінансових операцій порожній ---> System.NullReferenceException: Object reference not set to an instance of an object.
   at FundTrack.BLL.Concrete.FinOpService.<>c.<InitializeFinOps>b__10_0(FinOp f) in C:\FundTrack\FundTrack.BLL\Concrete\FinOpService.cs:line 228
   at System.Linq.Enumerable.SelectListIterator`2.ToList()
   at System.Linq.Enumerable.ToList[TSource](IEnumerable`1 source)
   at FundTrack.BLL.Concrete.FinOpService.SetIsEditableField(IEnumerable`1 finOps) in C:\FundTrack\FundTrack.BLL\Concrete\FinOpService.cs:line 258
   at FundTrack.BLL.Concrete.FinOpService.InitializeFinOps(IEnumerable`1 finOps) in C:\FundTrack\FundTrack.BLL\Concrete\FinOpService.cs:line 245
   --- End of inner exception stack trace ---
   at FundTrack.BLL.Concrete.FinOpService.InitializeFinOps(IEnumerable`1 finOps) in C:\FundTrack\FundTrack.BLL\Concrete\FinOpService.cs:line 250
   at FundTrack.BLL.Concrete.FinOpService.GetFinOpByOrgAccountIdForPage(Int32 orgAccountId, Int32 currentPage, Int32 itemsPerPage, Int32 finOpType) in C:\FundTrack\FundTrack.BLL\Concrete\FinOpService.cs:line 209
StackTrace:     at FundTrack.BLL.Concrete.FinOpService.GetFinOpByOrgAccountIdForPage(Int32 orgAccountId, Int32 currentPage, Int32 itemsPerPage, Int32 finOpType) in C:\FundTrack\FundTrack.BLL\Concrete\FinOpService.cs:line 219
   at FundTrack.WebUI.Controllers.FinOpController.GetFinOpsByIdForPage(Int32 accountId, Int32 currentPage, Int32 pageSize, Int32 finOpType) in C:\FundTrack\FundTrack.WebUI\Controllers\FinOpController.cs:line 88
   at lambda_method(Closure , Object , Object[] )
   at Microsoft.AspNetCore.Mvc.Internal.ControllerActionInvoker.<InvokeActionMethodAsync>d__27.MoveNext()
--- End of stack trace from previous location where exception was thrown ---
   at System.Runtime.ExceptionServices.ExceptionDispatchInfo.Throw()
   at System.Runtime.CompilerServices.TaskAwaiter.HandleNonSuccessAndDebuggerNotification(Task task)
   at Microsoft.AspNetCore.Mvc.Internal.ControllerActionInvoker.<InvokeNextActionFilterAsync>d__25.MoveNext()
--- End of stack trace from previous location where exception was thrown ---
   at System.Runtime.ExceptionServices.ExceptionDispatchInfo.Throw()
   at Microsoft.AspNetCore.Mvc.Internal.ControllerActionInvoker.Rethrow(ActionExecutedContext context)
   at Microsoft.AspNetCore.Mvc.Internal.ControllerActionInvoker.Next(State& next, Scope& scope, Object& state, Boolean& isCompleted)
   at Microsoft.AspNetCore.Mvc.Internal.ControllerActionInvoker.<InvokeNextResourceFilter>d__22.MoveNext()
--- End of stack trace from previous location where exception was thrown ---
   at System.Runtime.ExceptionServices.ExceptionDispatchInfo.Throw()
   at Microsoft.AspNetCore.Mvc.Internal.ControllerActionInvoker.Rethrow(ResourceExecutedContext context)
   at Microsoft.AspNetCore.Mvc.Internal.ControllerActionInvoker.Next(State& next, Scope& scope, Object& state, Boolean& isCompleted)
   at Microsoft.AspNetCore.Mvc.Internal.ControllerActionInvoker.<InvokeAsync>d__20.MoveNext()
--- End of stack trace from previous location where exception was thrown ---
   at System.Runtime.ExceptionServices.ExceptionDispatchInfo.Throw()
   at System.Runtime.CompilerServices.TaskAwaiter.HandleNonSuccessAndDebuggerNotification(Task task)
   at Microsoft.AspNetCore.Builder.RouterMiddleware.<Invoke>d__4.MoveNext()
--- End of stack trace from previous location where exception was thrown ---
   at System.Runtime.ExceptionServices.ExceptionDispatchInfo.Throw()
   at System.Runtime.CompilerServices.TaskAwaiter.HandleNonSuccessAndDebuggerNotification(Task task)
   at Microsoft.AspNetCore.SpaServices.Webpack.ConditionalProxyMiddleware.<Invoke>d__5.MoveNext()
--- End of stack trace from previous location where exception was thrown ---
   at System.Runtime.ExceptionServices.ExceptionDispatchInfo.Throw()
   at System.Runtime.CompilerServices.TaskAwaiter.HandleNonSuccessAndDebuggerNotification(Task task)
   at Microsoft.AspNetCore.SpaServices.Webpack.ConditionalProxyMiddleware.<Invoke>d__5.MoveNext()
--- End of stack trace from previous location where exception was thrown ---
   at System.Runtime.ExceptionServices.ExceptionDispatchInfo.Throw()
   at System.Runtime.CompilerServices.TaskAwaiter.HandleNonSuccessAndDebuggerNotification(Task task)
   at Microsoft.AspNetCore.Authentication.AuthenticationMiddleware`1.<Invoke>d__18.MoveNext()
--- End of stack trace from previous location where exception was thrown ---
   at System.Runtime.ExceptionServices.ExceptionDispatchInfo.Throw()
   at Microsoft.AspNetCore.Authentication.AuthenticationMiddleware`1.<Invoke>d__18.MoveNext()
--- End of stack trace from previous location where exception was thrown ---
   at System.Runtime.ExceptionServices.ExceptionDispatchInfo.Throw()
   at System.Runtime.CompilerServices.TaskAwaiter.HandleNonSuccessAndDebuggerNotification(Task task)
   at System.Runtime.CompilerServices.TaskAwaiter.GetResult()
   at FundTrack.WebUI.Middlewares.GlobalErrorHandlingMiddleware.<Invoke>d__4.MoveNext() in C:\FundTrack\FundTrack.WebUI\Middlewares\GlobalErrorHandlingMiddleware.cs:line 28
____________________________________________________________________________________________________________________________________________

Date and time:  30.10.2017 12:40:50
Error message:  Список фінансових операцій порожній
Source:  FundTrack.BLL
InnerException:  FundTrack.BLL.Concrete.BusinessLogicException: Список фінансових операцій порожній ---> System.NullReferenceException: Object reference not set to an instance of an object.
   at FundTrack.BLL.Concrete.FinOpService.<>c.<InitializeFinOps>b__10_0(FinOp f) in C:\FundTrack\FundTrack.BLL\Concrete\FinOpService.cs:line 228
   at System.Linq.Enumerable.SelectListIterator`2.ToList()
   at System.Linq.Enumerable.ToList[TSource](IEnumerable`1 source)
   at FundTrack.BLL.Concrete.FinOpService.SetIsEditableField(IEnumerable`1 finOps) in C:\FundTrack\FundTrack.BLL\Concrete\FinOpService.cs:line 258
   at FundTrack.BLL.Concrete.FinOpService.InitializeFinOps(IEnumerable`1 finOps) in C:\FundTrack\FundTrack.BLL\Concrete\FinOpService.cs:line 245
   --- End of inner exception stack trace ---
   at FundTrack.BLL.Concrete.FinOpService.InitializeFinOps(IEnumerable`1 finOps) in C:\FundTrack\FundTrack.BLL\Concrete\FinOpService.cs:line 250
   at FundTrack.BLL.Concrete.FinOpService.GetFinOpByOrgAccountIdForPage(Int32 orgAccountId, Int32 currentPage, Int32 itemsPerPage, Int32 finOpType) in C:\FundTrack\FundTrack.BLL\Concrete\FinOpService.cs:line 209
StackTrace:     at FundTrack.BLL.Concrete.FinOpService.GetFinOpByOrgAccountIdForPage(Int32 orgAccountId, Int32 currentPage, Int32 itemsPerPage, Int32 finOpType) in C:\FundTrack\FundTrack.BLL\Concrete\FinOpService.cs:line 219
   at FundTrack.WebUI.Controllers.FinOpController.GetFinOpsByIdForPage(Int32 accountId, Int32 currentPage, Int32 pageSize, Int32 finOpType) in C:\FundTrack\FundTrack.WebUI\Controllers\FinOpController.cs:line 88
   at lambda_method(Closure , Object , Object[] )
   at Microsoft.AspNetCore.Mvc.Internal.ControllerActionInvoker.<InvokeActionMethodAsync>d__27.MoveNext()
--- End of stack trace from previous location where exception was thrown ---
   at System.Runtime.ExceptionServices.ExceptionDispatchInfo.Throw()
   at System.Runtime.CompilerServices.TaskAwaiter.HandleNonSuccessAndDebuggerNotification(Task task)
   at Microsoft.AspNetCore.Mvc.Internal.ControllerActionInvoker.<InvokeNextActionFilterAsync>d__25.MoveNext()
--- End of stack trace from previous location where exception was thrown ---
   at System.Runtime.ExceptionServices.ExceptionDispatchInfo.Throw()
   at Microsoft.AspNetCore.Mvc.Internal.ControllerActionInvoker.Rethrow(ActionExecutedContext context)
   at Microsoft.AspNetCore.Mvc.Internal.ControllerActionInvoker.Next(State& next, Scope& scope, Object& state, Boolean& isCompleted)
   at Microsoft.AspNetCore.Mvc.Internal.ControllerActionInvoker.<InvokeNextResourceFilter>d__22.MoveNext()
--- End of stack trace from previous location where exception was thrown ---
   at System.Runtime.ExceptionServices.ExceptionDispatchInfo.Throw()
   at Microsoft.AspNetCore.Mvc.Internal.ControllerActionInvoker.Rethrow(ResourceExecutedContext context)
   at Microsoft.AspNetCore.Mvc.Internal.ControllerActionInvoker.Next(State& next, Scope& scope, Object& state, Boolean& isCompleted)
   at Microsoft.AspNetCore.Mvc.Internal.ControllerActionInvoker.<InvokeAsync>d__20.MoveNext()
--- End of stack trace from previous location where exception was thrown ---
   at System.Runtime.ExceptionServices.ExceptionDispatchInfo.Throw()
   at System.Runtime.CompilerServices.TaskAwaiter.HandleNonSuccessAndDebuggerNotification(Task task)
   at Microsoft.AspNetCore.Builder.RouterMiddleware.<Invoke>d__4.MoveNext()
--- End of stack trace from previous location where exception was thrown ---
   at System.Runtime.ExceptionServices.ExceptionDispatchInfo.Throw()
   at System.Runtime.CompilerServices.TaskAwaiter.HandleNonSuccessAndDebuggerNotification(Task task)
   at Microsoft.AspNetCore.SpaServices.Webpack.ConditionalProxyMiddleware.<Invoke>d__5.MoveNext()
--- End of stack trace from previous location where exception was thrown ---
   at System.Runtime.ExceptionServices.ExceptionDispatchInfo.Throw()
   at System.Runtime.CompilerServices.TaskAwaiter.HandleNonSuccessAndDebuggerNotification(Task task)
   at Microsoft.AspNetCore.SpaServices.Webpack.ConditionalProxyMiddleware.<Invoke>d__5.MoveNext()
--- End of stack trace from previous location where exception was thrown ---
   at System.Runtime.ExceptionServices.ExceptionDispatchInfo.Throw()
   at System.Runtime.CompilerServices.TaskAwaiter.HandleNonSuccessAndDebuggerNotification(Task task)
   at Microsoft.AspNetCore.Authentication.AuthenticationMiddleware`1.<Invoke>d__18.MoveNext()
--- End of stack trace from previous location where exception was thrown ---
   at System.Runtime.ExceptionServices.ExceptionDispatchInfo.Throw()
   at Microsoft.AspNetCore.Authentication.AuthenticationMiddleware`1.<Invoke>d__18.MoveNext()
--- End of stack trace from previous location where exception was thrown ---
   at System.Runtime.ExceptionServices.ExceptionDispatchInfo.Throw()
   at System.Runtime.CompilerServices.TaskAwaiter.HandleNonSuccessAndDebuggerNotification(Task task)
   at System.Runtime.CompilerServices.TaskAwaiter.GetResult()
   at FundTrack.WebUI.Middlewares.GlobalErrorHandlingMiddleware.<Invoke>d__4.MoveNext() in C:\FundTrack\FundTrack.WebUI\Middlewares\GlobalErrorHandlingMiddleware.cs:line 28
____________________________________________________________________________________________________________________________________________

Date and time:  30.10.2017 12:40:56
Error message:  Список фінансових операцій порожній
Source:  FundTrack.BLL
InnerException:  FundTrack.BLL.Concrete.BusinessLogicException: Список фінансових операцій порожній ---> System.NullReferenceException: Object reference not set to an instance of an object.
   at FundTrack.BLL.Concrete.FinOpService.<>c.<InitializeFinOps>b__10_0(FinOp f) in C:\FundTrack\FundTrack.BLL\Concrete\FinOpService.cs:line 228
   at System.Linq.Enumerable.SelectListIterator`2.ToList()
   at System.Linq.Enumerable.ToList[TSource](IEnumerable`1 source)
   at FundTrack.BLL.Concrete.FinOpService.SetIsEditableField(IEnumerable`1 finOps) in C:\FundTrack\FundTrack.BLL\Concrete\FinOpService.cs:line 258
   at FundTrack.BLL.Concrete.FinOpService.InitializeFinOps(IEnumerable`1 finOps) in C:\FundTrack\FundTrack.BLL\Concrete\FinOpService.cs:line 245
   --- End of inner exception stack trace ---
   at FundTrack.BLL.Concrete.FinOpService.InitializeFinOps(IEnumerable`1 finOps) in C:\FundTrack\FundTrack.BLL\Concrete\FinOpService.cs:line 250
   at FundTrack.BLL.Concrete.FinOpService.GetFinOpByOrgAccountIdForPage(Int32 orgAccountId, Int32 currentPage, Int32 itemsPerPage, Int32 finOpType) in C:\FundTrack\FundTrack.BLL\Concrete\FinOpService.cs:line 209
StackTrace:     at FundTrack.BLL.Concrete.FinOpService.GetFinOpByOrgAccountIdForPage(Int32 orgAccountId, Int32 currentPage, Int32 itemsPerPage, Int32 finOpType) in C:\FundTrack\FundTrack.BLL\Concrete\FinOpService.cs:line 219
   at FundTrack.WebUI.Controllers.FinOpController.GetFinOpsByIdForPage(Int32 accountId, Int32 currentPage, Int32 pageSize, Int32 finOpType) in C:\FundTrack\FundTrack.WebUI\Controllers\FinOpController.cs:line 88
   at lambda_method(Closure , Object , Object[] )
   at Microsoft.AspNetCore.Mvc.Internal.ControllerActionInvoker.<InvokeActionMethodAsync>d__27.MoveNext()
--- End of stack trace from previous location where exception was thrown ---
   at System.Runtime.ExceptionServices.ExceptionDispatchInfo.Throw()
   at System.Runtime.CompilerServices.TaskAwaiter.HandleNonSuccessAndDebuggerNotification(Task task)
   at Microsoft.AspNetCore.Mvc.Internal.ControllerActionInvoker.<InvokeNextActionFilterAsync>d__25.MoveNext()
--- End of stack trace from previous location where exception was thrown ---
   at System.Runtime.ExceptionServices.ExceptionDispatchInfo.Throw()
   at Microsoft.AspNetCore.Mvc.Internal.ControllerActionInvoker.Rethrow(ActionExecutedContext context)
   at Microsoft.AspNetCore.Mvc.Internal.ControllerActionInvoker.Next(State& next, Scope& scope, Object& state, Boolean& isCompleted)
   at Microsoft.AspNetCore.Mvc.Internal.ControllerActionInvoker.<InvokeNextResourceFilter>d__22.MoveNext()
--- End of stack trace from previous location where exception was thrown ---
   at System.Runtime.ExceptionServices.ExceptionDispatchInfo.Throw()
   at Microsoft.AspNetCore.Mvc.Internal.ControllerActionInvoker.Rethrow(ResourceExecutedContext context)
   at Microsoft.AspNetCore.Mvc.Internal.ControllerActionInvoker.Next(State& next, Scope& scope, Object& state, Boolean& isCompleted)
   at Microsoft.AspNetCore.Mvc.Internal.ControllerActionInvoker.<InvokeAsync>d__20.MoveNext()
--- End of stack trace from previous location where exception was thrown ---
   at System.Runtime.ExceptionServices.ExceptionDispatchInfo.Throw()
   at System.Runtime.CompilerServices.TaskAwaiter.HandleNonSuccessAndDebuggerNotification(Task task)
   at Microsoft.AspNetCore.Builder.RouterMiddleware.<Invoke>d__4.MoveNext()
--- End of stack trace from previous location where exception was thrown ---
   at System.Runtime.ExceptionServices.ExceptionDispatchInfo.Throw()
   at System.Runtime.CompilerServices.TaskAwaiter.HandleNonSuccessAndDebuggerNotification(Task task)
   at Microsoft.AspNetCore.SpaServices.Webpack.ConditionalProxyMiddleware.<Invoke>d__5.MoveNext()
--- End of stack trace from previous location where exception was thrown ---
   at System.Runtime.ExceptionServices.ExceptionDispatchInfo.Throw()
   at System.Runtime.CompilerServices.TaskAwaiter.HandleNonSuccessAndDebuggerNotification(Task task)
   at Microsoft.AspNetCore.SpaServices.Webpack.ConditionalProxyMiddleware.<Invoke>d__5.MoveNext()
--- End of stack trace from previous location where exception was thrown ---
   at System.Runtime.ExceptionServices.ExceptionDispatchInfo.Throw()
   at System.Runtime.CompilerServices.TaskAwaiter.HandleNonSuccessAndDebuggerNotification(Task task)
   at Microsoft.AspNetCore.Authentication.AuthenticationMiddleware`1.<Invoke>d__18.MoveNext()
--- End of stack trace from previous location where exception was thrown ---
   at System.Runtime.ExceptionServices.ExceptionDispatchInfo.Throw()
   at Microsoft.AspNetCore.Authentication.AuthenticationMiddleware`1.<Invoke>d__18.MoveNext()
--- End of stack trace from previous location where exception was thrown ---
   at System.Runtime.ExceptionServices.ExceptionDispatchInfo.Throw()
   at System.Runtime.CompilerServices.TaskAwaiter.HandleNonSuccessAndDebuggerNotification(Task task)
   at System.Runtime.CompilerServices.TaskAwaiter.GetResult()
   at FundTrack.WebUI.Middlewares.GlobalErrorHandlingMiddleware.<Invoke>d__4.MoveNext() in C:\FundTrack\FundTrack.WebUI\Middlewares\GlobalErrorHandlingMiddleware.cs:line 28
____________________________________________________________________________________________________________________________________________

Date and time:  30.10.2017 12:43:03
Error message:  Список фінансових операцій порожній
Source:  FundTrack.BLL
InnerException:  FundTrack.BLL.Concrete.BusinessLogicException: Список фінансових операцій порожній ---> System.NullReferenceException: Object reference not set to an instance of an object.
   at FundTrack.BLL.Concrete.FinOpService.<>c.<InitializeFinOps>b__10_0(FinOp f) in C:\FundTrack\FundTrack.BLL\Concrete\FinOpService.cs:line 228
   at System.Linq.Enumerable.SelectListIterator`2.ToList()
   at System.Linq.Enumerable.ToList[TSource](IEnumerable`1 source)
   at FundTrack.BLL.Concrete.FinOpService.SetIsEditableField(IEnumerable`1 finOps) in C:\FundTrack\FundTrack.BLL\Concrete\FinOpService.cs:line 258
   at FundTrack.BLL.Concrete.FinOpService.InitializeFinOps(IEnumerable`1 finOps) in C:\FundTrack\FundTrack.BLL\Concrete\FinOpService.cs:line 245
   --- End of inner exception stack trace ---
   at FundTrack.BLL.Concrete.FinOpService.InitializeFinOps(IEnumerable`1 finOps) in C:\FundTrack\FundTrack.BLL\Concrete\FinOpService.cs:line 250
   at FundTrack.BLL.Concrete.FinOpService.GetFinOpByOrgAccountIdForPage(Int32 orgAccountId, Int32 currentPage, Int32 itemsPerPage, Int32 finOpType) in C:\FundTrack\FundTrack.BLL\Concrete\FinOpService.cs:line 209
StackTrace:     at FundTrack.BLL.Concrete.FinOpService.GetFinOpByOrgAccountIdForPage(Int32 orgAccountId, Int32 currentPage, Int32 itemsPerPage, Int32 finOpType) in C:\FundTrack\FundTrack.BLL\Concrete\FinOpService.cs:line 219
   at FundTrack.WebUI.Controllers.FinOpController.GetFinOpsByIdForPage(Int32 accountId, Int32 currentPage, Int32 pageSize, Int32 finOpType) in C:\FundTrack\FundTrack.WebUI\Controllers\FinOpController.cs:line 88
   at lambda_method(Closure , Object , Object[] )
   at Microsoft.AspNetCore.Mvc.Internal.ControllerActionInvoker.<InvokeActionMethodAsync>d__27.MoveNext()
--- End of stack trace from previous location where exception was thrown ---
   at System.Runtime.ExceptionServices.ExceptionDispatchInfo.Throw()
   at System.Runtime.CompilerServices.TaskAwaiter.HandleNonSuccessAndDebuggerNotification(Task task)
   at Microsoft.AspNetCore.Mvc.Internal.ControllerActionInvoker.<InvokeNextActionFilterAsync>d__25.MoveNext()
--- End of stack trace from previous location where exception was thrown ---
   at System.Runtime.ExceptionServices.ExceptionDispatchInfo.Throw()
   at Microsoft.AspNetCore.Mvc.Internal.ControllerActionInvoker.Rethrow(ActionExecutedContext context)
   at Microsoft.AspNetCore.Mvc.Internal.ControllerActionInvoker.Next(State& next, Scope& scope, Object& state, Boolean& isCompleted)
   at Microsoft.AspNetCore.Mvc.Internal.ControllerActionInvoker.<InvokeNextResourceFilter>d__22.MoveNext()
--- End of stack trace from previous location where exception was thrown ---
   at System.Runtime.ExceptionServices.ExceptionDispatchInfo.Throw()
   at Microsoft.AspNetCore.Mvc.Internal.ControllerActionInvoker.Rethrow(ResourceExecutedContext context)
   at Microsoft.AspNetCore.Mvc.Internal.ControllerActionInvoker.Next(State& next, Scope& scope, Object& state, Boolean& isCompleted)
   at Microsoft.AspNetCore.Mvc.Internal.ControllerActionInvoker.<InvokeAsync>d__20.MoveNext()
--- End of stack trace from previous location where exception was thrown ---
   at System.Runtime.ExceptionServices.ExceptionDispatchInfo.Throw()
   at System.Runtime.CompilerServices.TaskAwaiter.HandleNonSuccessAndDebuggerNotification(Task task)
   at Microsoft.AspNetCore.Builder.RouterMiddleware.<Invoke>d__4.MoveNext()
--- End of stack trace from previous location where exception was thrown ---
   at System.Runtime.ExceptionServices.ExceptionDispatchInfo.Throw()
   at System.Runtime.CompilerServices.TaskAwaiter.HandleNonSuccessAndDebuggerNotification(Task task)
   at Microsoft.AspNetCore.SpaServices.Webpack.ConditionalProxyMiddleware.<Invoke>d__5.MoveNext()
--- End of stack trace from previous location where exception was thrown ---
   at System.Runtime.ExceptionServices.ExceptionDispatchInfo.Throw()
   at System.Runtime.CompilerServices.TaskAwaiter.HandleNonSuccessAndDebuggerNotification(Task task)
   at Microsoft.AspNetCore.SpaServices.Webpack.ConditionalProxyMiddleware.<Invoke>d__5.MoveNext()
--- End of stack trace from previous location where exception was thrown ---
   at System.Runtime.ExceptionServices.ExceptionDispatchInfo.Throw()
   at System.Runtime.CompilerServices.TaskAwaiter.HandleNonSuccessAndDebuggerNotification(Task task)
   at Microsoft.AspNetCore.Authentication.AuthenticationMiddleware`1.<Invoke>d__18.MoveNext()
--- End of stack trace from previous location where exception was thrown ---
   at System.Runtime.ExceptionServices.ExceptionDispatchInfo.Throw()
   at Microsoft.AspNetCore.Authentication.AuthenticationMiddleware`1.<Invoke>d__18.MoveNext()
--- End of stack trace from previous location where exception was thrown ---
   at System.Runtime.ExceptionServices.ExceptionDispatchInfo.Throw()
   at System.Runtime.CompilerServices.TaskAwaiter.HandleNonSuccessAndDebuggerNotification(Task task)
   at System.Runtime.CompilerServices.TaskAwaiter.GetResult()
   at FundTrack.WebUI.Middlewares.GlobalErrorHandlingMiddleware.<Invoke>d__4.MoveNext() in C:\FundTrack\FundTrack.WebUI\Middlewares\GlobalErrorHandlingMiddleware.cs:line 28
____________________________________________________________________________________________________________________________________________

Date and time:  30.10.2017 13:55:12
Error message:  Неможливо виконати фінансову операцію "Розхід"
Source:  FundTrack.BLL
InnerException:  FundTrack.BLL.Concrete.BusinessLogicException: Неможливо виконати фінансову операцію "Розхід" ---> Microsoft.EntityFrameworkCore.DbUpdateException: An error occurred while updating the entries. See the inner exception for details. ---> System.Data.SqlTypes.SqlTypeException: SqlDateTime overflow. Must be between 1/1/1753 12:00:00 AM and 12/31/9999 11:59:59 PM.
   at System.Data.SqlClient.TdsParser.TdsExecuteRPC(_SqlRPC[] rpcArray, Int32 timeout, Boolean inSchema, TdsParserStateObject stateObj, Boolean isCommandProc, Boolean sync, TaskCompletionSource`1 completion, Int32 startRpc, Int32 startParam)
   at System.Data.SqlClient.SqlCommand.RunExecuteReaderTds(CommandBehavior cmdBehavior, RunBehavior runBehavior, Boolean returnStream, Boolean async, Int32 timeout, Task& task, Boolean asyncWrite, SqlDataReader ds)
   at System.Data.SqlClient.SqlCommand.ExecuteReader(CommandBehavior behavior)
   at Microsoft.EntityFrameworkCore.Storage.Internal.RelationalCommand.Execute(IRelationalConnection connection, String executeMethod, IReadOnlyDictionary`2 parameterValues, Boolean closeConnection)
   at Microsoft.EntityFrameworkCore.Storage.Internal.RelationalCommand.ExecuteReader(IRelationalConnection connection, IReadOnlyDictionary`2 parameterValues)
   at Microsoft.EntityFrameworkCore.Update.ReaderModificationCommandBatch.Execute(IRelationalConnection connection)
   --- End of inner exception stack trace ---
   at Microsoft.EntityFrameworkCore.Update.ReaderModificationCommandBatch.Execute(IRelationalConnection connection)
   at Microsoft.EntityFrameworkCore.Update.Internal.BatchExecutor.Execute(Tuple`2 parameters)
   at Microsoft.EntityFrameworkCore.Storage.Internal.SqlServerExecutionStrategy.Execute[TState,TResult](Func`2 operation, Func`2 verifySucceeded, TState state)
   at Microsoft.EntityFrameworkCore.ChangeTracking.Internal.StateManager.SaveChanges(IReadOnlyList`1 entriesToSave)
   at Microsoft.EntityFrameworkCore.ChangeTracking.Internal.StateManager.SaveChanges(Boolean acceptAllChangesOnSuccess)
   at Microsoft.EntityFrameworkCore.DbContext.SaveChanges(Boolean acceptAllChangesOnSuccess)
   at FundTrack.DAL.Concrete.UnitOfWork.SaveChanges() in C:\FundTrack\FundTrack.DAL\Concrete\UnitOfWork.cs:line 461
   at FundTrack.BLL.Concrete.FinOpService.CreateSpending(FinOpViewModel finOpModel) in C:\FundTrack\FundTrack.BLL\Concrete\FinOpService.cs:line 141
   --- End of inner exception stack trace ---
   at FundTrack.BLL.Concrete.FinOpService.CreateSpending(FinOpViewModel finOpModel) in C:\FundTrack\FundTrack.BLL\Concrete\FinOpService.cs:line 146
   at FundTrack.BLL.Concrete.FinOpService.CreateFinOp(FinOpFromBankViewModel finOpModel) in C:\FundTrack\FundTrack.BLL\Concrete\FinOpService.cs:line 44
StackTrace:     at FundTrack.BLL.Concrete.FinOpService.CreateFinOp(FinOpFromBankViewModel finOpModel) in C:\FundTrack\FundTrack.BLL\Concrete\FinOpService.cs:line 60
   at FundTrack.WebUI.Controllers.FinOpController.CreateFinOp(FinOpFromBankViewModel finOpModel) in C:\FundTrack\FundTrack.WebUI\Controllers\FinOpController.cs:line 46
   at lambda_method(Closure , Object , Object[] )
   at Microsoft.AspNetCore.Mvc.Internal.ControllerActionInvoker.<InvokeActionMethodAsync>d__27.MoveNext()
--- End of stack trace from previous location where exception was thrown ---
   at System.Runtime.ExceptionServices.ExceptionDispatchInfo.Throw()
   at System.Runtime.CompilerServices.TaskAwaiter.HandleNonSuccessAndDebuggerNotification(Task task)
   at Microsoft.AspNetCore.Mvc.Internal.ControllerActionInvoker.<InvokeNextActionFilterAsync>d__25.MoveNext()
--- End of stack trace from previous location where exception was thrown ---
   at System.Runtime.ExceptionServices.ExceptionDispatchInfo.Throw()
   at Microsoft.AspNetCore.Mvc.Internal.ControllerActionInvoker.Rethrow(ActionExecutedContext context)
   at Microsoft.AspNetCore.Mvc.Internal.ControllerActionInvoker.Next(State& next, Scope& scope, Object& state, Boolean& isCompleted)
   at Microsoft.AspNetCore.Mvc.Internal.ControllerActionInvoker.<InvokeNextResourceFilter>d__22.MoveNext()
--- End of stack trace from previous location where exception was thrown ---
   at System.Runtime.ExceptionServices.ExceptionDispatchInfo.Throw()
   at Microsoft.AspNetCore.Mvc.Internal.ControllerActionInvoker.Rethrow(ResourceExecutedContext context)
   at Microsoft.AspNetCore.Mvc.Internal.ControllerActionInvoker.Next(State& next, Scope& scope, Object& state, Boolean& isCompleted)
   at Microsoft.AspNetCore.Mvc.Internal.ControllerActionInvoker.<InvokeAsync>d__20.MoveNext()
--- End of stack trace from previous location where exception was thrown ---
   at System.Runtime.ExceptionServices.ExceptionDispatchInfo.Throw()
   at System.Runtime.CompilerServices.TaskAwaiter.HandleNonSuccessAndDebuggerNotification(Task task)
   at Microsoft.AspNetCore.Builder.RouterMiddleware.<Invoke>d__4.MoveNext()
--- End of stack trace from previous location where exception was thrown ---
   at System.Runtime.ExceptionServices.ExceptionDispatchInfo.Throw()
   at System.Runtime.CompilerServices.TaskAwaiter.HandleNonSuccessAndDebuggerNotification(Task task)
   at Microsoft.AspNetCore.SpaServices.Webpack.ConditionalProxyMiddleware.<Invoke>d__5.MoveNext()
--- End of stack trace from previous location where exception was thrown ---
   at System.Runtime.ExceptionServices.ExceptionDispatchInfo.Throw()
   at System.Runtime.CompilerServices.TaskAwaiter.HandleNonSuccessAndDebuggerNotification(Task task)
   at Microsoft.AspNetCore.SpaServices.Webpack.ConditionalProxyMiddleware.<Invoke>d__5.MoveNext()
--- End of stack trace from previous location where exception was thrown ---
   at System.Runtime.ExceptionServices.ExceptionDispatchInfo.Throw()
   at System.Runtime.CompilerServices.TaskAwaiter.HandleNonSuccessAndDebuggerNotification(Task task)
   at Microsoft.AspNetCore.Authentication.AuthenticationMiddleware`1.<Invoke>d__18.MoveNext()
--- End of stack trace from previous location where exception was thrown ---
   at System.Runtime.ExceptionServices.ExceptionDispatchInfo.Throw()
   at Microsoft.AspNetCore.Authentication.AuthenticationMiddleware`1.<Invoke>d__18.MoveNext()
--- End of stack trace from previous location where exception was thrown ---
   at System.Runtime.ExceptionServices.ExceptionDispatchInfo.Throw()
   at System.Runtime.CompilerServices.TaskAwaiter.HandleNonSuccessAndDebuggerNotification(Task task)
   at System.Runtime.CompilerServices.TaskAwaiter.GetResult()
   at FundTrack.WebUI.Middlewares.GlobalErrorHandlingMiddleware.<Invoke>d__4.MoveNext() in C:\FundTrack\FundTrack.WebUI\Middlewares\GlobalErrorHandlingMiddleware.cs:line 28
____________________________________________________________________________________________________________________________________________

